<?xml version='1.0' encoding='utf-8'?>
<robot name="urdf_arm">
  <link name="urdf_arm">
    <inertial>
      <origin xyz="-0.0174875527558622 0.00179910750290237 0" rpy="0 0 0" />
      <mass value="5.14039351525955" />
      <inertia ixx="0.0499222359614081" ixy="-1.45737146282782E-06" ixz="0.000941479736923806" iyy="0.0373806752216079" iyz="-1.04144812553937E-05" izz="0.0330605392668542" />
    </inertial>
    <visual>
      <origin xyz="0 0 0" rpy="0 0 0" />
      <geometry>
        <mesh filename="../meshes_obj/urdf_arm.obj" />
      </geometry>
      <material name="">
        <color rgba="1 1 1 1" />
      </material>
    </visual>
    <collision>
      <origin xyz="0 0 0" rpy="0 0 0" />
      <geometry>
        <mesh filename="../meshes_obj/urdf_arm.obj" />
      </geometry>
    </collision>
  </link>
  
  <link name="zarm_l1_link">
    <inertial>
      <origin xyz="0 0 0" rpy="0 0 0" />
      <mass value="0.962" />
      <inertia ixx="0.00225" ixy="-3e-05" ixz="0.0" iyy="0.00099" iyz="-2e-05" izz="0.00227" />
    </inertial>
    <visual>
      <origin xyz="0 0 0" rpy="0 0 0" />
      <geometry>
        <mesh filename="../meshes_obj/l_arm_pitch.obj" /> 
      </geometry>
      <material name="">
        <color rgba="1 1 1 1" /> 
      </material>
    </visual>
  </link>
  
  <joint name="zarm_l1_joint" type="revolute">
    <origin xyz="-0.017499853 0.299269999999999996 0.3" rpy="0 0 0" /> 
    <parent link="urdf_arm" /> 
    <child link="zarm_l1_link" />
    <axis xyz="0 1 0" />
    <limit lower="-3.14159265358979" upper="3.14" effort="100.0" velocity="41.3433333333333" />
    <dynamics damping="0.2" friction="0.1" />
  </joint>
   
  <link name="zarm_l2_link">
    <inertial>
      <origin xyz="-0.00791 0.0 -0.04655" rpy="0 0 0" />
      <mass value="0.57" />
      <inertia ixx="0.00163" ixy="0.0" ixz="5e-05" iyy="0.00211" iyz="0.0" izz="0.00122" />
    </inertial>
    <visual>
      <origin xyz="0 0 0" rpy="0 0 0" />
      <geometry>
        <mesh filename="../meshes_obj/l_arm_roll.obj" />
      </geometry>
      <material name="">
        <color rgba="1 1 1 1" />
      </material>
    </visual>
  </link>
  <joint name="zarm_l2_joint" type="revolute">
    <origin xyz="0 0 0" rpy="0 0 0" />
    <parent link="zarm_l1_link" />
    <child link="zarm_l2_link" />
    <axis xyz="1 0 0" />
    <limit lower="-3.14" upper="3.14" effort="50.0" velocity="8.37333333333333" />
    <dynamics damping="0.2" friction="0.1" />
  </joint>
  <link name="zarm_l3_link">
    <inertial>
      <origin xyz="0.00628 0.00107 -0.20878" rpy="0 0 0" />
      <mass value="1.65" />
      <inertia ixx="0.00815" ixy="-4e-05" ixz="0.00085" iyy="0.00828" iyz="0.00014" izz="0.00206" />
    </inertial>
    <visual>
      <origin xyz="0 0 0" rpy="0 0 0" />
      <geometry>
        <mesh filename="../meshes_obj/l_arm_yaw.obj" />
      </geometry>
      <material name="">
        <color rgba="1 1 1 1" />
      </material>
    </visual>
  </link>
  <joint name="zarm_l3_joint" type="revolute">
    <origin xyz="0 0 0" rpy="0 0 0" />
    <parent link="zarm_l2_link" />
    <child link="zarm_l3_link" />
    <axis xyz="0 0 1" />
    <limit lower="-3.14" upper="3.14" effort="39.0" velocity="19.3633333333333" />
    <dynamics damping="0.2" friction="0.1" />
  </joint>
  <link name="zarm_l4_link">
    <inertial>
      <origin xyz="-0.01611 0.00143 -0.04857" rpy="0 0 0" />
      <mass value="0.429" />
      <inertia ixx="0.00135" ixy="0.0" ixz="-0.0001" iyy="0.00114" iyz="0.0" izz="0.00083" />
    </inertial>
    <visual>
      <origin xyz="0 0 0" rpy="0 0 0" />
      <geometry>
        <mesh filename="../meshes_obj/l_forearm.obj" />
      </geometry>
      <material name="">
        <color rgba="1 1 1 1" />
      </material>
    </visual>
  </link>
  <joint name="zarm_l4_joint" type="revolute">
    <origin xyz="0.0199999999999998 0 -0.2837" rpy="0 0 0" />
    <parent link="zarm_l3_link" />
    <child link="zarm_l4_link" />
    <axis xyz="0 1 0" />
    <limit lower="-3.14" upper="3.14" effort="50.0" velocity="8.37333333333333" />
    <dynamics damping="0.2" friction="0.1" />
  </joint>
    <link name="zarm_l5_link">
    <inertial>
      <origin xyz="-0.00207 0.00018 -0.05079" rpy="0 0 0" />
      <mass value="0.61" />
      <inertia ixx="0.00107" ixy="0.0" ixz="-4e-05" iyy="0.00146" iyz="0.0" izz="0.00083" />
    </inertial>
    <visual>
      <origin xyz="0 0 0" rpy="0 0 0" />
      <geometry>
        <mesh filename="../meshes_obj/l_hand_yaw.obj" />
      </geometry>
      <material name="">
        <color rgba="1 1 1 1" />
      </material>
    </visual>
  </link>
  <joint name="zarm_l5_joint" type="revolute">
    <origin xyz="-0.0200000000000025 0 -0.127037274261591" rpy="0 0 0" />
    <parent link="zarm_l4_link" />
    <child link="zarm_l5_link" />
    <axis xyz="0 0 1" />
    <limit lower="-3.14" upper="3.14" effort="12.0" velocity="21.666" />
  </joint>

<link name="left_gripper_robotiq_85_base_link">
  <inertial>
    <origin xyz="0.00021987 -2.3546E-10 0.030163" rpy="0 0 0" />
    <mass value="0.30915" />
    <inertia ixx="0.00028972" ixy="-5.7879E-10" ixz="-1.8543E-06" iyy="0.00030737" iyz="1.682E-12" izz="0.00019914" />
  </inertial>
  <visual>
    <origin xyz="0 0 0" rpy="0 0 0" />
    <geometry>
      <mesh filename="../meshes_obj/robotiq_85_base_link_fine.obj" />
    </geometry>
    <material name="">
      <color rgba="1 1 1 1" />
    </material>
  </visual>
  <collision>
    <origin xyz="0 0 0" rpy="0 0 0" />
    <geometry>
      <mesh filename="../meshes_obj/robotiq_85_base_link_coarse.obj" />
    </geometry>
  </collision>
</link>
<!-- 新增中间连杆 -->
<link name="left_intermediate_link">
  <inertial>
    <origin xyz="0 0 0" rpy="0 0 0" /> <!-- 需根据实际模型调整 -->
    <mass value="0.1" /> <!-- 示例质量，需根据实际情况设置 -->
    <inertia ixx="0.0005" ixy="0.0" ixz="0.0" 
             iyy="0.0005" iyz="0.0" izz="0.0001" /> <!-- 示例惯性参数 -->
  </inertial>
  <visual>
    <origin xyz="0 0 0" rpy="0 0 0" />
    <geometry>
      <box size="0.05 0.05 0.02" /> <!-- 示例形状，可替换为mesh -->
    </geometry>
    <material name="">
      <color rgba="0.5 0.5 1.0 1.0" /> <!-- 蓝色，便于区分 -->
    </material>
  </visual>
  <collision>
    <origin xyz="0 0 0" rpy="0 0 0" />
    <geometry>
      <box size="0.05 0.05 0.02" />
    </geometry>
  </collision>
</link>

<!-- 新增关节（示例为绕Y轴旋转的旋转关节） -->
<joint name="left_intermediate_joint" type="revolute">
  <origin xyz="0 0 -0.1" rpy="0 0 0" /> <!-- 关节位置，需根据实际调整 -->
  <parent link="zarm_l5_link" />
  <child link="left_intermediate_link" />
  <axis xyz="1 0 0" /> 
  <limit lower="-1.57" upper="1.57" effort="10.0" velocity="5.0" /> <!-- 示例限制 -->
  <dynamics damping="0.1" friction="0.05" /> <!-- 动力学参数 -->
</joint>

<joint name="left_gripper_attachment_joint" type="fixed">
  
  <origin xyz="0 0 0" rpy="3.14 0 0" /> 
  <parent link="left_intermediate_link" />
  <child link="left_gripper_robotiq_85_base_link" />
</joint>
<link name="left_gripper_left_outer_knuckle">
    <inertial>
      <origin xyz="0.0178331863169983 3.68915177224286E-11 0.0021442477325704" rpy="0 0 0" />
      <mass value="0.00684838849434396" />
      <inertia ixx="2.66832029033166E-07" ixy="1.66142314639824E-15" ixz="1.45945633322873E-07" iyy="1.3889233257419E-06" iyz="2.82951161241588E-15" izz="1.26603336914415E-06" />
    </inertial>
    <visual>
      <origin xyz="0 0 0" rpy="0 0 0" />
      <geometry>
        <mesh filename="../meshes_obj/outer_knuckle_fine.obj" />
      </geometry>
      <material name="">
        <color rgba="0.1 0.1 0.1 1" />
      </material>
    </visual>
    <collision>
      <origin xyz="0 0 0" rpy="0 0 0" />
      <geometry>
        <mesh filename="../meshes_obj/outer_knuckle_coarse.obj" />
      </geometry>
    </collision>
  </link>
  <joint name="left_gripper_finger_joint" type="revolute">
    <origin xyz="0.0306011444260539 0 0.0627920162695395" rpy="0 0 0" />
    <parent link="left_gripper_robotiq_85_base_link" />
    <child link="left_gripper_left_outer_knuckle" />
    <axis xyz="0 -1 0" />
    <limit lower="-0.7" upper="0.7" velocity="2.0" effort="1000" />
  </joint>
  <link name="left_gripper_left_outer_finger">
    <inertial>
      <origin xyz="0.00131451599174296 2.88942057994543E-15 0.0215404163180413" rpy="0 0 0" />
      <mass value="0.0273093985570947" />
      <inertia ixx="8.51629628283022E-06" ixy="2.58174336207405E-19" ixz="3.83829504344079E-07" iyy="6.9133328065108E-06" iyz="-7.58589926143789E-19" izz="2.25006832221981E-06" />
    </inertial>
    <visual>
      <origin xyz="0 0 0" rpy="0 0 0" />
      <geometry>
        <mesh filename="../meshes_obj/outer_finger_fine.obj" />
      </geometry>
      <material name="">
        <color rgba="0.1 0.1 0.1 1" />
      </material>
    </visual>
    <collision>
      <origin xyz="0 0 0" rpy="0 0 0" />
      <geometry>
        <mesh filename="../meshes_obj/outer_finger_coarse.obj" />
      </geometry>
    </collision>
  </link>
  <joint name="left_gripper_left_outer_finger_joint" type="fixed">
    <origin xyz="0.0316910442266543 0 -0.00193396375724605" rpy="0 0 0" />
    <parent link="left_gripper_left_outer_knuckle" />
    <child link="left_gripper_left_outer_finger" />
    <axis xyz="0 -1 0" />
  </joint>
  <link name="left_gripper_left_inner_knuckle">
    <inertial>
      <origin xyz="0.017097546626628 -3.93808524389535E-10 0.0224918438201868" rpy="0 0 0" />
      <mass value="0.0110930853895903" />
      <inertia ixx="4.23392770691541E-06" ixy="5.748978936968E-15" ixz="1.78855677119788E-06" iyy="3.96548790524392E-06" iyz="1.05464666369669E-14" izz="3.24068002883007E-06" />
    </inertial>
    <visual>
      <origin xyz="0 0 0" rpy="0 0 0" />
      <geometry>
        <mesh filename="../meshes_obj/inner_knuckle_fine.obj" />
      </geometry>
      <material name="">
        <color rgba="0.1 0.1 0.1 1" />
      </material>
    </visual>
    <collision>
      <origin xyz="0 0 0" rpy="0 0 0" />
      <geometry>
        <mesh filename="../meshes_obj/inner_knuckle_coarse.obj" />
      </geometry>
    </collision>
  </link>
  <joint name="left_gripper_left_inner_knuckle_joint" type="revolute">
    <origin xyz="0.0127000000001501 0 0.0693074999999639" rpy="0 0 0" />
    <parent link="left_gripper_robotiq_85_base_link" />
    <child link="left_gripper_left_inner_knuckle" />
    <axis xyz="0 -1 0" />
    <limit lower="-1" upper="0.8757" velocity="2.0" effort="1000" />
    <mimic joint="left_gripper_finger_joint" multiplier="1" offset="0" />
  </joint>
  <link name="left_gripper_left_inner_finger">
    <inertial>
      <origin xyz="0.0060275613594574 -6.29183141465421E-15 0.00669925693133241" rpy="0 0 0" />
      <mass value="0.00724255346165745" />
      <inertia ixx="1.47824274053603E-06" ixy="-3.94884463570303E-19" ixz="-3.45268847648622E-07" iyy="1.70064480838395E-06" iyz="3.5059838910097E-19" izz="4.77151336838364E-07" />
    </inertial>
    <visual>
      <origin xyz="0 0 0" rpy="0 0 0" />
      <geometry>
        <mesh filename="../meshes_obj/inner_finger_fine.obj" />
      </geometry>
      <material name="">
        <color rgba="0.1 0.1 0.1 1" />
      </material>
    </visual>
    <collision>
      <origin xyz="0 0 0" rpy="0 0 0" />
      <geometry>
        <mesh filename="../meshes_obj/inner_finger_coarse.obj" />
      </geometry>
    </collision>
  </link>
  <joint name="left_gripper_left_inner_finger_joint" type="revolute">
    <origin xyz="0.034585310861294 0 0.0454970193817975" rpy="0 0 0" />
    <parent link="left_gripper_left_inner_knuckle" />
    <child link="left_gripper_left_inner_finger" />
    <axis xyz="0 -1 0" />
    <limit lower="-1" upper="0.8757" velocity="2.0" effort="1000" />
    <mimic joint="left_gripper_finger_joint" multiplier="-1" offset="0" />
  </joint>
  <link name="left_gripper_right_inner_knuckle">
    <inertial>
      <origin xyz="0.0168606186773776 3.93808471820465E-10 0.0226699950793434" rpy="0 0 0" />
      <mass value="0.0110930853895903" />
      <inertia ixx="4.27134775939882E-06" ixy="-8.53568456728898E-15" ixz="1.77774229944246E-06" iyy="3.96548790524392E-06" iyz="-8.45108024914164E-15" izz="3.20325997634666E-06" />
    </inertial>
    <visual>
      <origin xyz="0 0 0" rpy="0 0 0" />
      <geometry>
        <mesh filename="../meshes_obj/inner_knuckle_fine.obj" />
      </geometry>
      <material name="">
        <color rgba="0.1 0.1 0.1 1" />
      </material>
    </visual>
    <collision>
      <origin xyz="0 0 0" rpy="0 0 0" />
      <geometry>
        <mesh filename="../meshes_obj/inner_knuckle_coarse.obj" />
      </geometry>
    </collision>
  </link>
  <joint name="left_gripper_right_inner_knuckle_joint" type="revolute">
    <origin xyz="-0.0126999999998499 0 0.0693075000000361" rpy="0 0 3.14159265358979" />
    <parent link="left_gripper_robotiq_85_base_link" />
    <child link="left_gripper_right_inner_knuckle" />
    <axis xyz="0 1 0" />
    <limit lower="-1" upper="0.8757" velocity="2.0" effort="1000" />
    <mimic joint="left_gripper_finger_joint" multiplier="-1" offset="0" />
  </joint>
  <link name="left_gripper_right_inner_finger">
    <inertial>
      <origin xyz="0.00602756228812038 -6.47284509480176E-15 0.00669925609578108" rpy="0 0 0" />
      <mass value="0.00724255346165744" />
      <inertia ixx="1.47824283625957E-06" ixy="-3.95952064019123E-19" ixz="-3.45268708875543E-07" iyy="1.70064480838394E-06" iyz="3.55286507960029E-19" izz="4.77151241114822E-07" />
    </inertial>
    <visual>
      <origin xyz="0 0 0" rpy="0 0 0" />
      <geometry>
        <mesh filename="../meshes_obj/inner_finger_fine.obj" />
      </geometry>
      <material name="">
        <color rgba="0.1 0.1 0.1 1" />
      </material>
    </visual>
    <collision>
      <origin xyz="0 0 0" rpy="0 0 0" />
      <geometry>
        <mesh filename="../meshes_obj/inner_finger_coarse.obj" />
      </geometry>
    </collision>
  </link>
  <joint name="left_gripper_right_inner_finger_joint" type="revolute">
    <origin xyz="0.0341060475457406 0 0.0458573878541688" rpy="0 0 0" />
    <parent link="left_gripper_right_inner_knuckle" />
    <child link="left_gripper_right_inner_finger" />
    <axis xyz="0 1 0" />
    <limit lower="-1" upper="0.8757" velocity="2.0" effort="1000" />
    <mimic joint="left_gripper_finger_joint" multiplier="1" offset="0" />
  </joint>
  <link name="left_gripper_right_outer_knuckle">
    <inertial>
      <origin xyz="0.0178097074051638 3.60493211424024E-11 0.00233123458346721" rpy="0 0 0" />
      <mass value="0.00684838849401352" />
      <inertia ixx="2.70004361573169E-07" ixy="1.59579467624491E-15" ixz="1.56396493788199E-07" iyy="1.38892332558312E-06" iyz="2.82357800318817E-15" izz="1.26286103637978E-06" />
    </inertial>
    <visual>
      <origin xyz="0 0 0" rpy="0 0 0" />
      <geometry>
        <mesh filename="../meshes_obj/outer_knuckle_fine.obj" />
      </geometry>
      <material name="">
        <color rgba="0.1 0.1 0.1 1" />
      </material>
    </visual>
    <collision>
      <origin xyz="0 0 0" rpy="0 0 0" />
      <geometry>
        <mesh filename="../meshes_obj/outer_knuckle_coarse.obj" />
      </geometry>
    </collision>
  </link>
  <joint name="left_gripper_right_outer_knuckle_joint" type="revolute">
    <origin xyz="-0.0306011444258893 0 0.0627920162695395" rpy="0 0 3.14159265358979" />
    <parent link="left_gripper_robotiq_85_base_link" />
    <child link="left_gripper_right_outer_knuckle" />
    <axis xyz="0 1 0" />
    <limit lower="-1" upper="0.8757" velocity="2.0" effort="1000" />
    <mimic joint="left_gripper_finger_joint" multiplier="-1" offset="0" />
  </joint>
  <link name="left_gripper_right_outer_finger">
    <inertial>
      <origin xyz="0.00108844269639009 -2.611488350845E-15 0.0215530225245502" rpy="0 0 0" />
      <mass value="0.0273093985570947" />
      <inertia ixx="8.52366028592721E-06" ixy="3.41683380899422E-19" ixz="3.18003675694284E-07" iyy="6.91333280651081E-06" iyz="7.37726682706417E-19" izz="2.24270431912283E-06" />
    </inertial>
    <visual>
      <origin xyz="0 0 0" rpy="0 0 0" />
      <geometry>
        <mesh filename="../meshes_obj/outer_finger_fine.obj" />
      </geometry>
      <material name="">
        <color rgba="0.1 0.1 0.1 1" />
      </material>
    </visual>
    <collision>
      <origin xyz="0 0 0" rpy="0 0 0" />
      <geometry>
        <mesh filename="../meshes_obj/outer_finger_coarse.obj" />
      </geometry>
    </collision>
  </link>
  <joint name="left_gripper_right_outer_finger_joint" type="fixed">
    <origin xyz="0.0317095909367246 0 -0.0016013564954687" rpy="0 0 0" />
    <parent link="left_gripper_right_outer_knuckle" />
    <child link="left_gripper_right_outer_finger" />
    <axis xyz="0 1 0" />
  </joint>


  
<link name="zarm_r1_link">
  <inertial>
    <origin xyz="-0.00083 0.02218 0.00035" rpy="0 0 0" /> 
    <mass value="0.962" />
    <inertia ixx="0.00225" ixy="3e-05" ixz="0.0" iyy="0.00099" iyz="2e-05" izz="0.00227" /> 
  </inertial>
  <visual>
    <origin xyz="0 0 0" rpy="0 0 0" />
    <geometry>
      <mesh filename="../meshes_obj/r_arm_pitch.obj" /> 
    </geometry>
    <material name="">
      <color rgba="1 1 1 1" /> 
    </material>
  </visual>
</link>

<joint name="zarm_r1_joint" type="revolute">
  <origin xyz="-0.017499853 -0.299269999999999996 0.3" rpy="0 0 0" /> 
  <parent link="urdf_arm" />
  <child link="zarm_r1_link" />
  <axis xyz="0 1 0" /> 
  <limit lower="-3.14159265358979" upper="3.14" effort="100.0" velocity="41.3433333333333" />
  <dynamics damping="0.2" friction="0.1" />
</joint>


<link name="zarm_r2_link">
  <inertial>
    <origin xyz="-0.00791 0.0 -0.04655" rpy="0 0 0" /> 
    <mass value="0.57" />
    <inertia ixx="0.00163" ixy="0.0" ixz="5e-05" iyy="0.00211" iyz="0.0" izz="0.00122" />
  </inertial>
  <visual>
    <origin xyz="0 0 0" rpy="0 0 0" />
    <geometry>
      <mesh filename="../meshes_obj/r_arm_roll.obj" />
    </geometry>
    <material name="">
      <color rgba="1 1 1 1" />
    </material>
  </visual>
</link>

<joint name="zarm_r2_joint" type="revolute">
  <origin xyz="0 0 0" rpy="0 0 0" />
  <parent link="zarm_r1_link" />
  <child link="zarm_r2_link" />
  <axis xyz="1 0 0" /> 
  <limit lower="-3.14" upper="3.14" effort="50.0" velocity="8.37333333333333" />
  <dynamics damping="0.2" friction="0.1" />
</joint>


<link name="zarm_r3_link">
  <inertial>
    <origin xyz="0.00628 -0.00107 -0.20878" rpy="0 0 0" /> 
    <mass value="1.65" />
    <inertia ixx="0.00815" ixy="4e-05" ixz="0.00085" iyy="0.00828" iyz="-0.00014" izz="0.00206" /> 
  </inertial>
  <visual>
    <origin xyz="0 0 0" rpy="0 0 0" />
    <geometry>
      <mesh filename="../meshes_obj/r_arm_yaw.obj" />
    </geometry>
    <material name="">
      <color rgba="1 1 1 1" />
    </material>
  </visual>
</link>

<joint name="zarm_r3_joint" type="revolute">
  <origin xyz="0 0 0" rpy="0 0 0" />
  <parent link="zarm_r2_link" />
  <child link="zarm_r3_link" />
  <axis xyz="0 0 1" /> 
  <limit lower="-3.14" upper="3.14" effort="39.0" velocity="19.3633333333333" />
  <dynamics damping="0.2" friction="0.1" />
</joint>


<link name="zarm_r4_link">
  <inertial>
    <origin xyz="-0.01611 -0.00143 -0.04857" rpy="0 0 0" /> 
    <mass value="0.429" />
    <inertia ixx="0.00135" ixy="0.0" ixz="-0.0001" iyy="0.00114" iyz="0.0" izz="0.00083" />
  </inertial>
  <visual>
    <origin xyz="0 0 0" rpy="0 0 0" />
    <geometry>
      <mesh filename="../meshes_obj/r_forearm.obj" />
    </geometry>
    <material name="">
      <color rgba="1 1 1 1" />
    </material>
  </visual>
</link>

<joint name="zarm_r4_joint" type="revolute">
  <origin xyz="0.0199999999999998 0 -0.2837" rpy="0 0 0" /> 
  <parent link="zarm_r3_link" />
  <child link="zarm_r4_link" />
  <axis xyz="0 1 0" />
  <limit lower="-3.14" upper="3.14" effort="50.0" velocity="8.37333333333333" />
  <dynamics damping="0.2" friction="0.1" />
</joint>
  <link name="zarm_r5_link">
    <inertial>
      <origin xyz="-0.00207 -0.00018 -0.05079" rpy="0 0 0" />
      <mass value="0.61" />
      <inertia ixx="0.00107" ixy="0.0" ixz="-4e-05" iyy="0.00146" iyz="0.0" izz="0.00083" />
    </inertial>
    <visual>
      <origin xyz="0 0 0" rpy="0 0 0" />
      <geometry>
        <mesh filename="../meshes_obj/r_hand_yaw.obj" />
      </geometry>
      <material name="">
        <color rgba="1 1 1 1" />
      </material>
    </visual>
  </link>
  <joint name="zarm_r5_joint" type="revolute">
    <origin xyz="-0.0200000000000001 0 -0.127037274261587" rpy="0 0 0" />
    <parent link="zarm_r4_link" />
    <child link="zarm_r5_link" />
    <axis xyz="0 0 1" />
    <limit lower="-3.14" upper="3.14" effort="12.0" velocity="21.666" />
  </joint>


<link name="right_gripper_robotiq_85_base_link">
  <inertial>
    <origin xyz="0.00021987 -2.3546E-10 0.030163" rpy="0 0 0" />
    <mass value="0.30915" />
    <inertia ixx="0.00028972" ixy="-5.7879E-10" ixz="-1.8543E-06" iyy="0.00030737" iyz="1.682E-12" izz="0.00019914" />
  </inertial>
  <visual>
    <origin xyz="0 0 0" rpy="0 0 0" />
    <geometry>
      <mesh filename="../meshes_obj/robotiq_85_base_link_fine.obj" />
    </geometry>
    <material name="">
      <color rgba="1 1 1 1" />
    </material>
  </visual>
  <collision>
    <origin xyz="0 0 0" rpy="0 0 0" />
    <geometry>
      <mesh filename="../meshes_obj/robotiq_85_base_link_coarse.obj" />
    </geometry>
  </collision>
</link>

<!-- 新增中间连杆 -->
<link name="right_intermediate_link">
  <inertial>
    <origin xyz="0 0 0" rpy="0 0 0" /> <!-- 需根据实际模型调整 -->
    <mass value="0.1" /> <!-- 示例质量，需根据实际情况设置 -->
    <inertia ixx="0.0005" ixy="0.0" ixz="0.0" 
             iyy="0.0005" iyz="0.0" izz="0.0001" /> <!-- 示例惯性参数 -->
  </inertial>
  <visual>
    <origin xyz="0 0 0" rpy="0 0 0" />
    <geometry>
      <box size="0.05 0.05 0.02" /> <!-- 示例形状，可替换为mesh -->
    </geometry>
    <material name="">
      <color rgba="0.5 0.5 1.0 1.0" /> <!-- 蓝色，便于区分 -->
    </material>
  </visual>
  <collision>
    <origin xyz="0 0 0" rpy="0 0 0" />
    <geometry>
      <box size="0.05 0.05 0.02" />
    </geometry>
  </collision>
</link>

<!-- 新增关节（示例为绕Y轴旋转的旋转关节） -->
<joint name="right_intermediate_joint" type="revolute">
  <origin xyz="0 0 -0.1" rpy="0 0 0" /> <!-- 关节位置，需根据实际调整 -->
  <parent link="zarm_r5_link" />
  <child link="right_intermediate_link" />
  <axis xyz="1 0 0" /> 
  <limit lower="-1.57" upper="1.57" effort="10.0" velocity="5.0" /> <!-- 示例限制 -->
  <dynamics damping="0.1" friction="0.05" /> <!-- 动力学参数 -->
</joint>

<joint name="right_gripper_attachment_joint" type="fixed">
  
  <origin xyz="0 0 0" rpy="3.14 0 0" /> 
  <parent link="right_intermediate_link" />
  <child link="right_gripper_robotiq_85_base_link" />
</joint>
<link name="right_gripper_left_outer_knuckle">
    <inertial>
      <origin xyz="0.0178331863169983 3.68915177224286E-11 0.0021442477325704" rpy="0 0 0" />
      <mass value="0.00684838849434396" />
      <inertia ixx="2.66832029033166E-07" ixy="1.66142314639824E-15" ixz="1.45945633322873E-07" iyy="1.3889233257419E-06" iyz="2.82951161241588E-15" izz="1.26603336914415E-06" />
    </inertial>
    <visual>
      <origin xyz="0 0 0" rpy="0 0 0" />
      <geometry>
        <mesh filename="../meshes_obj/outer_knuckle_fine.obj" />
      </geometry>
      <material name="">
        <color rgba="0.1 0.1 0.1 1" />
      </material>
    </visual>
    <collision>
      <origin xyz="0 0 0" rpy="0 0 0" />
      <geometry>
        <mesh filename="../meshes_obj/outer_knuckle_coarse.obj" />
      </geometry>
    </collision>
  </link>
  <joint name="right_gripper_finger_joint" type="revolute">
    <origin xyz="0.0306011444260539 0 0.0627920162695395" rpy="0 0 0" />
    <parent link="right_gripper_robotiq_85_base_link" />
    <child link="right_gripper_left_outer_knuckle" />
    <axis xyz="0 -1 0" />
    <limit lower="-1" upper="1" velocity="2.0" effort="1000" />
  </joint>
  <link name="right_gripper_left_outer_finger">
    <inertial>
      <origin xyz="0.00131451599174296 2.88942057994543E-15 0.0215404163180413" rpy="0 0 0" />
      <mass value="0.0273093985570947" />
      <inertia ixx="8.51629628283022E-06" ixy="2.58174336207405E-19" ixz="3.83829504344079E-07" iyy="6.9133328065108E-06" iyz="-7.58589926143789E-19" izz="2.25006832221981E-06" />
    </inertial>
    <visual>
      <origin xyz="0 0 0" rpy="0 0 0" />
      <geometry>
        <mesh filename="../meshes_obj/outer_finger_fine.obj" />
      </geometry>
      <material name="">
        <color rgba="0.1 0.1 0.1 1" />
      </material>
    </visual>
    <collision>
      <origin xyz="0 0 0" rpy="0 0 0" />
      <geometry>
        <mesh filename="../meshes_obj/outer_finger_coarse.obj" />
      </geometry>
    </collision>
  </link>
  <joint name="right_gripper_left_outer_finger_joint" type="fixed">
    <origin xyz="0.0316910442266543 0 -0.00193396375724605" rpy="0 0 0" />
    <parent link="right_gripper_left_outer_knuckle" />
    <child link="right_gripper_left_outer_finger" />
    <axis xyz="0 -1 0" />
  </joint>
  <link name="right_gripper_left_inner_knuckle">
    <inertial>
      <origin xyz="0.017097546626628 -3.93808524389535E-10 0.0224918438201868" rpy="0 0 0" />
      <mass value="0.0110930853895903" />
      <inertia ixx="4.23392770691541E-06" ixy="5.748978936968E-15" ixz="1.78855677119788E-06" iyy="3.96548790524392E-06" iyz="1.05464666369669E-14" izz="3.24068002883007E-06" />
    </inertial>
    <visual>
      <origin xyz="0 0 0" rpy="0 0 0" />
      <geometry>
        <mesh filename="../meshes_obj/inner_knuckle_fine.obj" />
      </geometry>
      <material name="">
        <color rgba="0.1 0.1 0.1 1" />
      </material>
    </visual>
    <collision>
      <origin xyz="0 0 0" rpy="0 0 0" />
      <geometry>
        <mesh filename="../meshes_obj/inner_knuckle_coarse.obj" />
      </geometry>
    </collision>
  </link>
  <joint name="right_gripper_left_inner_knuckle_joint" type="revolute">
    <origin xyz="0.0127000000001501 0 0.0693074999999639" rpy="0 0 0" />
    <parent link="right_gripper_robotiq_85_base_link" />
    <child link="right_gripper_left_inner_knuckle" />
    <axis xyz="0 -1 0" />
    <limit lower="-1" upper="0.8757" velocity="2.0" effort="1000" />
    <mimic joint="right_gripper_finger_joint" multiplier="1" offset="0" />
  </joint>
  <link name="right_gripper_left_inner_finger">
    <inertial>
      <origin xyz="0.0060275613594574 -6.29183141465421E-15 0.00669925693133241" rpy="0 0 0" />
      <mass value="0.00724255346165745" />
      <inertia ixx="1.47824274053603E-06" ixy="-3.94884463570303E-19" ixz="-3.45268847648622E-07" iyy="1.70064480838395E-06" iyz="3.5059838910097E-19" izz="4.77151336838364E-07" />
    </inertial>
    <visual>
      <origin xyz="0 0 0" rpy="0 0 0" />
      <geometry>
        <mesh filename="../meshes_obj/inner_finger_fine.obj" />
      </geometry>
      <material name="">
        <color rgba="0.1 0.1 0.1 1" />
      </material>
    </visual>
    <collision>
      <origin xyz="0 0 0" rpy="0 0 0" />
      <geometry>
        <mesh filename="../meshes_obj/inner_finger_coarse.obj" />
      </geometry>
    </collision>
  </link>
  <joint name="right_gripper_left_inner_finger_joint" type="revolute">
    <origin xyz="0.034585310861294 0 0.0454970193817975" rpy="0 0 0" />
    <parent link="right_gripper_left_inner_knuckle" />
    <child link="right_gripper_left_inner_finger" />
    <axis xyz="0 -1 0" />
    <limit lower="-1" upper="0.8757" velocity="2.0" effort="1000" />
    <mimic joint="right_gripper_finger_joint" multiplier="-1" offset="0" />
  </joint>
  <link name="right_gripper_right_inner_knuckle">
    <inertial>
      <origin xyz="0.0168606186773776 3.93808471820465E-10 0.0226699950793434" rpy="0 0 0" />
      <mass value="0.0110930853895903" />
      <inertia ixx="4.27134775939882E-06" ixy="-8.53568456728898E-15" ixz="1.77774229944246E-06" iyy="3.96548790524392E-06" iyz="-8.45108024914164E-15" izz="3.20325997634666E-06" />
    </inertial>
    <visual>
      <origin xyz="0 0 0" rpy="0 0 0" />
      <geometry>
        <mesh filename="../meshes_obj/inner_knuckle_fine.obj" />
      </geometry>
      <material name="">
        <color rgba="0.1 0.1 0.1 1" />
      </material>
    </visual>
    <collision>
      <origin xyz="0 0 0" rpy="0 0 0" />
      <geometry>
        <mesh filename="../meshes_obj/inner_knuckle_coarse.obj" />
      </geometry>
    </collision>
  </link>
  <joint name="right_gripper_right_inner_knuckle_joint" type="revolute">
    <origin xyz="-0.0126999999998499 0 0.0693075000000361" rpy="0 0 3.14159265358979" />
    <parent link="right_gripper_robotiq_85_base_link" />
    <child link="right_gripper_right_inner_knuckle" />
    <axis xyz="0 1 0" />
    <limit lower="-1" upper="0.8757" velocity="2.0" effort="1000" />
    <mimic joint="right_gripper_finger_joint" multiplier="-1" offset="0" />
  </joint>
  <link name="right_gripper_right_inner_finger">
    <inertial>
      <origin xyz="0.00602756228812038 -6.47284509480176E-15 0.00669925609578108" rpy="0 0 0" />
      <mass value="0.00724255346165744" />
      <inertia ixx="1.47824283625957E-06" ixy="-3.95952064019123E-19" ixz="-3.45268708875543E-07" iyy="1.70064480838394E-06" iyz="3.55286507960029E-19" izz="4.77151241114822E-07" />
    </inertial>
    <visual>
      <origin xyz="0 0 0" rpy="0 0 0" />
      <geometry>
        <mesh filename="../meshes_obj/inner_finger_fine.obj" />
      </geometry>
      <material name="">
        <color rgba="0.1 0.1 0.1 1" />
      </material>
    </visual>
    <collision>
      <origin xyz="0 0 0" rpy="0 0 0" />
      <geometry>
        <mesh filename="../meshes_obj/inner_finger_coarse.obj" />
      </geometry>
    </collision>
  </link>
  <joint name="right_gripper_right_inner_finger_joint" type="revolute">
    <origin xyz="0.0341060475457406 0 0.0458573878541688" rpy="0 0 0" />
    <parent link="right_gripper_right_inner_knuckle" />
    <child link="right_gripper_right_inner_finger" />
    <axis xyz="0 1 0" />
    <limit lower="-1" upper="0.8757" velocity="2.0" effort="1000" />
    <mimic joint="right_gripper_finger_joint" multiplier="1" offset="0" />
  </joint>
  <link name="right_gripper_right_outer_knuckle">
    <inertial>
      <origin xyz="0.0178097074051638 3.60493211424024E-11 0.00233123458346721" rpy="0 0 0" />
      <mass value="0.00684838849401352" />
      <inertia ixx="2.70004361573169E-07" ixy="1.59579467624491E-15" ixz="1.56396493788199E-07" iyy="1.38892332558312E-06" iyz="2.82357800318817E-15" izz="1.26286103637978E-06" />
    </inertial>
    <visual>
      <origin xyz="0 0 0" rpy="0 0 0" />
      <geometry>
        <mesh filename="../meshes_obj/outer_knuckle_fine.obj" />
      </geometry>
      <material name="">
        <color rgba="0.1 0.1 0.1 1" />
      </material>
    </visual>
    <collision>
      <origin xyz="0 0 0" rpy="0 0 0" />
      <geometry>
        <mesh filename="../meshes_obj/outer_knuckle_coarse.obj" />
      </geometry>
    </collision>
  </link>
  <joint name="right_gripper_right_outer_knuckle_joint" type="revolute">
    <origin xyz="-0.0306011444258893 0 0.0627920162695395" rpy="0 0 3.14159265358979" />
    <parent link="right_gripper_robotiq_85_base_link" />
    <child link="right_gripper_right_outer_knuckle" />
    <axis xyz="0 1 0" />
    <limit lower="-1" upper="0.8757" velocity="2.0" effort="1000" />
    <mimic joint="right_gripper_finger_joint" multiplier="-1" offset="0" />
  </joint>
  <link name="right_gripper_right_outer_finger">
    <inertial>
      <origin xyz="0.00108844269639009 -2.611488350845E-15 0.0215530225245502" rpy="0 0 0" />
      <mass value="0.0273093985570947" />
      <inertia ixx="8.52366028592721E-06" ixy="3.41683380899422E-19" ixz="3.18003675694284E-07" iyy="6.91333280651081E-06" iyz="7.37726682706417E-19" izz="2.24270431912283E-06" />
    </inertial>
    <visual>
      <origin xyz="0 0 0" rpy="0 0 0" />
      <geometry>
        <mesh filename="../meshes_obj/outer_finger_fine.obj" />
      </geometry>
      <material name="">
        <color rgba="0.1 0.1 0.1 1" />
      </material>
    </visual>
    <collision>
      <origin xyz="0 0 0" rpy="0 0 0" />
      <geometry>
        <mesh filename="../meshes_obj/outer_finger_coarse.obj" />
      </geometry>
    </collision>
  </link>
  <joint name="right_gripper_right_outer_finger_joint" type="fixed">
    <origin xyz="0.0317095909367246 0 -0.0016013564954687" rpy="0 0 0" />
    <parent link="right_gripper_right_outer_knuckle" />
    <child link="right_gripper_right_outer_finger" />
    <axis xyz="0 1 0" />
  </joint>
  <link name="head_pitch_motor">
    <inertial>
      <origin xyz="2.15064692521312E-05 0.0060485397407308 -0.0105235281816768" rpy="0 0 0" />
      <mass value="0.0736988170115525" />
      <inertia ixx="3.67348067267319E-05" ixy="6.73619780094987E-08" ixz="-2.37137268464132E-08" iyy="4.13511095677461E-05" iyz="-7.39465521015481E-06" izz="3.68282513893872E-05" />
    </inertial>
    <visual>
      <origin xyz="0 0 0" rpy="0 0 0" />
      <geometry>
        <mesh filename="../meshes_obj/head_pitch_motor.obj" />
      </geometry>
      <material name="">
        <color rgba="1 1 1 1" />
      </material>
    </visual>
    <collision>
      <origin xyz="0 0 0" rpy="0 0 0" />
      <geometry>
        <mesh filename="../meshes_obj/head_pitch_motor.obj" />
      </geometry>
    </collision>
  </link>
  <joint name="head_pitch_motor" type="revolute">
    <origin xyz="-0.0184999999351704 0 0.488400000086134" rpy="0 0 0" />
    <parent link="urdf_arm" />
    <child link="head_pitch_motor" />
    <axis xyz="0 0 -1" />
    
    <limit lower="-3.14" upper="3.14" effort="0" velocity="0" />
  </joint>
  <link name="head">
    <inertial>
      <origin xyz="0.0270543321696196 -0.000611241791026834 0.108993350171997" rpy="0 0 0" />
      <mass value="0.604629438749788" />
      <inertia ixx="0.00220911712019339" ixy="4.4908476911183E-06" ixz="0.000409391213149813" iyy="0.00215799979792596" iyz="1.35756758490623E-05" izz="0.00193855033637337" />
    </inertial>
    <visual>
      <origin xyz="0 0 0" rpy="0 0 0" />
      <geometry>
        <mesh filename="../meshes_obj/head.obj" />
      </geometry>
      <material name="">
        <color rgba="1 1 1 1" />
      </material>
    </visual>
    <collision>
      <origin xyz="0 0 0" rpy="0 0 0" />
      <geometry>
        <mesh filename="../meshes_obj/head.obj" />
      </geometry>
    </collision>
  </link>
  <joint name="head" type="revolute">
    <origin xyz="0 0 0" rpy="0 0 0" />
    <parent link="head_pitch_motor" />
    <child link="head" />
    <axis xyz="0 -1 0" />
    
    <limit lower="-3.14" upper="3.14" effort="0" velocity="0" />
  </joint>
  <link name="head_camera">
    <inertial>
      <origin xyz="-0.00630026061866237 -0.016049154506062 -4.88215811403903E-05" rpy="0 0 0" />
      <mass value="0.0170256015508832" />
      <inertia ixx="1.0918264029313E-05" ixy="-1.05354408167635E-07" ixz="-1.05871497323788E-08" iyy="8.57178950734429E-07" iyz="-1.64018651463633E-08" izz="1.02869893338383E-05" />
    </inertial>
    <visual>
      <origin xyz="0 0 0" rpy="0 0 0" />
      <geometry>
        <mesh filename="../meshes_obj/head_camera.obj" />
      </geometry>
      <material name="">
        <color rgba="1 1 1 1" />
      </material>
    </visual>
    <collision>
      <origin xyz="0 0 0" rpy="0 0 0" />
      <geometry>
        <mesh filename="../meshes_obj/head_camera.obj" />
      </geometry>
    </collision>
  </link>
  <joint name="head_camera" type="fixed">
    <origin xyz="0.0974492283101479 0.0174530823583079 0.125581998333391" rpy="0 0.488692190558416 0" />
    <parent link="head" />
    <child link="head_camera" />
    <axis xyz="0 0 0" />
  </joint>

<link name="chassis">
  <inertial>
    <origin xyz="-0.11038 0.00343 0.30101" rpy="0 0 0" />
    
    <mass value="5" />
    <inertia ixx="10.408029" ixy="-0.000287" ixz="138.9546e-5" iyy="9.9227538" iyz="-4.99e-5" izz="10.3126794" />
  </inertial>
  <visual>
    <origin xyz="0 0 0" rpy="0 0 0" />
    <geometry>
      <mesh filename="../meshes_obj/chassis.obj" />
    </geometry>
    <material name="">
      <color rgba="1 1 1 1" />
    </material>
  </visual>
  <collision>
    <origin xyz="0 0 0" rpy="0 0 0" />
    <geometry>
      <mesh filename="../meshes_obj/chassis.obj" />
    </geometry>
  </collision>
</link>


  <joint name="chassis" type="prismatic">
    <origin xyz="-0.5808425065806821 -0.295 -0.754500000000001" rpy="0 0 0" />
    <parent link="urdf_arm" />
    <child link="chassis" />
    <axis xyz="0 0 1" />
    <limit lower="-3.14" upper="3.14" effort="0" velocity="0" />
  </joint>
  <link name="camera_torso">
    <inertial>
      <origin xyz="-0.00629451575980258 -0.0161363809954276 -0.000627399255521022" rpy="0 0 0" />
      <mass value="0.0174035563465764" />
      <inertia ixx="1.14512648371916E-05" ixy="-1.06865323527971E-07" ixz="2.15531841453902E-08" iyy="1.01358420465748E-06" iyz="-9.98083555754382E-09" izz="1.06808111754815E-05" />
    </inertial>
    <visual>
      <origin xyz="0 0 0" rpy="0 0 0" />
      <geometry>
        <mesh filename="../meshes_obj/camera_torso.obj" />
      </geometry>
      <material name="">
        <color rgba="1 1 1 1" />
      </material>
    </visual>
    <collision>
      <origin xyz="0 0 0" rpy="0 0 0" />
      <geometry>
        <mesh filename="../meshes_obj/camera_torso.obj" />
      </geometry>
    </collision>
  </link>
  <joint name="camera_torso" type="fixed">
    <origin xyz="0.115075952675679 0.01749999999949 0.27587244861972" rpy="0 0.855211333477246 0" />
    <parent link="urdf_arm" />
    <child link="camera_torso" />
    <axis xyz="0 0 0" />
  </joint>

<!-- 左前轮-->
  <joint name="fl_caster_rotation_joint" type="continuous">
    <axis xyz="0 0 1"/>
    <limit effort="6.5" velocity="10"/>
    <safety_controller k_velocity="10"/>
    <calibration rising="-0.785398163397"/>
    <dynamics damping="1.0" friction="0.0"/>
    <origin rpy="0 0 0" xyz="0.6 0.5 0"/>
    <parent link="chassis"/>
    <child link="fl_caster_rotation_link"/>
  </joint>
  
  <link name="fl_caster_rotation_link">
    <inertial>
      <mass value="3.473082"/>
      <origin xyz="0 0 0.07"/>
      <inertia ixx="0.012411765597" ixy="-0.000711733678" ixz="0.00050272983" iyy="0.015218160428" iyz="-0.000004273467" izz="0.011763977943"/>
    </inertial>
    <visual>
      <origin rpy="0 0 0" xyz="0 0 0"/>
      <geometry>
        <mesh filename="../meshes/caster.obj"/>
      </geometry>
    </visual>
    <collision>
      <origin rpy="0 0 0" xyz="0 0 0"/>
      <geometry>
        <mesh filename="../meshes/caster_L.obj"/>
      </geometry>
    </collision>
  </link>
  
  <transmission name="fl_caster_rotation_trans" type="transmission_interface/SimpleTransmission">
    <actuator name="fl_caster_rotation_motor">
      <hardwareInterface>hardware_interface/PositionJointInterface</hardwareInterface>
      <mechanicalReduction>-79.2380952381</mechanicalReduction>
      <electricalMotor>
        <type>DC</type>           <!-- 直流电机 -->
        <nominalVoltage>24.0</nominalVoltage>  <!-- 额定电压(V) -->
        <stallTorque>12.0</stallTorque>        <!-- 堵转扭矩(N·m) -->
        <freeSpeed>3000.0</freeSpeed>          <!-- 空载转速(RPM) -->
        <efficiency>0.85</efficiency>          <!-- 效率 -->
      </electricalMotor>
    </actuator>
    <joint name="fl_caster_rotation_joint"/>
  </transmission>
  
  <joint name="fl_caster_l_wheel_joint" type="continuous">
    <axis xyz="0 1 0"/>
    <limit effort="7" velocity="15"/>
    <safety_controller k_velocity="10"/>
    <dynamics damping="1.0" friction="0.0"/>
    <origin rpy="0 0 0" xyz="0 0.049 0"/>
    <parent link="fl_caster_rotation_link"/>
    <child link="fl_caster_l_wheel_link"/>
  </joint>
  
  <link name="fl_caster_l_wheel_link">
    <inertial>
      <mass value="0.44036"/>
      <origin xyz="0 0 0"/>
      <inertia ixx="0.012411765597" ixy="-0.000711733678" ixz="0.00050272983" iyy="0.015218160428" iyz="-0.000004273467" izz="0.011763977943"/>
    </inertial>
    <visual>
      <origin rpy="3.14 0 0" xyz="0 0 0"/>
      <geometry>
        <mesh filename="../meshes/wheel.obj"/>
      </geometry>
      <material name="wheel_tire">
        <color rgba="0.1 0.1 0.1 1.0"/> <!-- 黑色轮胎 -->
      </material>
    </visual>
    <collision>
      <origin rpy="1.57079632679 0 0" xyz="0 0 0"/>
      <geometry>
        <!-- <cylinder length="0.134" radius="0.074792"/> -->
        <mesh filename="../meshes/wheel.obj"/>
      </geometry>
    </collision>
  </link>
  
  <transmission name="fl_caster_l_wheel_trans" type="transmission_interface/SimpleTransmission">
    <actuator name="fl_caster_l_wheel_motor">
      <hardwareInterface>hardware_interface/VelocityJointInterface</hardwareInterface>
      <mechanicalReduction>79.2380952381</mechanicalReduction>
      <electricalMotor>
        <type>DC</type>
        <nominalVoltage>24.0</nominalVoltage>
        <stallTorque>15.0</stallTorque>
        <freeSpeed>4000.0</freeSpeed>
        <efficiency>0.88</efficiency>
      </electricalMotor>
      <!-- 编码器参数 -->
      <encoder>
        <type>incremental</type> <!-- 增量式编码器 -->
        <resolution>2048</resolution> <!-- 每转脉冲数 -->
        <noiseSigma>0.001</noiseSigma> <!-- 噪声标准差 -->
        <updateRate>1000</updateRate> <!-- 更新频率(Hz) -->
      </encoder>
    </actuator>
    <joint name="fl_caster_l_wheel_joint"/>
  </transmission>
  
  <joint name="fl_caster_r_wheel_joint" type="continuous">
    <axis xyz="0 1 0"/>
    <limit effort="7" velocity="15"/>
    <safety_controller k_velocity="10"/>
    <dynamics damping="1.0" friction="0.0"/>
    <origin rpy="0 0 0" xyz="0 -0.049 0"/>
    <parent link="fl_caster_rotation_link"/>
    <child link="fl_caster_r_wheel_link"/>
  </joint>
  
  <link name="fl_caster_r_wheel_link">
    <inertial>
      <mass value="0.44036"/>
      <origin xyz="0 0 0"/>
      <inertia ixx="0.012411765597" ixy="-0.000711733678" ixz="0.00050272983" iyy="0.015218160428" iyz="-0.000004273467" izz="0.011763977943"/>
    </inertial>
    <visual>
      <origin rpy="0 0 0" xyz="0 0 0"/>
      <geometry>
        <mesh filename="../meshes/wheel.obj"/>
      </geometry>
      <material name="wheel_tire">
        <color rgba="0.1 0.1 0.1 1.0"/> <!-- 黑色轮胎 -->
      </material>
    </visual>
    <collision>
      <origin rpy="1.57079632679 0 0" xyz="0 0 0"/>
      <geometry>
        <!-- <cylinder length="0.134" radius="0.074792"/> -->
        <mesh filename="../meshes/wheel.obj"/>
      </geometry>
    </collision>
  </link>
  
  <transmission name="fl_caster_r_wheel_trans" type="transmission_interface/SimpleTransmission">
    <actuator name="fl_caster_r_wheel_motor">
      <hardwareInterface>hardware_interface/VelocityJointInterface</hardwareInterface>
      <mechanicalReduction>-79.2380952381</mechanicalReduction>
      <electricalMotor>
        <type>DC</type>
        <nominalVoltage>24.0</nominalVoltage>
        <stallTorque>15.0</stallTorque>
        <freeSpeed>4000.0</freeSpeed>
        <efficiency>0.88</efficiency>
      </electricalMotor>
      <!-- 编码器参数 -->
      <encoder>
        <type>incremental</type>
        <resolution>2048</resolution>
        <noiseSigma>0.001</noiseSigma>
        <updateRate>1000</updateRate>
      </encoder>
    </actuator>
    <joint name="fl_caster_r_wheel_joint"/>
  </transmission>
  
  <!-- 传感器：IMU（可选，用于姿态估计） -->
  <link name="fl_imu_link">
    <inertial>
      <mass value="0.1"/>
      <origin xyz="0 0 0"/>
      <inertia ixx="0.001" ixy="0" ixz="0" iyy="0.001" iyz="0" izz="0.001"/>
    </inertial>
    <visual>
      <origin rpy="0 0 0" xyz="0 0 0"/>
      <geometry>
        <box size="0.02 0.02 0.01"/>
      </geometry>
      <material name="imu">
        <color rgba="0.8 0.2 0.2 1.0"/> <!-- 红色 -->
      </material>
    </visual>
  </link>
  
  <joint name="fl_imu_joint" type="fixed">
    <parent link="fl_caster_rotation_link"/>
    <child link="fl_imu_link"/>
    <origin rpy="0 0 0" xyz="0 0 0.1"/>
  </joint>
  

  <!-- 右前轮-->
  <joint name="fr_caster_rotation_joint" type="continuous">
    <axis xyz="0 0 1"/>
    <limit effort="6.5" velocity="10"/>
    <safety_controller k_velocity="10"/>
    <calibration rising="-0.785398163397"/>
    <dynamics damping="1.0" friction="0.0"/>
    <origin rpy="0 0 0" xyz="0.6 0.1 0"/>
    <parent link="chassis"/>
    <child link="fr_caster_rotation_link"/>
  </joint>
  
  <link name="fr_caster_rotation_link">
    <inertial>
      <mass value="3.473082"/>
      <origin xyz="0 0 0.07"/>
      <inertia ixx="0.012411765597" ixy="-0.000711733678" ixz="0.00050272983" iyy="0.015218160428" iyz="-0.000004273467" izz="0.011763977943"/>
    </inertial>
    <visual>
      <origin rpy="0 0 0" xyz="0 0 0"/>
      <geometry>
        <mesh filename="../meshes/caster.obj"/>
      </geometry>
    </visual>
    <collision>
      <origin rpy="0 0 0" xyz="0 0 0"/>
      <geometry>
        <mesh filename="../meshes/caster_L.obj"/>
      </geometry>
    </collision>
  </link>
  
  <transmission name="fr_caster_rotation_trans" type="transmission_interface/SimpleTransmission">
    <actuator name="fr_caster_rotation_motor">
      <hardwareInterface>hardware_interface/PositionJointInterface</hardwareInterface>
      <mechanicalReduction>-79.2380952381</mechanicalReduction>
      <electricalMotor>
        <type>DC</type>           <!-- 直流电机 -->
        <nominalVoltage>24.0</nominalVoltage>  <!-- 额定电压(V) -->
        <stallTorque>12.0</stallTorque>        <!-- 堵转扭矩(N·m) -->
        <freeSpeed>3000.0</freeSpeed>          <!-- 空载转速(RPM) -->
        <efficiency>0.85</efficiency>          <!-- 效率 -->
      </electricalMotor>
    </actuator>
    <joint name="fr_caster_rotation_joint"/>
  </transmission>
  
  <joint name="fr_caster_l_wheel_joint" type="continuous">
    <axis xyz="0 1 0"/>
    <limit effort="7" velocity="15"/>
    <safety_controller k_velocity="10"/>
    <dynamics damping="1.0" friction="0.0"/>
    <origin rpy="0 0 0" xyz="0 0.049 0"/>
    <parent link="fr_caster_rotation_link"/>
    <child link="fr_caster_l_wheel_link"/>
  </joint>
  
  <link name="fr_caster_l_wheel_link">
    <inertial>
      <mass value="0.44036"/>
      <origin xyz="0 0 0"/>
      <inertia ixx="0.012411765597" ixy="-0.000711733678" ixz="0.00050272983" iyy="0.015218160428" iyz="-0.000004273467" izz="0.011763977943"/>
    </inertial>
    <visual>
      <origin rpy="3.14 0 0" xyz="0 0 0"/>
      <geometry>
        <mesh filename="../meshes/wheel.obj"/>
      </geometry>
      <material name="wheel_tire">
        <color rgba="0.1 0.1 0.1 1.0"/> <!-- 黑色轮胎 -->
      </material>
    </visual>
    <collision>
      <origin rpy="1.57079632679 0 0" xyz="0 0 0"/>
      <geometry>
        <!-- <cylinder length="0.134" radius="0.074792"/> -->
        <mesh filename="../meshes/wheel.obj"/>
      </geometry>
    </collision>
  </link>
  
  <transmission name="fr_caster_l_wheel_trans" type="transmission_interface/SimpleTransmission">
    <actuator name="fr_caster_l_wheel_motor">
      <hardwareInterface>hardware_interface/VelocityJointInterface</hardwareInterface>
      <mechanicalReduction>79.2380952381</mechanicalReduction>
      <electricalMotor>
        <type>DC</type>
        <nominalVoltage>24.0</nominalVoltage>
        <stallTorque>15.0</stallTorque>
        <freeSpeed>4000.0</freeSpeed>
        <efficiency>0.88</efficiency>
      </electricalMotor>
      <!-- 编码器参数 -->
      <encoder>
        <type>incremental</type> <!-- 增量式编码器 -->
        <resolution>2048</resolution> <!-- 每转脉冲数 -->
        <noiseSigma>0.001</noiseSigma> <!-- 噪声标准差 -->
        <updateRate>1000</updateRate> <!-- 更新频率(Hz) -->
      </encoder>
    </actuator>
    <joint name="fr_caster_l_wheel_joint"/>
  </transmission>
  
  <joint name="fr_caster_r_wheel_joint" type="continuous">
    <axis xyz="0 1 0"/>
    <limit effort="7" velocity="15"/>
    <safety_controller k_velocity="10"/>
    <dynamics damping="1.0" friction="0.0"/>
    <origin rpy="0 0 0" xyz="0 -0.049 0"/>
    <parent link="fr_caster_rotation_link"/>
    <child link="fr_caster_r_wheel_link"/>
  </joint>
  
  <link name="fr_caster_r_wheel_link">
    <inertial>
      <mass value="0.44036"/>
      <origin xyz="0 0 0"/>
      <inertia ixx="0.012411765597" ixy="-0.000711733678" ixz="0.00050272983" iyy="0.015218160428" iyz="-0.000004273467" izz="0.011763977943"/>
    </inertial>
    <visual>
      <origin rpy="0 0 0" xyz="0 0 0"/>
      <geometry>
        <mesh filename="../meshes/wheel.obj"/>
      </geometry>
      <material name="wheel_tire">
        <color rgba="0.1 0.1 0.1 1.0"/> <!-- 黑色轮胎 -->
      </material>
    </visual>
    <collision>
      <origin rpy="1.57079632679 0 0" xyz="0 0 0"/>
      <geometry>
        <!-- <cylinder length="0.134" radius="0.074792"/> -->
        <mesh filename="../meshes/wheel.obj"/>
      </geometry>
    </collision>
  </link>
  
  <transmission name="fr_caster_r_wheel_trans" type="transmission_interface/SimpleTransmission">
    <actuator name="fr_caster_r_wheel_motor">
      <hardwareInterface>hardware_interface/VelocityJointInterface</hardwareInterface>
      <mechanicalReduction>-79.2380952381</mechanicalReduction>
      <electricalMotor>
        <type>DC</type>
        <nominalVoltage>24.0</nominalVoltage>
        <stallTorque>15.0</stallTorque>
        <freeSpeed>4000.0</freeSpeed>
        <efficiency>0.88</efficiency>
      </electricalMotor>
      <!-- 编码器参数 -->
      <encoder>
        <type>incremental</type>
        <resolution>2048</resolution>
        <noiseSigma>0.001</noiseSigma>
        <updateRate>1000</updateRate>
      </encoder>
    </actuator>
    <joint name="fr_caster_r_wheel_joint"/>
  </transmission>
  
  <!-- 传感器：IMU（可选，用于姿态估计） -->
  <link name="fr_imu_link">
    <inertial>
      <mass value="0.1"/>
      <origin xyz="0 0 0"/>
      <inertia ixx="0.001" ixy="0" ixz="0" iyy="0.001" iyz="0" izz="0.001"/>
    </inertial>
    <visual>
      <origin rpy="0 0 0" xyz="0 0 0"/>
      <geometry>
        <box size="0.02 0.02 0.01"/>
      </geometry>
      <material name="imu">
        <color rgba="0.8 0.2 0.2 1.0"/> <!-- 红色 -->
      </material>
    </visual>
  </link>
  
  <joint name="fr_imu_joint" type="fixed">
    <parent link="fr_caster_rotation_link"/>
    <child link="fr_imu_link"/>
    <origin rpy="0 0 0" xyz="0 0 0.1"/>
  </joint>


<!-- 左后轮-->
  <joint name="bl_caster_rotation_joint" type="continuous">
    <axis xyz="0 0 1"/>
    <limit effort="6.5" velocity="10"/>
    <safety_controller k_velocity="10"/>
    <calibration rising="-0.785398163397"/>
    <dynamics damping="1.0" friction="0.0"/>
    <origin rpy="0 0 0" xyz="0.1 0.5 0"/>
    <parent link="chassis"/>
    <child link="bl_caster_rotation_link"/>
  </joint>
  
  <link name="bl_caster_rotation_link">
    <inertial>
      <mass value="3.473082"/>
      <origin xyz="0 0 0.07"/>
      <inertia ixx="0.012411765597" ixy="-0.000711733678" ixz="0.00050272983" iyy="0.015218160428" iyz="-0.000004273467" izz="0.011763977943"/>
    </inertial>
    <visual>
      <origin rpy="0 0 0" xyz="0 0 0"/>
      <geometry>
        <mesh filename="../meshes/caster.obj"/>
      </geometry>
    </visual>
    <collision>
      <origin rpy="0 0 0" xyz="0 0 0"/>
      <geometry>
        <mesh filename="../meshes/caster_L.obj"/>
      </geometry>
    </collision>
  </link>
  
  <transmission name="bl_caster_rotation_trans" type="transmission_interface/SimpleTransmission">
    <actuator name="bl_caster_rotation_motor">
      <hardwareInterface>hardware_interface/PositionJointInterface</hardwareInterface>
      <mechanicalReduction>-79.2380952381</mechanicalReduction>
      <electricalMotor>
        <type>DC</type>           <!-- 直流电机 -->
        <nominalVoltage>24.0</nominalVoltage>  <!-- 额定电压(V) -->
        <stallTorque>12.0</stallTorque>        <!-- 堵转扭矩(N·m) -->
        <freeSpeed>3000.0</freeSpeed>          <!-- 空载转速(RPM) -->
        <efficiency>0.85</efficiency>          <!-- 效率 -->
      </electricalMotor>
    </actuator>
    <joint name="bl_caster_rotation_joint"/>
  </transmission>
  
  <joint name="bl_caster_l_wheel_joint" type="continuous">
    <axis xyz="0 1 0"/>
    <limit effort="7" velocity="15"/>
    <safety_controller k_velocity="10"/>
    <dynamics damping="1.0" friction="0.0"/>
    <origin rpy="0 0 0" xyz="0 0.049 0"/>
    <parent link="bl_caster_rotation_link"/>
    <child link="bl_caster_l_wheel_link"/>
  </joint>
  
  <link name="bl_caster_l_wheel_link">
    <inertial>
      <mass value="0.44036"/>
      <origin xyz="0 0 0"/>
      <inertia ixx="0.012411765597" ixy="-0.000711733678" ixz="0.00050272983" iyy="0.015218160428" iyz="-0.000004273467" izz="0.011763977943"/>
    </inertial>
    <visual>
      <origin rpy="3.14 0 0" xyz="0 0 0"/>
      <geometry>
        <mesh filename="../meshes/wheel.obj"/>
      </geometry>
      <material name="wheel_tire">
        <color rgba="0.1 0.1 0.1 1.0"/> <!-- 黑色轮胎 -->
      </material>
    </visual>
    <collision>
      <origin rpy="1.57079632679 0 0" xyz="0 0 0"/>
      <geometry>
        <!-- <cylinder length="0.134" radius="0.074792"/> -->
        <mesh filename="../meshes/wheel.obj"/>
      </geometry>
    </collision>
  </link>
  
  <transmission name="bl_caster_l_wheel_trans" type="transmission_interface/SimpleTransmission">
    <actuator name="bl_caster_l_wheel_motor">
      <hardwareInterface>hardware_interface/VelocityJointInterface</hardwareInterface>
      <mechanicalReduction>79.2380952381</mechanicalReduction>
      <electricalMotor>
        <type>DC</type>
        <nominalVoltage>24.0</nominalVoltage>
        <stallTorque>15.0</stallTorque>
        <freeSpeed>4000.0</freeSpeed>
        <efficiency>0.88</efficiency>
      </electricalMotor>
      <!-- 编码器参数 -->
      <encoder>
        <type>incremental</type> <!-- 增量式编码器 -->
        <resolution>2048</resolution> <!-- 每转脉冲数 -->
        <noiseSigma>0.001</noiseSigma> <!-- 噪声标准差 -->
        <updateRate>1000</updateRate> <!-- 更新频率(Hz) -->
      </encoder>
    </actuator>
    <joint name="bl_caster_l_wheel_joint"/>
  </transmission>
  
  <joint name="bl_caster_r_wheel_joint" type="continuous">
    <axis xyz="0 1 0"/>
    <limit effort="7" velocity="15"/>
    <safety_controller k_velocity="10"/>
    <dynamics damping="1.0" friction="0.0"/>
    <origin rpy="0 0 0" xyz="0 -0.049 0"/>
    <parent link="bl_caster_rotation_link"/>
    <child link="bl_caster_r_wheel_link"/>
  </joint>
  
  <link name="bl_caster_r_wheel_link">
    <inertial>
      <mass value="0.44036"/>
      <origin xyz="0 0 0"/>
      <inertia ixx="0.012411765597" ixy="-0.000711733678" ixz="0.00050272983" iyy="0.015218160428" iyz="-0.000004273467" izz="0.011763977943"/>
    </inertial>
    <visual>
      <origin rpy="0 0 0" xyz="0 0 0"/>
      <geometry>
        <mesh filename="../meshes/wheel.obj"/>
      </geometry>
      <material name="wheel_tire">
        <color rgba="0.1 0.1 0.1 1.0"/> <!-- 黑色轮胎 -->
      </material>
    </visual>
    <collision>
      <origin rpy="1.57079632679 0 0" xyz="0 0 0"/>
      <geometry>
        <!-- <cylinder length="0.134" radius="0.074792"/> -->
        <mesh filename="../meshes/wheel.obj"/>
      </geometry>
    </collision>
  </link>
  
  <transmission name="bl_caster_r_wheel_trans" type="transmission_interface/SimpleTransmission">
    <actuator name="bl_caster_r_wheel_motor">
      <hardwareInterface>hardware_interface/VelocityJointInterface</hardwareInterface>
      <mechanicalReduction>-79.2380952381</mechanicalReduction>
      <electricalMotor>
        <type>DC</type>
        <nominalVoltage>24.0</nominalVoltage>
        <stallTorque>15.0</stallTorque>
        <freeSpeed>4000.0</freeSpeed>
        <efficiency>0.88</efficiency>
      </electricalMotor>
      <!-- 编码器参数 -->
      <encoder>
        <type>incremental</type>
        <resolution>2048</resolution>
        <noiseSigma>0.001</noiseSigma>
        <updateRate>1000</updateRate>
      </encoder>
    </actuator>
    <joint name="bl_caster_r_wheel_joint"/>
  </transmission>
  
  <!-- 传感器：IMU（可选，用于姿态估计） -->
  <link name="bl_imu_link">
    <inertial>
      <mass value="0.1"/>
      <origin xyz="0 0 0"/>
      <inertia ixx="0.001" ixy="0" ixz="0" iyy="0.001" iyz="0" izz="0.001"/>
    </inertial>
    <visual>
      <origin rpy="0 0 0" xyz="0 0 0"/>
      <geometry>
        <box size="0.02 0.02 0.01"/>
      </geometry>
      <material name="imu">
        <color rgba="0.8 0.2 0.2 1.0"/> <!-- 红色 -->
      </material>
    </visual>
  </link>
  
  <joint name="bl_imu_joint" type="fixed">
    <parent link="bl_caster_rotation_link"/>
    <child link="bl_imu_link"/>
    <origin rpy="0 0 0" xyz="0 0 0.1"/>
  </joint>


  <!-- 右后轮-->
  <joint name="br_caster_rotation_joint" type="continuous">
    <axis xyz="0 0 1"/>
    <limit effort="6.5" velocity="10"/>
    <safety_controller k_velocity="10"/>
    <calibration rising="-0.785398163397"/>
    <dynamics damping="1.0" friction="0.0"/>
    <origin rpy="0 0 0" xyz="0.1 0.1 0"/>
    <parent link="chassis"/>
    <child link="br_caster_rotation_link"/>
  </joint>
  
  <link name="br_caster_rotation_link">
    <inertial>
      <mass value="3.473082"/>
      <origin xyz="0 0 0.07"/>
      <inertia ixx="0.012411765597" ixy="-0.000711733678" ixz="0.00050272983" iyy="0.015218160428" iyz="-0.000004273467" izz="0.011763977943"/>
    </inertial>
    <visual>
      <origin rpy="0 0 0" xyz="0 0 0"/>
      <geometry>
        <mesh filename="../meshes/caster.obj"/>
      </geometry>
    </visual>
    <collision>
      <origin rpy="0 0 0" xyz="0 0 0"/>
      <geometry>
        <mesh filename="../meshes/caster_L.obj"/>
      </geometry>
    </collision>
  </link>
  
  <transmission name="br_caster_rotation_trans" type="transmission_interface/SimpleTransmission">
    <actuator name="br_caster_rotation_motor">
      <hardwareInterface>hardware_interface/PositionJointInterface</hardwareInterface>
      <mechanicalReduction>-79.2380952381</mechanicalReduction>
      <electricalMotor>
        <type>DC</type>           <!-- 直流电机 -->
        <nominalVoltage>24.0</nominalVoltage>  <!-- 额定电压(V) -->
        <stallTorque>12.0</stallTorque>        <!-- 堵转扭矩(N·m) -->
        <freeSpeed>3000.0</freeSpeed>          <!-- 空载转速(RPM) -->
        <efficiency>0.85</efficiency>          <!-- 效率 -->
      </electricalMotor>
    </actuator>
    <joint name="br_caster_rotation_joint"/>
  </transmission>
  
  <joint name="br_caster_l_wheel_joint" type="continuous">
    <axis xyz="0 1 0"/>
    <limit effort="7" velocity="15"/>
    <safety_controller k_velocity="10"/>
    <dynamics damping="1.0" friction="0.0"/>
    <origin rpy="0 0 0" xyz="0 0.049 0"/>
    <parent link="br_caster_rotation_link"/>
    <child link="br_caster_l_wheel_link"/>
  </joint>
  
  <link name="br_caster_l_wheel_link">
    <inertial>
      <mass value="0.44036"/>
      <origin xyz="0 0 0"/>
      <inertia ixx="0.012411765597" ixy="-0.000711733678" ixz="0.00050272983" iyy="0.015218160428" iyz="-0.000004273467" izz="0.011763977943"/>
    </inertial>
    <visual>
      <origin rpy="3.14 0 0" xyz="0 0 0"/>
      <geometry>
        <mesh filename="../meshes/wheel.obj"/>
      </geometry>
      <material name="wheel_tire">
        <color rgba="0.1 0.1 0.1 1.0"/> <!-- 黑色轮胎 -->
      </material>
    </visual>
    <collision>
      <origin rpy="1.57079632679 0 0" xyz="0 0 0"/>
      <geometry>
        <!-- <cylinder length="0.134" radius="0.074792"/> -->
        <mesh filename="../meshes/wheel.obj"/>
      </geometry>
    </collision>
  </link>
  
  <transmission name="br_caster_l_wheel_trans" type="transmission_interface/SimpleTransmission">
    <actuator name="br_caster_l_wheel_motor">
      <hardwareInterface>hardware_interface/VelocityJointInterface</hardwareInterface>
      <mechanicalReduction>79.2380952381</mechanicalReduction>
      <electricalMotor>
        <type>DC</type>
        <nominalVoltage>24.0</nominalVoltage>
        <stallTorque>15.0</stallTorque>
        <freeSpeed>4000.0</freeSpeed>
        <efficiency>0.88</efficiency>
      </electricalMotor>
      <!-- 编码器参数 -->
      <encoder>
        <type>incremental</type> <!-- 增量式编码器 -->
        <resolution>2048</resolution> <!-- 每转脉冲数 -->
        <noiseSigma>0.001</noiseSigma> <!-- 噪声标准差 -->
        <updateRate>1000</updateRate> <!-- 更新频率(Hz) -->
      </encoder>
    </actuator>
    <joint name="br_caster_l_wheel_joint"/>
  </transmission>
  
  <joint name="br_caster_r_wheel_joint" type="continuous">
    <axis xyz="0 1 0"/>
    <limit effort="7" velocity="15"/>
    <safety_controller k_velocity="10"/>
    <dynamics damping="1.0" friction="0.0"/>
    <origin rpy="0 0 0" xyz="0 -0.049 0"/>
    <parent link="br_caster_rotation_link"/>
    <child link="br_caster_r_wheel_link"/>
  </joint>
  
  <link name="br_caster_r_wheel_link">
    <inertial>
      <mass value="0.44036"/>
      <origin xyz="0 0 0"/>
      <inertia ixx="0.012411765597" ixy="-0.000711733678" ixz="0.00050272983" iyy="0.015218160428" iyz="-0.000004273467" izz="0.011763977943"/>
    </inertial>
    <visual>
      <origin rpy="0 0 0" xyz="0 0 0"/>
      <geometry>
        <mesh filename="../meshes/wheel.obj"/>
      </geometry>
      <material name="wheel_tire">
        <color rgba="0.1 0.1 0.1 1.0"/> <!-- 黑色轮胎 -->
      </material>
    </visual>
    <collision>
      <origin rpy="1.57079632679 0 0" xyz="0 0 0"/>
      <geometry>
        <!-- <cylinder length="0.134" radius="0.074792"/> -->
        <mesh filename="../meshes/wheel.obj"/>
      </geometry>
    </collision>
  </link>
  
  <transmission name="br_caster_r_wheel_trans" type="transmission_interface/SimpleTransmission">
    <actuator name="br_caster_r_wheel_motor">
      <hardwareInterface>hardware_interface/VelocityJointInterface</hardwareInterface>
      <mechanicalReduction>-79.2380952381</mechanicalReduction>
      <electricalMotor>
        <type>DC</type>
        <nominalVoltage>24.0</nominalVoltage>
        <stallTorque>15.0</stallTorque>
        <freeSpeed>4000.0</freeSpeed>
        <efficiency>0.88</efficiency>
      </electricalMotor>
      <!-- 编码器参数 -->
      <encoder>
        <type>incremental</type>
        <resolution>2048</resolution>
        <noiseSigma>0.001</noiseSigma>
        <updateRate>1000</updateRate>
      </encoder>
    </actuator>
    <joint name="br_caster_r_wheel_joint"/>
  </transmission>
  
  <!-- 传感器：IMU（可选，用于姿态估计） -->
  <link name="br_imu_link">
    <inertial>
      <mass value="0.1"/>
      <origin xyz="0 0 0"/>
      <inertia ixx="0.001" ixy="0" ixz="0" iyy="0.001" iyz="0" izz="0.001"/>
    </inertial>
    <visual>
      <origin rpy="0 0 0" xyz="0 0 0"/>
      <geometry>
        <box size="0.02 0.02 0.01"/>
      </geometry>
      <material name="imu">
        <color rgba="0.8 0.2 0.2 1.0"/> <!-- 红色 -->
      </material>
    </visual>
  </link>
  
  <joint name="br_imu_joint" type="fixed">
    <parent link="br_caster_rotation_link"/>
    <child link="br_imu_link"/>
    <origin rpy="0 0 0" xyz="0 0 0.1"/>
  </joint>
</robot>