#VRML_SIM R2025a utf8
# license: Apache License 2.0
# license url: http://www.apache.org/licenses/LICENSE-2.0
# This is a proto file for Webots for the urdf_arm
# Extracted from: /home/luocl/Desktop/webots_flask_server_http/Webots_PR2_Path_Planning/protos/urdf_arm_mix/urdf/urdf_arm_mix.urdf

PROTO urdf_arm [
  field  SFVec3f     translation     0 0 0
  field  SFRotation  rotation        0 0 1 0
  field  SFString    name            "urdf_arm"  # Is `Robot.name`.
  field  SFString    controller      "void"      # Is `Robot.controller`.
  field  MFString    controllerArgs  []          # Is `Robot.controllerArgs`.
  field  SFString    customData      ""          # Is `Robot.customData`.
  field  SFBool      supervisor      FALSE       # Is `Robot.supervisor`.
  field  SFBool      synchronization TRUE        # Is `Robot.synchronization`.
  field  SFBool      selfCollision   FALSE       # Is `Robot.selfCollision`.
  field MFNode     extensionSlot1  []          # CUSTOM: adds a slot for a new device
  field MFNode     extensionSlot2  []          # CUSTOM: adds a slot for a new device
]
{
  Robot {
    translation IS translation
    rotation IS rotation
    controller IS controller
    controllerArgs IS controllerArgs
    customData IS customData
    supervisor IS supervisor
    synchronization IS synchronization
    selfCollision IS selfCollision
    children [
      DEF urdf_arm_visual CadShape {
        url "meshes_obj/urdf_arm.obj"
      }
      HingeJoint {
        jointParameters HingeJointParameters {
          axis 0.000000 1.000000 0.000000
          anchor -0.017500 0.299270 0.300000
          dampingConstant 0.2
          staticFriction 0.1
        }
        device [
          RotationalMotor {
            name "zarm_l1_joint"
            maxVelocity 41.3433333333333
            minPosition -3.14159265358979
            maxPosition 3.14
            maxTorque 100.0
          }
          PositionSensor {
            name "zarm_l1_joint_sensor"
          }
        ]
        endPoint Solid {
          translation -0.017500 0.299270 0.300000
          children [
            DEF l_arm_pitch_visual CadShape {
              url "meshes_obj/l_arm_pitch.obj"
            }
            HingeJoint {
              jointParameters HingeJointParameters {
                dampingConstant 0.2
                staticFriction 0.1
              }
              device [
                RotationalMotor {
                  name "zarm_l2_joint"
                  maxVelocity 8.37333333333333
                  minPosition -3.14
                  maxPosition 3.14
                  maxTorque 50.0
                }
                PositionSensor {
                  name "zarm_l2_joint_sensor"
                }
              ]
              endPoint Solid {
                children [
                  DEF l_arm_roll_visual CadShape {
                    url "meshes_obj/l_arm_roll.obj"
                  }
                  HingeJoint {
                    jointParameters HingeJointParameters {
                      axis 0.000000 0.000000 1.000000
                      dampingConstant 0.2
                      staticFriction 0.1
                    }
                    device [
                      RotationalMotor {
                        name "zarm_l3_joint"
                        maxVelocity 19.3633333333333
                        minPosition -3.14
                        maxPosition 3.14
                        maxTorque 39.0
                      }
                      PositionSensor {
                        name "zarm_l3_joint_sensor"
                      }
                    ]
                    endPoint Solid {
                      children [
                        DEF l_arm_yaw_visual CadShape {
                          url "meshes_obj/l_arm_yaw.obj"
                        }
                        HingeJoint {
                          jointParameters HingeJointParameters {
                            axis 0.000000 1.000000 0.000000
                            anchor 0.020000 0.000000 -0.283700
                            dampingConstant 0.2
                            staticFriction 0.1
                          }
                          device [
                            RotationalMotor {
                              name "zarm_l4_joint"
                              maxVelocity 8.37333333333333
                              minPosition -3.14
                              maxPosition 3.14
                              maxTorque 50.0
                            }
                            PositionSensor {
                              name "zarm_l4_joint_sensor"
                            }
                          ]
                          endPoint Solid {
                            translation 0.020000 0.000000 -0.283700
                            children [
                              DEF l_forearm_visual CadShape {
                                url "meshes_obj/l_forearm.obj"
                              }
                              HingeJoint {
                                jointParameters HingeJointParameters {
                                  axis 0.000000 0.000000 1.000000
                                  anchor -0.020000 0.000000 -0.127037
                                }
                                device [
                                  RotationalMotor {
                                    name "zarm_l5_joint"
                                    maxVelocity 21.666
                                    minPosition -3.14
                                    maxPosition 3.14
                                    maxTorque 12.0
                                  }
                                  PositionSensor {
                                    name "zarm_l5_joint_sensor"
                                  }
                                ]
                                endPoint Solid {
                                  translation -0.020000 0.000000 -0.127037
                                  children [
                                    DEF l_hand_yaw_visual CadShape {
                                      url "meshes_obj/l_hand_yaw.obj"
                                    }
                                    HingeJoint {
                                      jointParameters HingeJointParameters {
                                        anchor 0.000000 0.000000 -0.100000
                                        dampingConstant 0.1
                                        staticFriction 0.05
                                      }
                                      device [
                                        RotationalMotor {
                                          name "left_intermediate_joint"
                                          maxVelocity 5.0
                                          minPosition -1.57
                                          maxPosition 1.57
                                          maxTorque 10.0
                                        }
                                        PositionSensor {
                                          name "left_intermediate_joint_sensor"
                                        }
                                      ]
                                      endPoint Solid {
                                        translation 0.000000 0.000000 -0.100000
                                        children [
                                          Shape {
                                            appearance DEF left_intermediate_link_material PBRAppearance {
                                              baseColor 0.500000 0.500000 1.000000
                                              roughness 1.000000
                                              metalness 0
                                            }
                                            geometry Box {
                                               size 0.050000 0.050000 0.020000
                                            }
                                          }
                                          Solid {
                                            rotation 1.000000 0.000000 0.000000 3.140000
                                            children [
                                              DEF robotiq_85_base_link_fine_visual CadShape {
                                                url "meshes_obj/robotiq_85_base_link_fine.obj"
                                              }
                                              HingeJoint {
                                                jointParameters HingeJointParameters {
                                                  axis 0.000000 -1.000000 0.000000
                                                  anchor 0.030601 0.000000 0.062792
                                                }
                                                device [
                                                  RotationalMotor {
                                                    name "left_gripper_finger_joint"
                                                    maxVelocity 2.0
                                                    minPosition -0.7
                                                    maxPosition 0.7
                                                    maxTorque 1000.0
                                                  }
                                                  PositionSensor {
                                                    name "left_gripper_finger_joint_sensor"
                                                  }
                                                ]
                                                endPoint Solid {
                                                  translation 0.030601 0.000000 0.062792
                                                  children [
                                                    DEF outer_knuckle_fine_visual CadShape {
                                                      url "meshes_obj/outer_knuckle_fine.obj"
                                                    }
                                                    Solid {
                                                      translation 0.031691 0.000000 -0.001934
                                                      children [
                                                        DEF outer_finger_fine_visual CadShape {
                                                          url "meshes_obj/outer_finger_fine.obj"
                                                        }
                                                      ]
                                                      name "left_gripper_left_outer_finger"
                                                      boundingObject DEF outer_finger_coarse Mesh {
                                                        url "meshes_obj/outer_finger_coarse.obj"
                                                      }
                                                      physics Physics {
                                                        density -1
                                                        mass 0.027309
                                                        centerOfMass [ 0.001315 0.000000 0.021540 ]
                                                        inertiaMatrix [
                                                          8.516296e-06 6.913333e-06 2.250068e-06
                                                          2.581743e-19 3.838295e-07 -7.585899e-19
                                                        ]
                                                      }
                                                    }
                                                  ]
                                                  name "left_gripper_left_outer_knuckle"
                                                  boundingObject DEF outer_knuckle_coarse Mesh {
                                                    url "meshes_obj/outer_knuckle_coarse.obj"
                                                  }
                                                  physics Physics {
                                                    density -1
                                                    mass 0.006848
                                                    centerOfMass [ 0.017833 0.000000 0.002144 ]
                                                    inertiaMatrix [
                                                      2.668320e-07 1.388923e-06 1.266033e-06
                                                      1.661423e-15 1.459456e-07 2.829512e-15
                                                    ]
                                                  }
                                                }
                                              }
                                              HingeJoint {
                                                jointParameters HingeJointParameters {
                                                  axis 0.000000 -1.000000 0.000000
                                                  anchor 0.012700 0.000000 0.069307
                                                }
                                                device [
                                                  RotationalMotor {
                                                    name "left_gripper_left_inner_knuckle_joint"
                                                    maxVelocity 2.0
                                                    minPosition -1.0
                                                    maxPosition 0.8757
                                                    maxTorque 1000.0
                                                  }
                                                  PositionSensor {
                                                    name "left_gripper_left_inner_knuckle_joint_sensor"
                                                  }
                                                ]
                                                endPoint Solid {
                                                  translation 0.012700 0.000000 0.069307
                                                  children [
                                                    DEF inner_knuckle_fine_visual CadShape {
                                                      url "meshes_obj/inner_knuckle_fine.obj"
                                                    }
                                                    HingeJoint {
                                                      jointParameters HingeJointParameters {
                                                        axis 0.000000 -1.000000 0.000000
                                                        anchor 0.034585 0.000000 0.045497
                                                      }
                                                      device [
                                                        RotationalMotor {
                                                          name "left_gripper_left_inner_finger_joint"
                                                          maxVelocity 2.0
                                                          minPosition -1.0
                                                          maxPosition 0.8757
                                                          maxTorque 1000.0
                                                        }
                                                        PositionSensor {
                                                          name "left_gripper_left_inner_finger_joint_sensor"
                                                        }
                                                      ]
                                                      endPoint Solid {
                                                        translation 0.034585 0.000000 0.045497
                                                        children [
                                                          DEF inner_finger_fine_visual CadShape {
                                                            url "meshes_obj/inner_finger_fine.obj"
                                                          }
                                                        ]
                                                        name "left_gripper_left_inner_finger"
                                                        boundingObject DEF inner_finger_coarse Mesh {
                                                          url "meshes_obj/inner_finger_coarse.obj"
                                                        }
                                                        physics Physics {
                                                          density -1
                                                          mass 0.007243
                                                          centerOfMass [ 0.006028 -0.000000 0.006699 ]
                                                          inertiaMatrix [
                                                            1.478243e-06 1.700645e-06 4.771513e-07
                                                            -3.948845e-19 -3.452688e-07 3.505984e-19
                                                          ]
                                                        }
                                                      }
                                                    }
                                                  ]
                                                  name "left_gripper_left_inner_knuckle"
                                                  boundingObject DEF inner_knuckle_coarse Mesh {
                                                    url "meshes_obj/inner_knuckle_coarse.obj"
                                                  }
                                                  physics Physics {
                                                    density -1
                                                    mass 0.011093
                                                    centerOfMass [ 0.017098 -0.000000 0.022492 ]
                                                    inertiaMatrix [
                                                      4.233928e-06 3.965488e-06 3.240680e-06
                                                      5.748979e-15 1.788557e-06 1.054647e-14
                                                    ]
                                                  }
                                                }
                                              }
                                              HingeJoint {
                                                jointParameters HingeJointParameters {
                                                  axis -0.000000 -1.000000 0.000000
                                                  anchor -0.012700 0.000000 0.069308
                                                }
                                                device [
                                                  RotationalMotor {
                                                    name "left_gripper_right_inner_knuckle_joint"
                                                    maxVelocity 2.0
                                                    minPosition -1.0
                                                    maxPosition 0.8757
                                                    maxTorque 1000.0
                                                  }
                                                  PositionSensor {
                                                    name "left_gripper_right_inner_knuckle_joint_sensor"
                                                  }
                                                ]
                                                endPoint Solid {
                                                  translation -0.012700 0.000000 0.069308
                                                  rotation 0.000000 0.000000 1.000000 3.141593
                                                  children [
                                                    USE inner_knuckle_fine_visual
                                                    HingeJoint {
                                                      jointParameters HingeJointParameters {
                                                        axis 0.000000 1.000000 0.000000
                                                        anchor 0.034106 0.000000 0.045857
                                                      }
                                                      device [
                                                        RotationalMotor {
                                                          name "left_gripper_right_inner_finger_joint"
                                                          maxVelocity 2.0
                                                          minPosition -1.0
                                                          maxPosition 0.8757
                                                          maxTorque 1000.0
                                                        }
                                                        PositionSensor {
                                                          name "left_gripper_right_inner_finger_joint_sensor"
                                                        }
                                                      ]
                                                      endPoint Solid {
                                                        translation 0.034106 0.000000 0.045857
                                                        children [
                                                          USE inner_finger_fine_visual
                                                          # ===== 新增：左手真空吸盘 =====
                                                          VacuumGripper {
                                                            translation 0 0.000 0.03  # 与右手位置对称
                                                            rotation 0 0 1 0               
                                                            name "left_gripper_vacuum"  # 名称区分右手
                                                            isOn FALSE
                                                            tensileStrength -1       
                                                            shearStrength -1                
                                                            contactPoints 1               
                                                            children [
                                                              Shape {
                                                                appearance USE SUCTION_APPEARANCE  # 复用右手的外观定义
                                                                geometry Cylinder {
                                                                  height 0.05
                                                                  radius 0.01
                                                                }
                                                              }
                                                            ]
                                                            boundingObject Cylinder {
                                                              height 0.005
                                                              radius 0.008
                                                            }
                                                          }
                                                          # ==============================
                                                        ]
                                                        name "left_gripper_right_inner_finger"
                                                        boundingObject USE inner_finger_coarse
                                                        physics Physics {
                                                          density -1
                                                          mass 0.007243
                                                          centerOfMass [ 0.006028 -0.000000 0.006699 ]
                                                          inertiaMatrix [
                                                            1.478243e-06 1.700645e-06 4.771512e-07
                                                            -3.959521e-19 -3.452687e-07 3.552865e-19
                                                          ]
                                                        }
                                                      }
                                                    }
                                                  ]
                                                  name "left_gripper_right_inner_knuckle"
                                                  boundingObject USE inner_knuckle_coarse
                                                  physics Physics {
                                                    density -1
                                                    mass 0.011093
                                                    centerOfMass [ 0.016861 0.000000 0.022670 ]
                                                    inertiaMatrix [
                                                      4.271348e-06 3.965488e-06 3.203260e-06
                                                      -8.535685e-15 1.777742e-06 -8.451080e-15
                                                    ]
                                                  }
                                                }
                                              }
                                              HingeJoint {
                                                jointParameters HingeJointParameters {
                                                  axis -0.000000 -1.000000 0.000000
                                                  anchor -0.030601 0.000000 0.062792
                                                }
                                                device [
                                                  RotationalMotor {
                                                    name "left_gripper_right_outer_knuckle_joint"
                                                    maxVelocity 2.0
                                                    minPosition -1.0
                                                    maxPosition 0.8757
                                                    maxTorque 1000.0
                                                  }
                                                  PositionSensor {
                                                    name "left_gripper_right_outer_knuckle_joint_sensor"
                                                  }
                                                ]
                                                endPoint Solid {
                                                  translation -0.030601 0.000000 0.062792
                                                  rotation 0.000000 0.000000 1.000000 3.141593
                                                  children [
                                                    USE outer_knuckle_fine_visual
                                                    Solid {
                                                      translation 0.031710 0.000000 -0.001601
                                                      children [
                                                        USE outer_finger_fine_visual
                                                      ]
                                                      name "left_gripper_right_outer_finger"
                                                      boundingObject USE outer_finger_coarse
                                                      physics Physics {
                                                        density -1
                                                        mass 0.027309
                                                        centerOfMass [ 0.001088 -0.000000 0.021553 ]
                                                        inertiaMatrix [
                                                          8.523660e-06 6.913333e-06 2.242704e-06
                                                          3.416834e-19 3.180037e-07 7.377267e-19
                                                        ]
                                                      }
                                                    }
                                                  ]
                                                  name "left_gripper_right_outer_knuckle"
                                                  boundingObject USE outer_knuckle_coarse
                                                  physics Physics {
                                                    density -1
                                                    mass 0.006848
                                                    centerOfMass [ 0.017810 0.000000 0.002331 ]
                                                    inertiaMatrix [
                                                      2.700044e-07 1.388923e-06 1.262861e-06
                                                      1.595795e-15 1.563965e-07 2.823578e-15
                                                    ]
                                                  }
                                                }
                                              }
                                            ]
                                            name "left_gripper_robotiq_85_base_link"
                                            boundingObject DEF robotiq_85_base_link_coarse Mesh {
                                              url "meshes_obj/robotiq_85_base_link_coarse.obj"
                                            }
                                            physics Physics {
                                              density -1
                                              mass 0.309150
                                              centerOfMass [ 0.000220 -0.000000 0.030163 ]
                                              inertiaMatrix [
                                                2.897200e-04 3.073700e-04 1.991400e-04
                                                -5.787900e-10 -1.854300e-06 1.682000e-12
                                              ]
                                            }
                                          }
                                        ]
                                        name "left_intermediate_link"
                                        boundingObject Box {
                                           size 0.050000 0.050000 0.020000
                                        }
                                        physics Physics {
                                          density -1
                                          mass 0.100000
                                          centerOfMass [ 0.000000 0.000000 0.000000 ]
                                          inertiaMatrix [
                                            5.000000e-04 5.000000e-04 1.000000e-04
                                            0.000000e+00 0.000000e+00 0.000000e+00
                                          ]
                                        }
                                      }
                                    }
                                  ]
                                  name "zarm_l5_link"
                                  physics Physics {
                                    density -1
                                    mass 0.610000
                                    centerOfMass [ -0.002070 0.000180 -0.050790 ]
                                    inertiaMatrix [
                                      1.070000e-03 1.460000e-03 8.300000e-04
                                      0.000000e+00 -4.000000e-05 0.000000e+00
                                    ]
                                  }
                                }
                              }
                            ]
                            name "zarm_l4_link"
                            physics Physics {
                              density -1
                              mass 0.429000
                              centerOfMass [ -0.016110 0.001430 -0.048570 ]
                              inertiaMatrix [
                                1.350000e-03 1.140000e-03 8.300000e-04
                                0.000000e+00 -1.000000e-04 0.000000e+00
                              ]
                            }
                          }
                        }
                      ]
                      name "zarm_l3_link"
                      physics Physics {
                        density -1
                        mass 1.650000
                        centerOfMass [ 0.006280 0.001070 -0.208780 ]
                        inertiaMatrix [
                          8.150000e-03 8.280000e-03 2.060000e-03
                          -4.000000e-05 8.500000e-04 1.400000e-04
                        ]
                      }
                    }
                  }
                ]
                name "zarm_l2_link"
                physics Physics {
                  density -1
                  mass 0.570000
                  centerOfMass [ -0.007910 0.000000 -0.046550 ]
                  inertiaMatrix [
                    1.630000e-03 2.110000e-03 1.220000e-03
                    0.000000e+00 5.000000e-05 0.000000e+00
                  ]
                }
              }
            }
          ]
          name "zarm_l1_link"
          physics Physics {
            density -1
            mass 0.962000
            centerOfMass [ 0.000000 0.000000 0.000000 ]
            inertiaMatrix [
              2.250000e-03 9.900000e-04 2.270000e-03
              -3.000000e-05 0.000000e+00 -2.000000e-05
            ]
          }
        }
      }
      HingeJoint {
        jointParameters HingeJointParameters {
          axis 0.000000 1.000000 0.000000
          anchor -0.017500 -0.299270 0.300000
          dampingConstant 0.2
          staticFriction 0.1
        }
        device [
          RotationalMotor {
            name "zarm_r1_joint"
            maxVelocity 41.3433333333333
            minPosition -3.14159265358979
            maxPosition 3.14
            maxTorque 100.0
          }
          PositionSensor {
            name "zarm_r1_joint_sensor"
          }
        ]
        endPoint Solid {
          translation -0.017500 -0.299270 0.300000
          children [
            DEF r_arm_pitch_visual CadShape {
              url "meshes_obj/r_arm_pitch.obj"
            }
            HingeJoint {
              jointParameters HingeJointParameters {
                dampingConstant 0.2
                staticFriction 0.1
              }
              device [
                RotationalMotor {
                  name "zarm_r2_joint"
                  maxVelocity 8.37333333333333
                  minPosition -3.14
                  maxPosition 3.14
                  maxTorque 50.0
                }
                PositionSensor {
                  name "zarm_r2_joint_sensor"
                }
              ]
              endPoint Solid {
                children [
                  DEF r_arm_roll_visual CadShape {
                    url "meshes_obj/r_arm_roll.obj"
                  }
                  HingeJoint {
                    jointParameters HingeJointParameters {
                      axis 0.000000 0.000000 1.000000
                      dampingConstant 0.2
                      staticFriction 0.1
                    }
                    device [
                      RotationalMotor {
                        name "zarm_r3_joint"
                        maxVelocity 19.3633333333333
                        minPosition -3.14
                        maxPosition 3.14
                        maxTorque 39.0
                      }
                      PositionSensor {
                        name "zarm_r3_joint_sensor"
                      }
                    ]
                    endPoint Solid {
                      children [
                        DEF r_arm_yaw_visual CadShape {
                          url "meshes_obj/r_arm_yaw.obj"
                        }
                        HingeJoint {
                          jointParameters HingeJointParameters {
                            axis 0.000000 1.000000 0.000000
                            anchor 0.020000 0.000000 -0.283700
                            dampingConstant 0.2
                            staticFriction 0.1
                          }
                          device [
                            RotationalMotor {
                              name "zarm_r4_joint"
                              maxVelocity 8.37333333333333
                              minPosition -3.14
                              maxPosition 3.14
                              maxTorque 50.0
                            }
                            PositionSensor {
                              name "zarm_r4_joint_sensor"
                            }
                          ]
                          endPoint Solid {
                            translation 0.020000 0.000000 -0.283700
                            children [
                              DEF r_forearm_visual CadShape {
                                url "meshes_obj/r_forearm.obj"
                              }
                              HingeJoint {
                                jointParameters HingeJointParameters {
                                  axis 0.000000 0.000000 1.000000
                                  anchor -0.020000 0.000000 -0.127037
                                }
                                device [
                                  RotationalMotor {
                                    name "zarm_r5_joint"
                                    maxVelocity 21.666
                                    minPosition -3.14
                                    maxPosition 3.14
                                    maxTorque 12.0
                                  }
                                  PositionSensor {
                                    name "zarm_r5_joint_sensor"
                                  }
                                ]
                                endPoint Solid {
                                  translation -0.020000 0.000000 -0.127037
                                  children [
                                    DEF r_hand_yaw_visual CadShape {
                                      url "meshes_obj/r_hand_yaw.obj"
                                    }
                                    HingeJoint {
                                      jointParameters HingeJointParameters {
                                        anchor 0.000000 0.000000 -0.100000
                                        dampingConstant 0.1
                                        staticFriction 0.05
                                      }
                                      device [
                                        RotationalMotor {
                                          name "right_intermediate_joint"
                                          maxVelocity 5.0
                                          minPosition -1.57
                                          maxPosition 1.57
                                          maxTorque 10.0
                                        }
                                        PositionSensor {
                                          name "right_intermediate_joint_sensor"
                                        }
                                      ]
                                      endPoint Solid {
                                        translation 0.000000 0.000000 -0.100000
                                        children [
                                          Shape {
                                            appearance DEF right_intermediate_link_material PBRAppearance {
                                              baseColor 0.500000 0.500000 1.000000
                                              roughness 1.000000
                                              metalness 0
                                            }
                                            geometry Box {
                                               size 0.050000 0.050000 0.020000
                                            }
                                          }
                                          Solid {
                                            rotation 1.000000 0.000000 0.000000 3.140000
                                            children [
                                              USE robotiq_85_base_link_fine_visual
                                              HingeJoint {
                                                jointParameters HingeJointParameters {
                                                  axis 0.000000 -1.000000 0.000000
                                                  anchor 0.030601 0.000000 0.062792
                                                }
                                                device [
                                                  RotationalMotor {
                                                    name "right_gripper_finger_joint"
                                                    maxVelocity 2.0
                                                    minPosition -1.0
                                                    maxPosition 1.0
                                                    maxTorque 1000.0
                                                  }
                                                  PositionSensor {
                                                    name "right_gripper_finger_joint_sensor"
                                                  }
                                                ]
                                                endPoint Solid {
                                                  translation 0.030601 0.000000 0.062792
                                                  children [
                                                    USE outer_knuckle_fine_visual
                                                    Solid {
                                                      translation 0.031691 0.000000 -0.001934
                                                      children [
                                                        USE outer_finger_fine_visual
                                                      ]
                                                      name "right_gripper_left_outer_finger"
                                                      boundingObject USE outer_finger_coarse
                                                      physics Physics {
                                                        density -1
                                                        mass 0.027309
                                                        centerOfMass [ 0.001315 0.000000 0.021540 ]
                                                        inertiaMatrix [
                                                          8.516296e-06 6.913333e-06 2.250068e-06
                                                          2.581743e-19 3.838295e-07 -7.585899e-19
                                                        ]
                                                      }
                                                    }
                                                  ]
                                                  name "right_gripper_left_outer_knuckle"
                                                  boundingObject USE outer_knuckle_coarse
                                                  physics Physics {
                                                    density -1
                                                    mass 0.006848
                                                    centerOfMass [ 0.017833 0.000000 0.002144 ]
                                                    inertiaMatrix [
                                                      2.668320e-07 1.388923e-06 1.266033e-06
                                                      1.661423e-15 1.459456e-07 2.829512e-15
                                                    ]
                                                  }
                                                }
                                              }
                                              HingeJoint {
                                                jointParameters HingeJointParameters {
                                                  axis 0.000000 -1.000000 0.000000
                                                  anchor 0.012700 0.000000 0.069307
                                                }
                                                device [
                                                  RotationalMotor {
                                                    name "right_gripper_left_inner_knuckle_joint"
                                                    maxVelocity 2.0
                                                    minPosition -1.0
                                                    maxPosition 0.8757
                                                    maxTorque 1000.0
                                                  }
                                                  PositionSensor {
                                                    name "right_gripper_left_inner_knuckle_joint_sensor"
                                                  }
                                                ]
                                                endPoint Solid {
                                                  translation 0.012700 0.000000 0.069307
                                                  children [
                                                    USE inner_knuckle_fine_visual
                                                    HingeJoint {
                                                      jointParameters HingeJointParameters {
                                                        axis 0.000000 -1.000000 0.000000
                                                        anchor 0.034585 0.000000 0.045497
                                                      }
                                                      device [
                                                        RotationalMotor {
                                                          name "right_gripper_left_inner_finger_joint"
                                                          maxVelocity 2.0
                                                          minPosition -1.0
                                                          maxPosition 0.8757
                                                          maxTorque 1000.0
                                                        }
                                                        PositionSensor {
                                                          name "right_gripper_left_inner_finger_joint_sensor"
                                                        }
                                                      ]
                                                      endPoint Solid {
                                                        translation 0.034585 0.000000 0.045497
                                                        children [
                                                          USE inner_finger_fine_visual
                                                        ]
                                                        name "right_gripper_left_inner_finger"
                                                        boundingObject USE inner_finger_coarse
                                                        physics Physics {
                                                          density -1
                                                          mass 0.007243
                                                          centerOfMass [ 0.006028 -0.000000 0.006699 ]
                                                          inertiaMatrix [
                                                            1.478243e-06 1.700645e-06 4.771513e-07
                                                            -3.948845e-19 -3.452688e-07 3.505984e-19
                                                          ]
                                                        }
                                                      }
                                                    }
                                                  ]
                                                  name "right_gripper_left_inner_knuckle"
                                                  boundingObject USE inner_knuckle_coarse
                                                  physics Physics {
                                                    density -1
                                                    mass 0.011093
                                                    centerOfMass [ 0.017098 -0.000000 0.022492 ]
                                                    inertiaMatrix [
                                                      4.233928e-06 3.965488e-06 3.240680e-06
                                                      5.748979e-15 1.788557e-06 1.054647e-14
                                                    ]
                                                  }
                                                }
                                              }
                                              HingeJoint {
                                                jointParameters HingeJointParameters {
                                                  axis -0.000000 -1.000000 0.000000
                                                  anchor -0.012700 0.000000 0.069308
                                                }
                                                device [
                                                  RotationalMotor {
                                                    name "right_gripper_right_inner_knuckle_joint"
                                                    maxVelocity 2.0
                                                    minPosition -1.0
                                                    maxPosition 0.8757
                                                    maxTorque 1000.0
                                                  }
                                                  PositionSensor {
                                                    name "right_gripper_right_inner_knuckle_joint_sensor"
                                                  }
                                                ]
                                                endPoint Solid {
                                                  translation -0.012700 0.000000 0.069308
                                                  rotation 0.000000 0.000000 1.000000 3.141593
                                                  children [
                                                    USE inner_knuckle_fine_visual
                                                    HingeJoint {
                                                      jointParameters HingeJointParameters {
                                                        axis 0.000000 1.000000 0.000000
                                                        anchor 0.034106 0.000000 0.045857
                                                      }
                                                      device [
                                                        RotationalMotor {
                                                          name "right_gripper_right_inner_finger_joint"
                                                          maxVelocity 2.0
                                                          minPosition -1.0
                                                          maxPosition 0.8757
                                                          maxTorque 1000.0
                                                        }
                                                        PositionSensor {
                                                          name "right_gripper_right_inner_finger_joint_sensor"
                                                        }
                                                      ]
                                                      endPoint Solid {
                                                        translation 0.034106 0.000000 0.045857
                                                        children [
                                                          USE inner_finger_fine_visual
                                                          # ===== 正确位置：添加在 endPoint Solid 的 children 中 =====
                                                          VacuumGripper {
                                                            translation 0 0.000 0.03
                                                            rotation 0 0 1 0               
                                                            name "right_gripper_vacuum"
                                                            isOn FALSE
                                                            tensileStrength -1       
                                                            shearStrength -1                
                                                            contactPoints 1               
                                                            children [
                                                              Shape {
                                                                appearance DEF SUCTION_APPEARANCE PBRAppearance {
                                                                  baseColor 0.2 0.2 0.8
                                                                  roughness 0.4
                                                                  metalness 0.6
                                                                }
                                                                geometry Cylinder {
                                                                  height 0.05
                                                                  radius 0.01
                                                                }
                                                              }
                                                            ]
                                                            boundingObject Cylinder {
                                                              height 0.005
                                                              radius 0.008
                                                            }
                                                          }
                                                          # ===================================================
                                                          # ===== 修改后的触摸传感器（覆盖整个手指） =====
                                                          TouchSensor {
                                                            name "right_suction_touch_sensor"
                                                            children [
                                                              Shape {
                                                                appearance PBRAppearance {
                                                                  baseColor 0.8 0.2 0.2  # 红色便于可视化（调试用）
                                                                  transparency 0.5       # 半透明
                                                                }
                                                                # 使用Box或其他形状覆盖手指区域
                                                                geometry Box {
                                                                  size 0.01 0.03 0.01  # 根据手指尺寸调整
                                                                }
                                                              }
                                                            ]
                                                            # 关键：使用与可视化形状相同的boundingObject
                                                            boundingObject Box {
                                                              size 0.01 0.03 0.01  # 与上面的Box尺寸一致
                                                            }
                                                          }
                                                          # ============================================
                                                        ]
                                                        name "right_gripper_right_inner_finger"
                                                        boundingObject USE inner_finger_coarse
                                                        physics Physics {
                                                          density -1
                                                          mass 0.007243
                                                          centerOfMass [ 0.006028 -0.000000 0.006699 ]
                                                          inertiaMatrix [
                                                            1.478243e-06 1.700645e-06 4.771512e-07
                                                            -3.959521e-19 -3.452687e-07 3.552865e-19
                                                          ]
                                                        }
                                                      }
                                                    }
                                                  ]
                                                  name "right_gripper_right_inner_knuckle"
                                                  boundingObject USE inner_knuckle_coarse
                                                  physics Physics {
                                                    density -1
                                                    mass 0.011093
                                                    centerOfMass [ 0.016861 0.000000 0.022670 ]
                                                    inertiaMatrix [
                                                      4.271348e-06 3.965488e-06 3.203260e-06
                                                      -8.535685e-15 1.777742e-06 -8.451080e-15
                                                    ]
                                                  }
                                                }
                                              }
                                              HingeJoint {
                                                jointParameters HingeJointParameters {
                                                  axis -0.000000 -1.000000 0.000000
                                                  anchor -0.030601 0.000000 0.062792
                                                }
                                                device [
                                                  RotationalMotor {
                                                    name "right_gripper_right_outer_knuckle_joint"
                                                    maxVelocity 2.0
                                                    minPosition -1.0
                                                    maxPosition 0.8757
                                                    maxTorque 1000.0
                                                  }
                                                  PositionSensor {
                                                    name "right_gripper_right_outer_knuckle_joint_sensor"
                                                  }
                                                ]
                                                endPoint Solid {
                                                  translation -0.030601 0.000000 0.062792
                                                  rotation 0.000000 0.000000 1.000000 3.141593
                                                  children [
                                                    USE outer_knuckle_fine_visual
                                                    Solid {
                                                      translation 0.031710 0.000000 -0.001601
                                                      children [
                                                        USE outer_finger_fine_visual
                                                      ]
                                                      name "right_gripper_right_outer_finger"
                                                      boundingObject USE outer_finger_coarse
                                                      physics Physics {
                                                        density -1
                                                        mass 0.027309
                                                        centerOfMass [ 0.001088 -0.000000 0.021553 ]
                                                        inertiaMatrix [
                                                          8.523660e-06 6.913333e-06 2.242704e-06
                                                          3.416834e-19 3.180037e-07 7.377267e-19
                                                        ]
                                                      }
                                                    }
                                                  ]
                                                  name "right_gripper_right_outer_knuckle"
                                                  boundingObject USE outer_knuckle_coarse
                                                  physics Physics {
                                                    density -1
                                                    mass 0.006848
                                                    centerOfMass [ 0.017810 0.000000 0.002331 ]
                                                    inertiaMatrix [
                                                      2.700044e-07 1.388923e-06 1.262861e-06
                                                      1.595795e-15 1.563965e-07 2.823578e-15
                                                    ]
                                                  }
                                                }
                                              }
                                            ]
                                            name "right_gripper_robotiq_85_base_link"
                                            boundingObject USE robotiq_85_base_link_coarse
                                            physics Physics {
                                              density -1
                                              mass 0.309150
                                              centerOfMass [ 0.000220 -0.000000 0.030163 ]
                                              inertiaMatrix [
                                                2.897200e-04 3.073700e-04 1.991400e-04
                                                -5.787900e-10 -1.854300e-06 1.682000e-12
                                              ]
                                            }
                                          }
                                        ]
                                        name "right_intermediate_link"
                                        boundingObject Box {
                                           size 0.050000 0.050000 0.020000
                                        }
                                        physics Physics {
                                          density -1
                                          mass 0.100000
                                          centerOfMass [ 0.000000 0.000000 0.000000 ]
                                          inertiaMatrix [
                                            5.000000e-04 5.000000e-04 1.000000e-04
                                            0.000000e+00 0.000000e+00 0.000000e+00
                                          ]
                                        }
                                      }
                                    }
                                  ]
                                  name "zarm_r5_link"
                                  physics Physics {
                                    density -1
                                    mass 0.610000
                                    centerOfMass [ -0.002070 -0.000180 -0.050790 ]
                                    inertiaMatrix [
                                      1.070000e-03 1.460000e-03 8.300000e-04
                                      0.000000e+00 -4.000000e-05 0.000000e+00
                                    ]
                                  }
                                }
                              }
                            ]
                            name "zarm_r4_link"
                            physics Physics {
                              density -1
                              mass 0.429000
                              centerOfMass [ -0.016110 -0.001430 -0.048570 ]
                              inertiaMatrix [
                                1.350000e-03 1.140000e-03 8.300000e-04
                                0.000000e+00 -1.000000e-04 0.000000e+00
                              ]
                            }
                          }
                        }
                      ]
                      name "zarm_r3_link"
                      physics Physics {
                        density -1
                        mass 1.650000
                        centerOfMass [ 0.006280 -0.001070 -0.208780 ]
                        inertiaMatrix [
                          8.150000e-03 8.280000e-03 2.060000e-03
                          4.000000e-05 8.500000e-04 -1.400000e-04
                        ]
                      }
                    }
                  }
                ]
                name "zarm_r2_link"
                physics Physics {
                  density -1
                  mass 0.570000
                  centerOfMass [ -0.007910 0.000000 -0.046550 ]
                  inertiaMatrix [
                    1.630000e-03 2.110000e-03 1.220000e-03
                    0.000000e+00 5.000000e-05 0.000000e+00
                  ]
                }
              }
            }
          ]
          name "zarm_r1_link"
          physics Physics {
            density -1
            mass 0.962000
            centerOfMass [ -0.000830 0.022180 0.000350 ]
            inertiaMatrix [
              2.250000e-03 9.900000e-04 2.270000e-03
              3.000000e-05 0.000000e+00 2.000000e-05
            ]
          }
        }
      }
      HingeJoint {
        jointParameters HingeJointParameters {
          axis 0.000000 0.000000 -1.000000
          anchor -0.018500 0.000000 0.488400
        }
        device [
          RotationalMotor {
            name "head_pitch_motor"
            minPosition -3.14
            maxPosition 3.14
            maxTorque 10000
          }
          PositionSensor {
            name "head_pitch_motor_sensor"
          }
        ]
        endPoint Solid {
          translation -0.018500 0.000000 0.488400
          children [
            DEF head_pitch_motor_visual CadShape {
              url "meshes_obj/head_pitch_motor.obj"
            }
            HingeJoint {
              jointParameters HingeJointParameters {
                axis 0.000000 -1.000000 0.000000
              }
              device [
                RotationalMotor {
                  name "head"
                  minPosition -3.14
                  maxPosition 3.14
                  maxTorque 10000
                }
                PositionSensor {
                  name "head_sensor"
                }
              ]
              endPoint Solid {
                children [
                  DEF head_visual CadShape {
                    url "meshes_obj/head.obj"
                  }
                  Solid {
                    translation 0.097449 0.017453 0.125582
                    rotation 0.000000 1.000000 0.000000 0.488692
                    children [
                      DEF head_camera_visual CadShape {
                        url "meshes_obj/head_camera.obj"
                      }
                    ]
                    name "head_camera"
                    boundingObject DEF head_camera Mesh {
                      url "meshes_obj/head_camera.obj"
                    }
                    physics Physics {
                      density -1
                      mass 0.017026
                      centerOfMass [ -0.006300 -0.016049 -0.000049 ]
                      inertiaMatrix [
                        1.091826e-05 8.571790e-07 1.028699e-05
                        -1.053544e-07 -1.058715e-08 -1.640187e-08
                      ]
                    }
                  }
                ]
                name "head"
                boundingObject DEF head Mesh {
                  url "meshes_obj/head.obj"
                }
                physics Physics {
                  density -1
                  mass 0.604629
                  centerOfMass [ 0.027054 -0.000611 0.108993 ]
                  inertiaMatrix [
                    2.209117e-03 2.158000e-03 1.938550e-03
                    4.490848e-06 4.093912e-04 1.357568e-05
                  ]
                }
              }
            }
          ]
          name "head_pitch_motor"
          boundingObject DEF head_pitch_motor Mesh {
            url "meshes_obj/head_pitch_motor.obj"
          }
          physics Physics {
            density -1
            mass 0.073699
            centerOfMass [ 0.000022 0.006049 -0.010524 ]
            inertiaMatrix [
              3.673481e-05 4.135111e-05 3.682825e-05
              6.736198e-08 -2.371373e-08 -7.394655e-06
            ]
          }
        }
      }
      SliderJoint {
        jointParameters JointParameters {
          axis 0.000000 0.000000 1.000000
        }
        device [
          LinearMotor {
            name "chassis"
            minPosition -3.14
            maxPosition 3.14
            maxForce 10000
          }
          PositionSensor {
            name "chassis_sensor"
          }
        ]
        endPoint Solid {
          translation -0.580843 -0.295000 -0.754500
          children [
            DEF chassis_visual CadShape {
              url "meshes_obj/chassis.obj"
            }
            DEF fl_caster_rotation_joint HingeJoint {
              jointParameters HingeJointParameters {
                axis 0.0 0.0 1.0
                anchor 0.600000 0.500000 0.000000
                dampingConstant 1.0
                staticFriction 0.0
              }
              device [
                RotationalMotor {
                  name "fl_caster_rotation_joint"
                  maxVelocity 10.0
                  maxTorque 70
                }
                PositionSensor {
                  name "fl_caster_rotation_joint_sensor"
                }
              ]
              endPoint Solid {
                translation 0.600000 0.500000 0.000000
                children [
                  DEF caster_visual CadShape {
                    url "meshes/caster.obj"
                  }
                  DEF fl_caster_l_wheel_joint HingeJoint {
                    jointParameters HingeJointParameters {
                      axis 0.0 1.0 0.0
                      anchor 0.0 0.049 0.0
                      dampingConstant 1.0
                      staticFriction 0.0
                    }
                    device [
                      RotationalMotor {
                        name "fl_caster_l_wheel_joint"
                        maxVelocity 15.0
                        maxTorque 7.0
                      }
                      PositionSensor {
                        name "fl_caster_l_wheel_joint_sensor"
                      }
                    ]
                    endPoint Solid {
                      translation 0.000000 0.049000 0.000000
                      children [
                        Pose {
                          rotation 1.000000 0.000000 0.000000 3.140000
                          children [
                            DEF wheel_visual CadShape {
                              url "meshes/wheel.obj"
                            }
                          ]
                        }
                      ]
                      name "fl_caster_l_wheel_link"
                      boundingObject DEF wheel Mesh {
                        url "meshes/wheel.obj"
                      }
                      physics Physics {
                        density -1
                        mass 0.440360
                        centerOfMass [ 0.000000 0.000000 0.000000 ]
                        inertiaMatrix [
                          1.241177e-02 1.521816e-02 1.176398e-02
                          -7.117337e-04 5.027298e-04 -4.273467e-06
                        ]
                      }
                    }
                  }
                  DEF fl_caster_r_wheel_joint HingeJoint {
                    jointParameters HingeJointParameters {
                      axis 0.0 1.0 0.0
                      anchor 0.0 -0.049 0.0
                      dampingConstant 1.0
                      staticFriction 0.0
                    }
                    device [
                      RotationalMotor {
                        name "fl_caster_r_wheel_joint"
                        maxVelocity 15.0
                        maxTorque 7.0
                      }
                      PositionSensor {
                        name "fl_caster_r_wheel_joint_sensor"
                      }
                    ]
                    endPoint Solid {
                      translation 0.000000 -0.049000 0.000000
                      children [
                        USE wheel_visual
                      ]
                      name "fl_caster_r_wheel_link"
                      boundingObject USE wheel
                      physics Physics {
                        density -1
                        mass 0.440360
                        centerOfMass [ 0.000000 0.000000 0.000000 ]
                        inertiaMatrix [
                          1.241177e-02 1.521816e-02 1.176398e-02
                          -7.117337e-04 5.027298e-04 -4.273467e-06
                        ]
                      }
                    }
                  }
                  Solid {
                    translation 0.000000 0.000000 0.100000
                    children [
                      Shape {
                        appearance DEF imu PBRAppearance {
                          baseColor 0.800000 0.200000 0.200000
                          roughness 1.000000
                          metalness 0
                        }
                        geometry Box {
                           size 0.020000 0.020000 0.010000
                        }
                      }
                    ]
                    name "fl_imu_link"
                    physics Physics {
                      density -1
                      mass 0.100000
                      centerOfMass [ 0.000000 0.000000 0.000000 ]
                      inertiaMatrix [
                        1.000000e-03 1.000000e-03 1.000000e-03
                        0.000000e+00 0.000000e+00 0.000000e+00
                      ]
                    }
                  }
                ]
                name "fl_caster_rotation_link"
                boundingObject DEF caster_L Mesh {
                  url "meshes/caster_L.obj"
                }
                physics Physics {
                  density -1
                  mass 3.473082
                  centerOfMass [ 0.000000 0.000000 0.070000 ]
                  inertiaMatrix [
                    1.241177e-02 1.521816e-02 1.176398e-02
                    -7.117337e-04 5.027298e-04 -4.273467e-06
                  ]
                }
              }
            }
            DEF fr_caster_rotation_joint HingeJoint {
              jointParameters HingeJointParameters {
                axis 0.000000 0.000000 1.000000
                anchor 0.600000 0.100000 0.000000
                dampingConstant 1.0
                staticFriction 0.0
              }
              device [
                RotationalMotor {
                  name "fr_caster_rotation_joint"
                  maxVelocity 10.0
                  maxTorque 70
                }
                PositionSensor {
                  name "fr_caster_rotation_joint_sensor"
                }
              ]
              endPoint Solid {
                translation 0.600000 0.100000 0.000000
                children [
                  USE caster_visual
                  DEF fr_caster_l_wheel_joint HingeJoint {
                    jointParameters HingeJointParameters {
                      axis 0.0 1.0 0.0
                      anchor 0.0 0.049 0.0
                      dampingConstant 1.0
                      staticFriction 0.0
                    }
                    device [
                      RotationalMotor {
                        name "fr_caster_l_wheel_joint"
                        maxVelocity 15.0
                        maxTorque 7.0
                      }
                      PositionSensor {
                        name "fr_caster_l_wheel_joint_sensor"
                      }
                    ]
                    endPoint Solid {
                      translation 0.000000 0.049000 0.000000
                      children [
                        Pose {
                          rotation 1.000000 0.000000 0.000000 3.140000
                          children [
                            USE wheel_visual
                          ]
                        }
                      ]
                      name "fr_caster_l_wheel_link"
                      boundingObject USE wheel
                      physics Physics {
                        density -1
                        mass 0.440360
                        centerOfMass [ 0.000000 0.000000 0.000000 ]
                        inertiaMatrix [
                          1.241177e-02 1.521816e-02 1.176398e-02
                          -7.117337e-04 5.027298e-04 -4.273467e-06
                        ]
                      }
                    }
                  }
                  DEF fr_caster_r_wheel_joint HingeJoint {
                    jointParameters HingeJointParameters {
                      axis 0.0 1.0 0.0
                      anchor 0.0 -0.049 0.0
                      dampingConstant 1.0
                      staticFriction 0.0
                    }
                    device [
                      RotationalMotor {
                        name "fr_caster_r_wheel_joint"
                        maxVelocity 15.0
                        maxTorque 7.0
                      }
                      PositionSensor {
                        name "fr_caster_r_wheel_joint_sensor"
                      }
                    ]
                    endPoint Solid {
                      translation 0.000000 -0.049000 0.000000
                      children [
                        USE wheel_visual
                      ]
                      name "fr_caster_r_wheel_link"
                      boundingObject USE wheel
                      physics Physics {
                        density -1
                        mass 0.440360
                        centerOfMass [ 0.000000 0.000000 0.000000 ]
                        inertiaMatrix [
                          1.241177e-02 1.521816e-02 1.176398e-02
                          -7.117337e-04 5.027298e-04 -4.273467e-06
                        ]
                      }
                    }
                  }
                  Solid {
                    translation 0.000000 0.000000 0.100000
                    children [
                      Shape {
                        appearance USE imu
                        geometry Box {
                           size 0.020000 0.020000 0.010000
                        }
                      }
                    ]
                    name "fr_imu_link"
                    physics Physics {
                      density -1
                      mass 0.100000
                      centerOfMass [ 0.000000 0.000000 0.000000 ]
                      inertiaMatrix [
                        1.000000e-03 1.000000e-03 1.000000e-03
                        0.000000e+00 0.000000e+00 0.000000e+00
                      ]
                    }
                  }
                ]
                name "fr_caster_rotation_link"
                boundingObject USE caster_L
                physics Physics {
                  density -1
                  mass 3.473082
                  centerOfMass [ 0.000000 0.000000 0.070000 ]
                  inertiaMatrix [
                    1.241177e-02 1.521816e-02 1.176398e-02
                    -7.117337e-04 5.027298e-04 -4.273467e-06
                  ]
                }
              }
            }
            DEF bl_caster_rotation_joint HingeJoint {
              jointParameters HingeJointParameters {
                axis 0.000000 0.000000 1.000000
                anchor 0.100000 0.500000 0.000000
                dampingConstant 1.0
                staticFriction 0.0
              }
              device [
                RotationalMotor {
                  name "bl_caster_rotation_joint"
                  maxVelocity 10.0
                  maxTorque 70
                }
                PositionSensor {
                  name "bl_caster_rotation_joint_sensor"
                }
              ]
              endPoint Solid {
                translation 0.100000 0.500000 0.000000
                children [
                  USE caster_visual
                  DEF bl_caster_l_wheel_joint HingeJoint {
                    jointParameters HingeJointParameters {
                      axis 0.0 1.0 0.0
                      anchor 0.0 0.049 0.0
                      dampingConstant 1.0
                      staticFriction 0.0
                    }
                    device [
                      RotationalMotor {
                        name "bl_caster_l_wheel_joint"
                        maxVelocity 15.0
                        maxTorque 7.0
                      }
                      PositionSensor {
                        name "bl_caster_l_wheel_joint_sensor"
                      }
                    ]
                    endPoint Solid {
                      translation 0.000000 0.049000 0.000000
                      children [
                        Pose {
                          rotation 1.000000 0.000000 0.000000 3.140000
                          children [
                            USE wheel_visual
                          ]
                        }
                      ]
                      name "bl_caster_l_wheel_link"
                      boundingObject USE wheel
                      physics Physics {
                        density -1
                        mass 0.440360
                        centerOfMass [ 0.000000 0.000000 0.000000 ]
                        inertiaMatrix [
                          1.241177e-02 1.521816e-02 1.176398e-02
                          -7.117337e-04 5.027298e-04 -4.273467e-06
                        ]
                      }
                    }
                  }
                  DEF bl_caster_r_wheel_joint HingeJoint {
                    jointParameters HingeJointParameters {
                      axis 0.0 1.0 0.0
                      anchor 0.0 -0.049 0.0
                      dampingConstant 1.0
                      staticFriction 0.0
                    }
                    device [
                      RotationalMotor {
                        name "bl_caster_r_wheel_joint"
                        maxVelocity 15.0
                        maxTorque 7.0
                      }
                      PositionSensor {
                        name "bl_caster_r_wheel_joint_sensor"
                      }
                    ]
                    endPoint Solid {
                      translation 0.000000 -0.049000 0.000000
                      children [
                        USE wheel_visual
                      ]
                      name "bl_caster_r_wheel_link"
                      boundingObject USE wheel
                      physics Physics {
                        density -1
                        mass 0.440360
                        centerOfMass [ 0.000000 0.000000 0.000000 ]
                        inertiaMatrix [
                          1.241177e-02 1.521816e-02 1.176398e-02
                          -7.117337e-04 5.027298e-04 -4.273467e-06
                        ]
                      }
                    }
                  }
                  Solid {
                    translation 0.000000 0.000000 0.100000
                    children [
                      Shape {
                        appearance USE imu
                        geometry Box {
                           size 0.020000 0.020000 0.010000
                        }
                      }
                    ]
                    name "bl_imu_link"
                    physics Physics {
                      density -1
                      mass 0.100000
                      centerOfMass [ 0.000000 0.000000 0.000000 ]
                      inertiaMatrix [
                        1.000000e-03 1.000000e-03 1.000000e-03
                        0.000000e+00 0.000000e+00 0.000000e+00
                      ]
                    }
                  }
                ]
                name "bl_caster_rotation_link"
                boundingObject USE caster_L
                physics Physics {
                  density -1
                  mass 3.473082
                  centerOfMass [ 0.000000 0.000000 0.070000 ]
                  inertiaMatrix [
                    1.241177e-02 1.521816e-02 1.176398e-02
                    -7.117337e-04 5.027298e-04 -4.273467e-06
                  ]
                }
              }
            }
            DEF br_caster_rotation_joint HingeJoint {
              jointParameters HingeJointParameters {
                axis 0.000000 0.000000 1.000000
                anchor 0.100000 0.100000 0.000000
                dampingConstant 1.0
                staticFriction 0.0
              }
              device [
                RotationalMotor {
                  name "br_caster_rotation_joint"
                  maxVelocity 10.0
                  maxTorque 70
                }
                PositionSensor {
                  name "br_caster_rotation_joint_sensor"
                }
              ]
              endPoint Solid {
                translation 0.100000 0.100000 0.000000
                children [
                  USE caster_visual
                  DEF br_caster_l_wheel_joint HingeJoint {
                    jointParameters HingeJointParameters {
                      axis 0.0 1.0 0.0
                      anchor 0.0 0.049 0.0
                      dampingConstant 1.0
                      staticFriction 0.0
                    }
                    device [
                      RotationalMotor {
                        name "br_caster_l_wheel_joint"
                        maxVelocity 15.0
                        maxTorque 7.0
                      }
                      PositionSensor {
                        name "br_caster_l_wheel_joint_sensor"
                      }
                    ]
                    endPoint Solid {
                      translation 0.000000 0.049000 0.000000
                      children [
                        Pose {
                          rotation 1.000000 0.000000 0.000000 3.140000
                          children [
                            USE wheel_visual
                          ]
                        }
                      ]
                      name "br_caster_l_wheel_link"
                      boundingObject USE wheel
                      physics Physics {
                        density -1
                        mass 0.440360
                        centerOfMass [ 0.000000 0.000000 0.000000 ]
                        inertiaMatrix [
                          1.241177e-02 1.521816e-02 1.176398e-02
                          -7.117337e-04 5.027298e-04 -4.273467e-06
                        ]
                      }
                    }
                  }
                  DEF br_caster_r_wheel_joint HingeJoint {
                    jointParameters HingeJointParameters {
                      axis 0.0 1.0 0.0
                      anchor 0.0 -0.049 0.0
                      dampingConstant 1.0
                      staticFriction 0.0
                    }
                    device [
                      RotationalMotor {
                        name "br_caster_r_wheel_joint"
                        maxVelocity 15.0
                        maxTorque 7.0
                      }
                      PositionSensor {
                        name "br_caster_r_wheel_joint_sensor"
                      }
                    ]
                    endPoint Solid {
                      translation 0.000000 -0.049000 0.000000
                      children [
                        USE wheel_visual
                      ]
                      name "br_caster_r_wheel_link"
                      boundingObject USE wheel
                      physics Physics {
                        density -1
                        mass 0.440360
                        centerOfMass [ 0.000000 0.000000 0.000000 ]
                        inertiaMatrix [
                          1.241177e-02 1.521816e-02 1.176398e-02
                          -7.117337e-04 5.027298e-04 -4.273467e-06
                        ]
                      }
                    }
                  }
                  Solid {
                    translation 0.000000 0.000000 0.100000
                    children [
                      Shape {
                        appearance USE imu
                        geometry Box {
                           size 0.020000 0.020000 0.010000
                        }
                      }
                    ]
                    name "br_imu_link"
                    physics Physics {
                      density -1
                      mass 0.100000
                      centerOfMass [ 0.000000 0.000000 0.000000 ]
                      inertiaMatrix [
                        1.000000e-03 1.000000e-03 1.000000e-03
                        0.000000e+00 0.000000e+00 0.000000e+00
                      ]
                    }
                  }
                ]
                name "br_caster_rotation_link"
                boundingObject USE caster_L
                physics Physics {
                  density -1
                  mass 3.473082
                  centerOfMass [ 0.000000 0.000000 0.070000 ]
                  inertiaMatrix [
                    1.241177e-02 1.521816e-02 1.176398e-02
                    -7.117337e-04 5.027298e-04 -4.273467e-06
                  ]
                }
              }
            }
          ]
          name "chassis"
          boundingObject DEF chassis Mesh {
            url "meshes_obj/chassis.obj"
          }
          physics Physics {
            mass 5
            density -1
            centerOfMass [ -0.110380 0.003430 0.301010 ]
            inertiaMatrix [
              1.040803e+01 9.922754e+00 1.031268e+01
              -2.870000e-04 1.389546e-03 -4.990000e-05
            ]
          }
        }
      }
      Solid {
        translation 0.115076 0.017500 0.275872
        rotation 0.0 1.0 0.0 3.14159265359
        children [
          DEF camera_torso_visual CadShape {
            url "meshes_obj/camera_torso.obj"
          }
          Pose {
            rotation 1 0 0 1.57
            children [
              Pose {
                rotation 0 0 1 3.14
                children [
                  InertialUnit {
                    name "imu_sensor"
                  }
                ]
              }
            ]
          }
        ]
        name "camera_torso"
        boundingObject DEF camera_torso Mesh {
          url "meshes_obj/camera_torso.obj"
        }
        physics Physics {
          density -1
          mass 0.017404
          centerOfMass [ -0.006295 -0.016136 -0.000627 ]
          inertiaMatrix [
            1.145126e-05 1.013584e-06 1.068081e-05
            -1.068653e-07 2.155318e-08 -9.980836e-09
          ]
        }
      }
      DEF EXTENSION_SLOT Transform {
        translation 0 0 0
        children IS extensionSlot1
      }
      DEF EXTENSION_SLOT Transform {
        translation 0 0 0
        children IS extensionSlot2
      }
    ]
    name IS name
    boundingObject DEF urdf_arm Mesh {
      url "meshes_obj/urdf_arm.obj"
    }
    physics Physics {
      density -1
      mass 5.140394
      centerOfMass [ -0.017488 0.001799 0.000000 ]
      inertiaMatrix [
        4.992224e-02 3.738068e-02 3.306054e-02
        -1.457371e-06 9.414797e-04 -1.041448e-05
      ]
    }
  }
}