#VRML_SIM R2025a utf8
# license: Apache License 2.0
# license url: http://www.apache.org/licenses/LICENSE-2.0
# This is a proto file for Webots for the BipedS48
# Extracted from: E:\homework\practice\robortes\converurdf\biped_s48\urdf\biped_s48.urdf

PROTO BipedS48 [
  field  SFVec3f     translation     0 0 0
  field  SFRotation  rotation        0 0 1 0
  field  SFString    name            "BipedS48"  # Is `Robot.name`.
  field  SFString    controller      "void"      # Is `Robot.controller`.
  field  MFString    controllerArgs  []          # Is `Robot.controllerArgs`.
  field  SFString    customData      ""          # Is `Robot.customData`.
  field  SFBool      supervisor      FALSE       # Is `Robot.supervisor`.
  field  SFBool      synchronization TRUE        # Is `Robot.synchronization`.
  field  SFBool      selfCollision   FALSE       # Is `Robot.selfCollision`.
]
{
  Robot {
    translation IS translation
    rotation IS rotation
    controller IS controller
    controllerArgs IS controllerArgs
    customData IS customData
    supervisor IS supervisor
    synchronization IS synchronization
    selfCollision IS selfCollision
    children [
      Solid {
        children [
          Shape {
            appearance DEF base_link_material PBRAppearance {
              roughness 1.000000
              metalness 0
            }
            geometry DEF torso Mesh {
              url "kuavo_assets\models\biped_s48\meshes\torso.STL"
            }
          }
          HingeJoint {
            jointParameters HingeJointParameters {
              anchor -0.002500 0.087000 -0.066000
            }
            device [
              RotationalMotor {
                name "leg_l1_joint"
                maxVelocity 23.55
                minPosition -0.314159265358979
                maxPosition 0.663225115757845
                maxTorque 180.0
              }
              PositionSensor {
                name "leg_l1_joint_sensor"
              }
            ]
            endPoint Solid {
              translation -0.002500 0.087000 -0.066000
              children [
                Shape {
                  appearance DEF leg_l1_link_material PBRAppearance {
                    roughness 1.000000
                    metalness 0
                  }
                  geometry DEF l_leg_roll Mesh {
                    url "kuavo_assets\models\biped_s48\meshes\l_leg_roll.STL"
                  }
                }
                HingeJoint {
                  jointParameters HingeJointParameters {
                    axis 0.000000 0.000000 1.000000
                  }
                  device [
                    RotationalMotor {
                      name "leg_l2_joint"
                      maxVelocity 41.3433333333333
                      minPosition -0.872664625997165
                      maxPosition 0.785398163397448
                      maxTorque 100.0
                    }
                    PositionSensor {
                      name "leg_l2_joint_sensor"
                    }
                  ]
                  endPoint Solid {
                    children [
                      Shape {
                        appearance DEF leg_l2_link_material PBRAppearance {
                          roughness 1.000000
                          metalness 0
                        }
                        geometry DEF l_leg_yaw Mesh {
                          url "kuavo_assets\models\biped_s48\meshes\l_leg_yaw.STL"
                        }
                      }
                      HingeJoint {
                        jointParameters HingeJointParameters {
                          axis 0.000000 1.000000 0.000000
                          anchor 0.000500 -0.001000 -0.128700
                        }
                        device [
                          RotationalMotor {
                            name "leg_l3_joint"
                            maxVelocity 41.3433333333333
                            minPosition -2.00712863979348
                            maxPosition 1.5707963267949
                            maxTorque 100.0
                          }
                          PositionSensor {
                            name "leg_l3_joint_sensor"
                          }
                        ]
                        endPoint Solid {
                          translation 0.000500 -0.001000 -0.128700
                          children [
                            Shape {
                              appearance DEF leg_l3_link_material PBRAppearance {
                                roughness 1.000000
                                metalness 0
                              }
                              geometry DEF l_leg_pitch Mesh {
                                url "kuavo_assets\models\biped_s48\meshes\l_leg_pitch.STL"
                              }
                            }
                            HingeJoint {
                              jointParameters HingeJointParameters {
                                axis 0.000000 1.000000 0.000000
                                anchor -0.000069 0.000000 -0.284000
                              }
                              device [
                                RotationalMotor {
                                  name "leg_l4_joint"
                                  maxVelocity 23.55
                                  maxPosition 2.53072741539178
                                  maxTorque 180.0
                                }
                                PositionSensor {
                                  name "leg_l4_joint_sensor"
                                }
                              ]
                              endPoint Solid {
                                translation -0.000069 0.000000 -0.284000
                                children [
                                  Shape {
                                    appearance DEF leg_l4_link_material PBRAppearance {
                                      roughness 1.000000
                                      metalness 0
                                    }
                                    geometry DEF l_knee Mesh {
                                      url "kuavo_assets\models\biped_s48\meshes\l_knee.STL"
                                    }
                                  }
                                  HingeJoint {
                                    jointParameters HingeJointParameters {
                                      axis 0.000000 1.000000 0.000000
                                      anchor -0.000432 0.000000 -0.346000
                                    }
                                    device [
                                      RotationalMotor {
                                        name "leg_l5_joint"
                                        maxVelocity 23.0266666666667
                                        minPosition -0.872664625997165
                                        maxPosition 0.349065850398866
                                        maxTorque 36.0
                                      }
                                      PositionSensor {
                                        name "leg_l5_joint_sensor"
                                      }
                                    ]
                                    endPoint Solid {
                                      translation -0.000432 0.000000 -0.346000
                                      children [
                                        Shape {
                                          appearance DEF leg_l5_link_material PBRAppearance {
                                            roughness 1.000000
                                            metalness 0
                                          }
                                          geometry DEF l_foot_pitch Mesh {
                                            url "kuavo_assets\models\biped_s48\meshes\l_foot_pitch.STL"
                                          }
                                        }
                                        HingeJoint {
                                          jointParameters HingeJointParameters {
                                          }
                                          device [
                                            RotationalMotor {
                                              name "leg_l6_joint"
                                              maxVelocity 23.0266666666667
                                              minPosition -0.261799387799149
                                              maxPosition 0.261799387799149
                                              maxTorque 36.0
                                            }
                                            PositionSensor {
                                              name "leg_l6_joint_sensor"
                                            }
                                          ]
                                          endPoint Solid {
                                            children [
                                              Shape {
                                                appearance DEF leg_l6_link_material PBRAppearance {
                                                  roughness 1.000000
                                                  metalness 0
                                                }
                                                geometry DEF l_foot_roll Mesh {
                                                  url "kuavo_assets\models\biped_s48\meshes\l_foot_roll.STL"
                                                }
                                              }
                                              Solid {
                                                translation 0.170840 0.047730 -0.059500
                                                name "ll_foot_toe"
                                                boundingObject Sphere {
                                                  radius 0.005
                                                }
                                                physics Physics {
                                                }
                                              }
                                              Solid {
                                                translation -0.073164 0.047730 -0.059500
                                                name "ll_foot_heel"
                                                boundingObject Sphere {
                                                  radius 0.005
                                                }
                                                physics Physics {
                                                }
                                              }
                                              Solid {
                                                translation 0.170840 -0.047730 -0.059500
                                                name "lr_foot_toe"
                                                boundingObject Sphere {
                                                  radius 0.005
                                                }
                                                physics Physics {
                                                }
                                              }
                                              Solid {
                                                translation -0.073164 -0.047730 -0.059500
                                                name "lr_foot_heel"
                                                boundingObject Sphere {
                                                  radius 0.005
                                                }
                                                physics Physics {
                                                }
                                              }
                                              Solid {
                                                translation 0.170840 0.000000 -0.059500
                                                name "l_foot_toe"
                                                boundingObject Sphere {
                                                  radius 0.005
                                                }
                                                physics Physics {
                                                }
                                              }
                                              Solid {
                                                translation -0.073164 0.000000 -0.059500
                                                name "l_foot_heel"
                                                boundingObject Sphere {
                                                  radius 0.005
                                                }
                                                physics Physics {
                                                }
                                              }
                                            ]
                                            name "leg_l6_link"
                                            boundingObject Pose {
                                              translation 0.048800 0.000000 0.000000
                                              children [
                                                Box {
                                                   size 0.250000 0.100000 0.040000
                                                }
                                              ]
                                            }
                                            physics Physics {
                                              density -1
                                              mass 0.498613
                                              centerOfMass [ 0.037328 -0.000002 -0.038840 ]
                                              inertiaMatrix [
                                                3.924200e-04 1.586550e-03 1.725760e-03
                                                3.000000e-08 4.664000e-05 0.000000e+00
                                              ]
                                            }
                                          }
                                        }
                                      ]
                                      name "leg_l5_link"
                                      physics Physics {
                                        density -1
                                        mass 0.071935
                                        centerOfMass [ 0.000000 0.000000 0.000000 ]
                                        inertiaMatrix [
                                          6.920000e-06 6.920000e-06 1.218000e-05
                                          0.000000e+00 0.000000e+00 0.000000e+00
                                        ]
                                      }
                                    }
                                  }
                                ]
                                name "leg_l4_link"
                                physics Physics {
                                  density -1
                                  mass 1.627768
                                  centerOfMass [ 0.006962 0.000053 -0.115499 ]
                                  inertiaMatrix [
                                    1.243912e-02 1.229563e-02 9.793700e-04
                                    -2.290000e-06 5.881000e-05 -2.895000e-05
                                  ]
                                }
                              }
                            }
                          ]
                          name "leg_l3_link"
                          physics Physics {
                            density -1
                            mass 4.503931
                            centerOfMass [ 0.001505 0.011996 -0.084116 ]
                            inertiaMatrix [
                              3.893650e-02 3.942609e-02 9.999610e-03
                              7.866000e-05 1.020860e-03 2.191380e-03
                            ]
                          }
                        }
                      }
                    ]
                    name "leg_l2_link"
                    physics Physics {
                      density -1
                      mass 0.580292
                      centerOfMass [ 0.000000 -0.002311 -0.090625 ]
                      inertiaMatrix [
                        2.239840e-03 1.231750e-03 1.463910e-03
                        0.000000e+00 3.000000e-08 -6.980000e-06
                      ]
                    }
                  }
                }
              ]
              name "leg_l1_link"
              physics Physics {
                density -1
                mass 1.710931
                centerOfMass [ -0.004301 -0.000027 -0.008512 ]
                inertiaMatrix [
                  2.060920e-03 2.772740e-03 3.708260e-03
                  1.970000e-06 6.944000e-05 -5.100000e-06
                ]
              }
            }
          }
          HingeJoint {
            jointParameters HingeJointParameters {
              anchor -0.002500 -0.087000 -0.066000
            }
            device [
              RotationalMotor {
                name "leg_r1_joint"
                maxVelocity 23.55
                minPosition -0.663225115757845
                maxPosition 0.314159265358979
                maxTorque 180.0
              }
              PositionSensor {
                name "leg_r1_joint_sensor"
              }
            ]
            endPoint Solid {
              translation -0.002500 -0.087000 -0.066000
              children [
                Shape {
                  appearance DEF leg_r1_link_material PBRAppearance {
                    roughness 1.000000
                    metalness 0
                  }
                  geometry DEF r_leg_roll Mesh {
                    url "kuavo_assets\models\biped_s48\meshes\r_leg_roll.STL"
                  }
                }
                HingeJoint {
                  jointParameters HingeJointParameters {
                    axis 0.000000 0.000000 1.000000
                  }
                  device [
                    RotationalMotor {
                      name "leg_r2_joint"
                      maxVelocity 41.3433333333333
                      minPosition -0.785398163397448
                      maxPosition 0.872664625997165
                      maxTorque 100.0
                    }
                    PositionSensor {
                      name "leg_r2_joint_sensor"
                    }
                  ]
                  endPoint Solid {
                    children [
                      Shape {
                        appearance DEF leg_r2_link_material PBRAppearance {
                          roughness 1.000000
                          metalness 0
                        }
                        geometry DEF r_leg_yaw Mesh {
                          url "kuavo_assets\models\biped_s48\meshes\r_leg_yaw.STL"
                        }
                      }
                      HingeJoint {
                        jointParameters HingeJointParameters {
                          axis 0.000000 1.000000 0.000000
                          anchor -0.000049 0.000000 -0.128700
                        }
                        device [
                          RotationalMotor {
                            name "leg_r3_joint"
                            maxVelocity 41.3433333333333
                            minPosition -2.00712863979348
                            maxPosition 1.5707963267949
                            maxTorque 100.0
                          }
                          PositionSensor {
                            name "leg_r3_joint_sensor"
                          }
                        ]
                        endPoint Solid {
                          translation -0.000049 0.000000 -0.128700
                          children [
                            Shape {
                              appearance DEF leg_r3_link_material PBRAppearance {
                                roughness 1.000000
                                metalness 0
                              }
                              geometry DEF r_leg_pitch Mesh {
                                url "kuavo_assets\models\biped_s48\meshes\r_leg_pitch.STL"
                              }
                            }
                            HingeJoint {
                              jointParameters HingeJointParameters {
                                axis 0.000000 1.000000 0.000000
                                anchor 0.000147 0.000000 -0.284000
                              }
                              device [
                                RotationalMotor {
                                  name "leg_r4_joint"
                                  maxVelocity 23.55
                                  maxPosition 2.53072741539178
                                  maxTorque 180.0
                                }
                                PositionSensor {
                                  name "leg_r4_joint_sensor"
                                }
                              ]
                              endPoint Solid {
                                translation 0.000147 0.000000 -0.284000
                                children [
                                  Shape {
                                    appearance DEF leg_r4_link_material PBRAppearance {
                                      roughness 1.000000
                                      metalness 0
                                    }
                                    geometry DEF r_knee Mesh {
                                      url "kuavo_assets\models\biped_s48\meshes\r_knee.STL"
                                    }
                                  }
                                  HingeJoint {
                                    jointParameters HingeJointParameters {
                                      axis 0.000000 1.000000 0.000000
                                      anchor 0.000120 0.000000 -0.346000
                                    }
                                    device [
                                      RotationalMotor {
                                        name "leg_r5_joint"
                                        maxVelocity 23.0266666666667
                                        minPosition -0.872664625997165
                                        maxPosition 0.349065850398866
                                        maxTorque 36.0
                                      }
                                      PositionSensor {
                                        name "leg_r5_joint_sensor"
                                      }
                                    ]
                                    endPoint Solid {
                                      translation 0.000120 0.000000 -0.346000
                                      children [
                                        Shape {
                                          appearance DEF leg_r5_link_material PBRAppearance {
                                            roughness 1.000000
                                            metalness 0
                                          }
                                          geometry DEF r_foot_pitch Mesh {
                                            url "kuavo_assets\models\biped_s48\meshes\r_foot_pitch.STL"
                                          }
                                        }
                                        HingeJoint {
                                          jointParameters HingeJointParameters {
                                          }
                                          device [
                                            RotationalMotor {
                                              name "leg_r6_joint"
                                              maxVelocity 23.0266666666667
                                              minPosition -0.261799387799149
                                              maxPosition 0.261799387799149
                                              maxTorque 36.0
                                            }
                                            PositionSensor {
                                              name "leg_r6_joint_sensor"
                                            }
                                          ]
                                          endPoint Solid {
                                            children [
                                              Shape {
                                                appearance DEF leg_r6_link_material PBRAppearance {
                                                  roughness 1.000000
                                                  metalness 0
                                                }
                                                geometry DEF r_foot_roll Mesh {
                                                  url "kuavo_assets\models\biped_s48\meshes\r_foot_roll.STL"
                                                }
                                              }
                                              Solid {
                                                translation 0.170840 0.047730 -0.059500
                                                name "rl_foot_toe"
                                                boundingObject Sphere {
                                                  radius 0.005
                                                }
                                                physics Physics {
                                                }
                                              }
                                              Solid {
                                                translation -0.073164 0.047730 -0.059500
                                                name "rl_foot_heel"
                                                boundingObject Sphere {
                                                  radius 0.005
                                                }
                                                physics Physics {
                                                }
                                              }
                                              Solid {
                                                translation 0.170840 -0.047730 -0.059500
                                                name "rr_foot_toe"
                                                boundingObject Sphere {
                                                  radius 0.005
                                                }
                                                physics Physics {
                                                }
                                              }
                                              Solid {
                                                translation -0.073164 -0.047730 -0.059500
                                                name "rr_foot_heel"
                                                boundingObject Sphere {
                                                  radius 0.005
                                                }
                                                physics Physics {
                                                }
                                              }
                                              Solid {
                                                translation 0.170840 0.000000 -0.059500
                                                name "r_foot_toe"
                                                boundingObject Sphere {
                                                  radius 0.005
                                                }
                                                physics Physics {
                                                }
                                              }
                                              Solid {
                                                translation -0.073164 0.000000 -0.059500
                                                name "r_foot_heel"
                                                boundingObject Sphere {
                                                  radius 0.005
                                                }
                                                physics Physics {
                                                }
                                              }
                                            ]
                                            name "leg_r6_link"
                                            boundingObject Pose {
                                              translation 0.048800 0.000000 0.000000
                                              children [
                                                Box {
                                                   size 0.250000 0.100000 0.040000
                                                }
                                              ]
                                            }
                                            physics Physics {
                                              density -1
                                              mass 0.498613
                                              centerOfMass [ 0.037341 -0.000002 -0.038827 ]
                                              inertiaMatrix [
                                                3.923800e-04 1.586550e-03 1.725790e-03
                                                3.000000e-08 4.618000e-05 0.000000e+00
                                              ]
                                            }
                                          }
                                        }
                                      ]
                                      name "leg_r5_link"
                                      physics Physics {
                                        density -1
                                        mass 0.071935
                                        centerOfMass [ 0.000000 0.000000 0.000000 ]
                                        inertiaMatrix [
                                          6.920000e-06 6.920000e-06 1.218000e-05
                                          0.000000e+00 0.000000e+00 0.000000e+00
                                        ]
                                      }
                                    }
                                  }
                                ]
                                name "leg_r4_link"
                                physics Physics {
                                  density -1
                                  mass 1.626557
                                  centerOfMass [ 0.007432 -0.000053 -0.115587 ]
                                  inertiaMatrix [
                                    1.241258e-02 1.226920e-02 9.792700e-04
                                    2.280000e-06 6.289000e-05 2.902000e-05
                                  ]
                                }
                              }
                            }
                          ]
                          name "leg_r3_link"
                          physics Physics {
                            density -1
                            mass 4.503860
                            centerOfMass [ 0.002083 -0.011996 -0.084114 ]
                            inertiaMatrix [
                              3.893478e-02 3.942522e-02 1.000016e-02
                              -7.792000e-05 1.030640e-03 -2.191540e-03
                            ]
                          }
                        }
                      }
                    ]
                    name "leg_r2_link"
                    physics Physics {
                      density -1
                      mass 0.580292
                      centerOfMass [ 0.000000 0.002311 -0.090625 ]
                      inertiaMatrix [
                        2.239840e-03 1.231750e-03 1.463910e-03
                        0.000000e+00 -3.000000e-08 6.980000e-06
                      ]
                    }
                  }
                }
              ]
              name "leg_r1_link"
              physics Physics {
                density -1
                mass 1.710930
                centerOfMass [ -0.004301 0.000027 -0.008512 ]
                inertiaMatrix [
                  2.060920e-03 2.772740e-03 3.708260e-03
                  -1.970000e-06 6.944000e-05 5.100000e-06
                ]
              }
            }
          }
          HingeJoint {
            jointParameters HingeJointParameters {
              axis 0.000000 1.000000 0.000000
              anchor -0.017500 0.292700 0.424500
            }
            device [
              RotationalMotor {
                name "zarm_l1_joint"
                maxVelocity 41.3433333333333
                minPosition -3.14159265358979
                maxPosition 1.5707963267949
                maxTorque 100.0
              }
              PositionSensor {
                name "zarm_l1_joint_sensor"
              }
            ]
            endPoint Solid {
              translation -0.017500 0.292700 0.424500
              children [
                Shape {
                  appearance DEF zarm_l1_link_material PBRAppearance {
                    roughness 1.000000
                    metalness 0
                  }
                  geometry DEF l_arm_pitch Mesh {
                    url "kuavo_assets\models\biped_s48\meshes\l_arm_pitch.STL"
                  }
                }
                HingeJoint {
                  jointParameters HingeJointParameters {
                  }
                  device [
                    RotationalMotor {
                      name "zarm_l2_joint"
                      maxVelocity 19.154
                      minPosition -0.349065850398866
                      maxPosition 2.0943951023932
                      maxTorque 50.0
                    }
                    PositionSensor {
                      name "zarm_l2_joint_sensor"
                    }
                  ]
                  endPoint Solid {
                    children [
                      Shape {
                        appearance DEF zarm_l2_link_material PBRAppearance {
                          roughness 1.000000
                          metalness 0
                        }
                        geometry DEF l_arm_roll Mesh {
                          url "kuavo_assets\models\biped_s48\meshes\l_arm_roll.STL"
                        }
                      }
                      HingeJoint {
                        jointParameters HingeJointParameters {
                          axis 0.000000 0.000000 1.000000
                        }
                        device [
                          RotationalMotor {
                            name "zarm_l3_joint"
                            maxVelocity 18.84
                            minPosition -1.5707963267949
                            maxPosition 1.5707963267949
                            maxTorque 39.0
                          }
                          PositionSensor {
                            name "zarm_l3_joint_sensor"
                          }
                        ]
                        endPoint Solid {
                          children [
                            Shape {
                              appearance DEF zarm_l3_link_material PBRAppearance {
                                roughness 1.000000
                                metalness 0
                              }
                              geometry DEF l_arm_yaw Mesh {
                                url "kuavo_assets\models\biped_s48\meshes\l_arm_yaw.STL"
                              }
                            }
                            HingeJoint {
                              jointParameters HingeJointParameters {
                                axis 0.000000 1.000000 0.000000
                                anchor 0.020000 0.000000 -0.283700
                              }
                              device [
                                RotationalMotor {
                                  name "zarm_l4_joint"
                                  maxVelocity 18.84
                                  minPosition -2.61799387799149
                                  maxTorque 50.0
                                }
                                PositionSensor {
                                  name "zarm_l4_joint_sensor"
                                }
                              ]
                              endPoint Solid {
                                translation 0.020000 0.000000 -0.283700
                                children [
                                  Shape {
                                    appearance DEF zarm_l4_link_material PBRAppearance {
                                      roughness 1.000000
                                      metalness 0
                                    }
                                    geometry DEF l_forearm Mesh {
                                      url "kuavo_assets\models\biped_s48\meshes\l_forearm.STL"
                                    }
                                  }
                                  HingeJoint {
                                    jointParameters HingeJointParameters {
                                      axis 0.000000 0.000000 1.000000
                                      anchor -0.020000 0.000000 -0.127037
                                    }
                                    device [
                                      RotationalMotor {
                                        name "zarm_l5_joint"
                                        maxVelocity 21.666
                                        minPosition -1.5707963267949
                                        maxPosition 1.5707963267949
                                        maxTorque 12.0
                                      }
                                      PositionSensor {
                                        name "zarm_l5_joint_sensor"
                                      }
                                    ]
                                    endPoint Solid {
                                      translation -0.020000 0.000000 -0.127037
                                      children [
                                        Shape {
                                          appearance DEF zarm_l5_link_material PBRAppearance {
                                            roughness 1.000000
                                            metalness 0
                                          }
                                          geometry DEF l_hand_yaw Mesh {
                                            url "kuavo_assets\models\biped_s48\meshes\l_hand_yaw.STL"
                                          }
                                        }
                                        HingeJoint {
                                          jointParameters HingeJointParameters {
                                            anchor 0.000200 0.000000 -0.106463
                                          }
                                          device [
                                            RotationalMotor {
                                              name "zarm_l6_joint"
                                              maxVelocity 21.666
                                              minPosition -1.30899693899575
                                              maxPosition 0.698131700797732
                                              maxTorque 12.0
                                            }
                                            PositionSensor {
                                              name "zarm_l6_joint_sensor"
                                            }
                                          ]
                                          endPoint Solid {
                                            translation 0.000200 0.000000 -0.106463
                                            children [
                                              Shape {
                                                appearance DEF zarm_l6_link_material PBRAppearance {
                                                  roughness 1.000000
                                                  metalness 0
                                                }
                                                geometry DEF l_hand_roll Mesh {
                                                  url "kuavo_assets\models\biped_s48\meshes\l_hand_roll.STL"
                                                }
                                              }
                                              HingeJoint {
                                                jointParameters HingeJointParameters {
                                                  axis 0.000000 1.000000 0.000000
                                                  anchor 0.000000 0.000000 -0.021000
                                                }
                                                device [
                                                  RotationalMotor {
                                                    name "zarm_l7_joint"
                                                    maxVelocity 21.666
                                                    minPosition -0.698131700797732
                                                    maxPosition 0.698131700797732
                                                    maxTorque 12.0
                                                  }
                                                  PositionSensor {
                                                    name "zarm_l7_joint_sensor"
                                                  }
                                                ]
                                                endPoint Solid {
                                                  translation 0.000000 0.000000 -0.021000
                                                  children [
                                                    Shape {
                                                      appearance DEF zarm_l7_link_material PBRAppearance {
                                                        roughness 1.000000
                                                        metalness 0
                                                      }
                                                      geometry DEF l_hand_pitch Mesh {
                                                        url "kuavo_assets\models\biped_s48\meshes\l_hand_pitch.STL"
                                                      }
                                                    }
                                                    Solid {
                                                      translation 0.000000 -0.030000 -0.170000
                                                      name "zarm_l7_end_effector"
                                                      boundingObject Sphere {
                                                        radius 0.005
                                                      }
                                                      physics Physics {
                                                      }
                                                    }
                                                    Solid {
                                                      translation 0.000000 0.000000 -0.070000
                                                      rotation -0.000563 0.706825 -0.707388 3.140466
                                                      children [
                                                        Shape {
                                                          appearance DEF l_palm_material PBRAppearance {
                                                            baseColor 0.752940 0.752940 0.752940
                                                            roughness 1.000000
                                                            metalness 0
                                                          }
                                                          geometry DEF l_palm Mesh {
                                                            url "kuavo_assets\models\biped_s48\meshes\l_palm.STL"
                                                          }
                                                        }
                                                        HingeJoint {
                                                          jointParameters HingeJointParameters {
                                                            axis 0.000000 0.997564 0.069758
                                                            anchor -0.024500 0.022632 0.023263
                                                          }
                                                          device [
                                                            RotationalMotor {
                                                              name "l_thumbCMC"
                                                              maxPosition 1.5708
                                                              maxTorque 10000
                                                            }
                                                            PositionSensor {
                                                              name "l_thumbCMC_sensor"
                                                            }
                                                          ]
                                                          endPoint Solid {
                                                            translation -0.024500 0.022632 0.023263
                                                            rotation 0.058495 -0.997680 -0.034840 1.076423
                                                            children [
                                                              Shape {
                                                                appearance DEF l_thumb_prox_material PBRAppearance {
                                                                  baseColor 0.752940 0.752940 0.752940
                                                                  roughness 1.000000
                                                                  metalness 0
                                                                }
                                                                geometry DEF l_thumb_prox Mesh {
                                                                  url "kuavo_assets\models\biped_s48\meshes\l_thumb_prox.STL"
                                                                }
                                                              }
                                                              HingeJoint {
                                                                jointParameters HingeJointParameters {
                                                                  axis -0.879293 -0.000000 -0.476281
                                                                  anchor 0.000000 0.000000 0.013647
                                                                }
                                                                device [
                                                                  RotationalMotor {
                                                                    name "l_thumbMCP"
                                                                    maxPosition 0.8727
                                                                    maxTorque 10000
                                                                  }
                                                                  PositionSensor {
                                                                    name "l_thumbMCP_sensor"
                                                                  }
                                                                ]
                                                                endPoint Solid {
                                                                  translation 0.000000 0.000000 0.013647
                                                                  rotation 0.857613 -0.466111 0.217350 0.996025
                                                                  children [
                                                                    Shape {
                                                                      appearance DEF l_thumb_dist_material PBRAppearance {
                                                                        baseColor 0.752940 0.752940 0.752940
                                                                        roughness 1.000000
                                                                        metalness 0
                                                                      }
                                                                      geometry DEF l_thumb_dist Mesh {
                                                                        url "kuavo_assets\models\biped_s48\meshes\l_thumb_dist.STL"
                                                                      }
                                                                    }
                                                                  ]
                                                                  name "l_thumb_dist"
                                                                  boundingObject USE l_thumb_dist
                                                                  physics Physics {
                                                                    density -1
                                                                    mass 0.040000
                                                                    centerOfMass [ 0.001724 0.005143 -0.031065 ]
                                                                    inertiaMatrix [
                                                                      1.040500e-03 1.324400e-03 5.321900e-04
                                                                      -3.726800e-05 -3.941500e-05 -4.763800e-05
                                                                    ]
                                                                  }
                                                                }
                                                              }
                                                            ]
                                                            name "l_thumb_prox"
                                                            boundingObject USE l_thumb_prox
                                                            physics Physics {
                                                              density -1
                                                              mass 0.005000
                                                              centerOfMass [ 0.001724 0.005143 -0.031065 ]
                                                              inertiaMatrix [
                                                                1.040500e-03 1.324400e-03 5.321900e-04
                                                                -3.726800e-05 -3.941500e-05 -4.763800e-05
                                                              ]
                                                            }
                                                          }
                                                        }
                                                        HingeJoint {
                                                          jointParameters HingeJointParameters {
                                                            axis 0.998021 0.034852 -0.052336
                                                            anchor -0.029003 0.088291 0.002216
                                                          }
                                                          device [
                                                            RotationalMotor {
                                                              name "l_indexMCP"
                                                              maxPosition 1.309
                                                              maxTorque 10000
                                                            }
                                                            PositionSensor {
                                                              name "l_indexMCP_sensor"
                                                            }
                                                          ]
                                                          endPoint Solid {
                                                            translation -0.029003 0.088291 0.002216
                                                            rotation -0.434084 0.742169 0.510644 0.069846
                                                            children [
                                                              Shape {
                                                                appearance DEF l_Index_prox_material PBRAppearance {
                                                                  baseColor 0.752940 0.752940 0.752940
                                                                  roughness 1.000000
                                                                  metalness 0
                                                                }
                                                                geometry DEF l_Index_prox Mesh {
                                                                  url "kuavo_assets\models\biped_s48\meshes\l_Index_prox.STL"
                                                                }
                                                              }
                                                              HingeJoint {
                                                                jointParameters HingeJointParameters {
                                                                  anchor 0.000000 0.035000 0.000000
                                                                }
                                                                device [
                                                                  RotationalMotor {
                                                                    name "l_indexPIP"
                                                                    maxPosition 1.25
                                                                    maxTorque 10000
                                                                  }
                                                                  PositionSensor {
                                                                    name "l_indexPIP_sensor"
                                                                  }
                                                                ]
                                                                endPoint Solid {
                                                                  translation 0.000000 0.035000 0.000000
                                                                  rotation 1.000000 0.000000 0.000000 0.193530
                                                                  children [
                                                                    Shape {
                                                                      appearance DEF l_index_dist_material PBRAppearance {
                                                                        baseColor 0.752940 0.752940 0.752940
                                                                        roughness 1.000000
                                                                        metalness 0
                                                                      }
                                                                      geometry DEF l_index_dist Mesh {
                                                                        url "kuavo_assets\models\biped_s48\meshes\l_index_dist.STL"
                                                                      }
                                                                    }
                                                                  ]
                                                                  name "l_index_dist"
                                                                  boundingObject USE l_index_dist
                                                                  physics Physics {
                                                                    density -1
                                                                    mass 0.011000
                                                                    centerOfMass [ 0.001724 0.005143 -0.031065 ]
                                                                    inertiaMatrix [
                                                                      1.040500e-03 1.324400e-03 5.321900e-04
                                                                      -3.726800e-05 -3.941500e-05 -4.763800e-05
                                                                    ]
                                                                  }
                                                                }
                                                              }
                                                            ]
                                                            name "l_Index_prox"
                                                            boundingObject USE l_Index_prox
                                                            physics Physics {
                                                              density -1
                                                              mass 0.008000
                                                              centerOfMass [ 0.001724 0.005143 -0.031065 ]
                                                              inertiaMatrix [
                                                                1.040500e-03 1.324400e-03 5.321900e-04
                                                                -3.726800e-05 -3.941500e-05 -4.763800e-05
                                                              ]
                                                            }
                                                          }
                                                        }
                                                        HingeJoint {
                                                          jointParameters HingeJointParameters {
                                                            anchor -0.008000 0.092284 -0.001771
                                                          }
                                                          device [
                                                            RotationalMotor {
                                                              name "l_middleMCP"
                                                              maxPosition 1.309
                                                              maxTorque 10000
                                                            }
                                                            PositionSensor {
                                                              name "l_middleMCP_sensor"
                                                            }
                                                          ]
                                                          endPoint Solid {
                                                            translation -0.008000 0.092284 -0.001771
                                                            children [
                                                              Shape {
                                                                appearance DEF l_middle_prox_material PBRAppearance {
                                                                  baseColor 0.752940 0.752940 0.752940
                                                                  roughness 1.000000
                                                                  metalness 0
                                                                }
                                                                geometry DEF l_middle_prox Mesh {
                                                                  url "kuavo_assets\models\biped_s48\meshes\l_middle_prox.STL"
                                                                }
                                                              }
                                                              HingeJoint {
                                                                jointParameters HingeJointParameters {
                                                                  anchor 0.000000 0.042000 0.000000
                                                                }
                                                                device [
                                                                  RotationalMotor {
                                                                    name "l_middlePIP"
                                                                    maxPosition 1.25
                                                                    maxTorque 10000
                                                                  }
                                                                  PositionSensor {
                                                                    name "l_middlePIP_sensor"
                                                                  }
                                                                ]
                                                                endPoint Solid {
                                                                  translation 0.000000 0.042000 0.000000
                                                                  rotation 1.000000 0.000000 0.000000 0.183570
                                                                  children [
                                                                    Shape {
                                                                      appearance DEF l_middle_dist_material PBRAppearance {
                                                                        baseColor 0.752940 0.752940 0.752940
                                                                        roughness 1.000000
                                                                        metalness 0
                                                                      }
                                                                      geometry DEF l_middle_dist Mesh {
                                                                        url "kuavo_assets\models\biped_s48\meshes\l_middle_dist.STL"
                                                                      }
                                                                    }
                                                                  ]
                                                                  name "l_middle_dist"
                                                                  boundingObject USE l_middle_dist
                                                                  physics Physics {
                                                                    density -1
                                                                    mass 0.011000
                                                                    centerOfMass [ 0.001724 0.005143 -0.031065 ]
                                                                    inertiaMatrix [
                                                                      1.040500e-03 1.324400e-03 5.321900e-04
                                                                      -3.726800e-05 -3.941500e-05 -4.763800e-05
                                                                    ]
                                                                  }
                                                                }
                                                              }
                                                            ]
                                                            name "l_middle_prox"
                                                            boundingObject USE l_middle_prox
                                                            physics Physics {
                                                              density -1
                                                              mass 0.011000
                                                              centerOfMass [ 0.001724 0.005143 -0.031065 ]
                                                              inertiaMatrix [
                                                                1.040500e-03 1.324400e-03 5.321900e-04
                                                                -3.726800e-05 -3.941500e-05 -4.763800e-05
                                                              ]
                                                            }
                                                          }
                                                        }
                                                        HingeJoint {
                                                          jointParameters HingeJointParameters {
                                                            axis 0.998021 -0.034852 0.052336
                                                            anchor 0.013103 0.090291 -0.001785
                                                          }
                                                          device [
                                                            RotationalMotor {
                                                              name "l_ringMCP"
                                                              maxPosition 1.309
                                                              maxTorque 10000
                                                            }
                                                            PositionSensor {
                                                              name "l_ringMCP_sensor"
                                                            }
                                                          ]
                                                          endPoint Solid {
                                                            translation 0.013103 0.090291 -0.001785
                                                            rotation -0.159229 -0.818927 -0.551367 0.063734
                                                            children [
                                                              Shape {
                                                                appearance DEF l_ring_prox_material PBRAppearance {
                                                                  baseColor 0.752940 0.752940 0.752940
                                                                  roughness 1.000000
                                                                  metalness 0
                                                                }
                                                                geometry DEF l_ring_prox Mesh {
                                                                  url "kuavo_assets\models\biped_s48\meshes\l_ring_prox.STL"
                                                                }
                                                              }
                                                              HingeJoint {
                                                                jointParameters HingeJointParameters {
                                                                  anchor 0.000000 0.042000 0.000000
                                                                }
                                                                device [
                                                                  RotationalMotor {
                                                                    name "l_ringPIP"
                                                                    maxPosition 1.25
                                                                    maxTorque 10000
                                                                  }
                                                                  PositionSensor {
                                                                    name "l_ringPIP_sensor"
                                                                  }
                                                                ]
                                                                endPoint Solid {
                                                                  translation 0.000000 0.042000 0.000000
                                                                  rotation 1.000000 0.000000 0.000000 0.165830
                                                                  children [
                                                                    Shape {
                                                                      appearance DEF l_ring_dist_material PBRAppearance {
                                                                        baseColor 0.752940 0.752940 0.752940
                                                                        roughness 1.000000
                                                                        metalness 0
                                                                      }
                                                                      geometry DEF l_ring_dist Mesh {
                                                                        url "kuavo_assets\models\biped_s48\meshes\l_ring_dist.STL"
                                                                      }
                                                                    }
                                                                  ]
                                                                  name "l_ring_dist"
                                                                  boundingObject USE l_ring_dist
                                                                  physics Physics {
                                                                    density -1
                                                                    mass 0.008000
                                                                    centerOfMass [ 0.001724 0.005143 -0.031065 ]
                                                                    inertiaMatrix [
                                                                      1.040500e-03 1.324400e-03 5.321900e-04
                                                                      -3.726800e-05 -3.941500e-05 -4.763800e-05
                                                                    ]
                                                                  }
                                                                }
                                                              }
                                                            ]
                                                            name "l_ring_prox"
                                                            boundingObject USE l_ring_prox
                                                            physics Physics {
                                                              density -1
                                                              mass 0.011000
                                                              centerOfMass [ 0.001724 0.005143 -0.031065 ]
                                                              inertiaMatrix [
                                                                1.040500e-03 1.324400e-03 5.321900e-04
                                                                -3.726800e-05 -3.941500e-05 -4.763800e-05
                                                              ]
                                                            }
                                                          }
                                                        }
                                                        HingeJoint {
                                                          jointParameters HingeJointParameters {
                                                            axis 0.996197 -0.069661 0.052336
                                                            anchor 0.033731 0.083777 0.002216
                                                          }
                                                          device [
                                                            RotationalMotor {
                                                              name "l_littleMCP"
                                                              maxPosition 1.309
                                                              maxTorque 10000
                                                            }
                                                            PositionSensor {
                                                              name "l_littleMCP_sensor"
                                                            }
                                                          ]
                                                          endPoint Solid {
                                                            translation 0.033731 0.083777 0.002216
                                                            rotation -0.292852 -0.564060 -0.772059 0.091244
                                                            children [
                                                              Shape {
                                                                appearance DEF l_little_prox_material PBRAppearance {
                                                                  roughness 1.000000
                                                                  metalness 0
                                                                }
                                                                geometry DEF l_little_prox Mesh {
                                                                  url "kuavo_assets\models\biped_s48\meshes\l_little_prox.STL"
                                                                }
                                                              }
                                                              HingeJoint {
                                                                jointParameters HingeJointParameters {
                                                                  anchor 0.000000 0.035000 0.000000
                                                                }
                                                                device [
                                                                  RotationalMotor {
                                                                    name "l_littlePIP"
                                                                    maxPosition 1.25
                                                                    maxTorque 10000
                                                                  }
                                                                  PositionSensor {
                                                                    name "l_littlePIP_sensor"
                                                                  }
                                                                ]
                                                                endPoint Solid {
                                                                  translation 0.000000 0.035000 0.000000
                                                                  rotation 1.000000 0.000000 0.000000 0.202940
                                                                  children [
                                                                    Shape {
                                                                      appearance DEF l_little_dist_material PBRAppearance {
                                                                        baseColor 0.752940 0.752940 0.752940
                                                                        roughness 1.000000
                                                                        metalness 0
                                                                      }
                                                                      geometry DEF l_little_dist Mesh {
                                                                        url "kuavo_assets\models\biped_s48\meshes\l_little_dist.STL"
                                                                      }
                                                                    }
                                                                  ]
                                                                  name "l_little_dist"
                                                                  boundingObject USE l_little_dist
                                                                  physics Physics {
                                                                    density -1
                                                                    mass 0.008000
                                                                    centerOfMass [ 0.001724 0.005143 -0.031065 ]
                                                                    inertiaMatrix [
                                                                      1.040500e-03 1.324400e-03 5.321900e-04
                                                                      -3.726800e-05 -3.941500e-05 -4.763800e-05
                                                                    ]
                                                                  }
                                                                }
                                                              }
                                                            ]
                                                            name "l_little_prox"
                                                            boundingObject USE l_little_prox
                                                            physics Physics {
                                                              density -1
                                                              mass 0.008000
                                                              centerOfMass [ -0.000001 0.016662 0.000407 ]
                                                              inertiaMatrix [
                                                                3.352600e-07 1.012900e-07 3.709600e-07
                                                                2.846100e-11 -2.335800e-12 2.134600e-08
                                                              ]
                                                            }
                                                          }
                                                        }
                                                      ]
                                                      name "l_palm"
                                                      boundingObject USE l_palm
                                                      physics Physics {
                                                        density -1
                                                        mass 0.427000
                                                        centerOfMass [ 0.001724 0.005143 -0.031065 ]
                                                        inertiaMatrix [
                                                          1.040500e-03 1.324400e-03 5.321900e-04
                                                          -3.726800e-05 -3.941500e-05 -4.763800e-05
                                                        ]
                                                      }
                                                    }
                                                  ]
                                                  name "zarm_l7_link"
                                                  physics Physics {
                                                    density -1
                                                    mass 0.054211
                                                    centerOfMass [ 0.001860 0.010140 -0.090440 ]
                                                    inertiaMatrix [
                                                      7.100000e-04 7.000000e-04 1.200000e-04
                                                      1.000000e-05 2.000000e-05 -4.000000e-05
                                                    ]
                                                  }
                                                }
                                              }
                                            ]
                                            name "zarm_l6_link"
                                            physics Physics {
                                              density -1
                                              mass 0.331000
                                              centerOfMass [ -0.001110 0.003350 -0.013350 ]
                                              inertiaMatrix [
                                                2.200000e-04 2.700000e-04 2.800000e-04
                                                0.000000e+00 0.000000e+00 0.000000e+00
                                              ]
                                            }
                                          }
                                        }
                                      ]
                                      name "zarm_l5_link"
                                      physics Physics {
                                        density -1
                                        mass 0.610000
                                        centerOfMass [ -0.002070 0.000180 -0.050790 ]
                                        inertiaMatrix [
                                          1.070000e-03 1.460000e-03 8.300000e-04
                                          0.000000e+00 -4.000000e-05 0.000000e+00
                                        ]
                                      }
                                    }
                                  }
                                ]
                                name "zarm_l4_link"
                                physics Physics {
                                  density -1
                                  mass 0.429000
                                  centerOfMass [ -0.016110 0.001430 -0.048570 ]
                                  inertiaMatrix [
                                    1.350000e-03 1.140000e-03 8.300000e-04
                                    0.000000e+00 -1.000000e-04 0.000000e+00
                                  ]
                                }
                              }
                            }
                          ]
                          name "zarm_l3_link"
                          physics Physics {
                            density -1
                            mass 1.650000
                            centerOfMass [ 0.006280 0.001070 -0.208780 ]
                            inertiaMatrix [
                              8.150000e-03 8.280000e-03 2.060000e-03
                              -4.000000e-05 8.500000e-04 1.400000e-04
                            ]
                          }
                        }
                      }
                    ]
                    name "zarm_l2_link"
                    physics Physics {
                      density -1
                      mass 0.570000
                      centerOfMass [ -0.007910 0.000000 -0.046550 ]
                      inertiaMatrix [
                        1.630000e-03 2.110000e-03 1.220000e-03
                        0.000000e+00 5.000000e-05 0.000000e+00
                      ]
                    }
                  }
                }
              ]
              name "zarm_l1_link"
              physics Physics {
                density -1
                mass 0.962000
                centerOfMass [ -0.000830 -0.022180 0.000350 ]
                inertiaMatrix [
                  2.250000e-03 9.900000e-04 2.270000e-03
                  -3.000000e-05 0.000000e+00 -2.000000e-05
                ]
              }
            }
          }
          HingeJoint {
            jointParameters HingeJointParameters {
              axis 0.000000 1.000000 0.000000
              anchor -0.017500 -0.292700 0.424500
            }
            device [
              RotationalMotor {
                name "zarm_r1_joint"
                maxVelocity 41.3433333333333
                minPosition -3.14159265358979
                maxPosition 1.5707963267949
                maxTorque 100.0
              }
              PositionSensor {
                name "zarm_r1_joint_sensor"
              }
            ]
            endPoint Solid {
              translation -0.017500 -0.292700 0.424500
              children [
                Shape {
                  appearance DEF zarm_r1_link_material PBRAppearance {
                    roughness 1.000000
                    metalness 0
                  }
                  geometry DEF r_arm_pitch Mesh {
                    url "kuavo_assets\models\biped_s48\meshes\r_arm_pitch.STL"
                  }
                }
                HingeJoint {
                  jointParameters HingeJointParameters {
                  }
                  device [
                    RotationalMotor {
                      name "zarm_r2_joint"
                      maxVelocity 19.154
                      minPosition -2.0943951023932
                      maxPosition 0.349065850398866
                      maxTorque 50.0
                    }
                    PositionSensor {
                      name "zarm_r2_joint_sensor"
                    }
                  ]
                  endPoint Solid {
                    children [
                      Shape {
                        appearance DEF zarm_r2_link_material PBRAppearance {
                          roughness 1.000000
                          metalness 0
                        }
                        geometry DEF r_arm_roll Mesh {
                          url "kuavo_assets\models\biped_s48\meshes\r_arm_roll.STL"
                        }
                      }
                      HingeJoint {
                        jointParameters HingeJointParameters {
                          axis 0.000000 0.000000 1.000000
                        }
                        device [
                          RotationalMotor {
                            name "zarm_r3_joint"
                            maxVelocity 18.84
                            minPosition -1.5707963267949
                            maxPosition 1.5707963267949
                            maxTorque 39.0
                          }
                          PositionSensor {
                            name "zarm_r3_joint_sensor"
                          }
                        ]
                        endPoint Solid {
                          children [
                            Shape {
                              appearance DEF zarm_r3_link_material PBRAppearance {
                                roughness 1.000000
                                metalness 0
                              }
                              geometry DEF r_arm_yaw Mesh {
                                url "kuavo_assets\models\biped_s48\meshes\r_arm_yaw.STL"
                              }
                            }
                            HingeJoint {
                              jointParameters HingeJointParameters {
                                axis 0.000000 1.000000 0.000000
                                anchor 0.020000 0.000000 -0.283700
                              }
                              device [
                                RotationalMotor {
                                  name "zarm_r4_joint"
                                  maxVelocity 18.84
                                  minPosition -2.61799387799149
                                  maxTorque 50.0
                                }
                                PositionSensor {
                                  name "zarm_r4_joint_sensor"
                                }
                              ]
                              endPoint Solid {
                                translation 0.020000 0.000000 -0.283700
                                children [
                                  Shape {
                                    appearance DEF zarm_r4_link_material PBRAppearance {
                                      roughness 1.000000
                                      metalness 0
                                    }
                                    geometry DEF r_forearm Mesh {
                                      url "kuavo_assets\models\biped_s48\meshes\r_forearm.STL"
                                    }
                                  }
                                  HingeJoint {
                                    jointParameters HingeJointParameters {
                                      axis 0.000000 0.000000 1.000000
                                      anchor -0.020000 0.000000 -0.127037
                                    }
                                    device [
                                      RotationalMotor {
                                        name "zarm_r5_joint"
                                        maxVelocity 21.666
                                        minPosition -1.5707963267949
                                        maxPosition 1.5707963267949
                                        maxTorque 12.0
                                      }
                                      PositionSensor {
                                        name "zarm_r5_joint_sensor"
                                      }
                                    ]
                                    endPoint Solid {
                                      translation -0.020000 0.000000 -0.127037
                                      children [
                                        Shape {
                                          appearance DEF zarm_r5_link_material PBRAppearance {
                                            roughness 1.000000
                                            metalness 0
                                          }
                                          geometry DEF r_hand_yaw Mesh {
                                            url "kuavo_assets\models\biped_s48\meshes\r_hand_yaw.STL"
                                          }
                                        }
                                        HingeJoint {
                                          jointParameters HingeJointParameters {
                                            anchor 0.000000 0.000000 -0.106463
                                          }
                                          device [
                                            RotationalMotor {
                                              name "zarm_r6_joint"
                                              maxVelocity 21.666
                                              minPosition -0.698131700797732
                                              maxPosition 1.30899693899575
                                              maxTorque 12.0
                                            }
                                            PositionSensor {
                                              name "zarm_r6_joint_sensor"
                                            }
                                          ]
                                          endPoint Solid {
                                            translation 0.000000 0.000000 -0.106463
                                            children [
                                              Shape {
                                                appearance DEF zarm_r6_link_material PBRAppearance {
                                                  roughness 1.000000
                                                  metalness 0
                                                }
                                                geometry DEF r_hand_roll Mesh {
                                                  url "kuavo_assets\models\biped_s48\meshes\r_hand_roll.STL"
                                                }
                                              }
                                              HingeJoint {
                                                jointParameters HingeJointParameters {
                                                  axis 0.000000 1.000000 0.000000
                                                  anchor 0.000000 0.000000 -0.021000
                                                }
                                                device [
                                                  RotationalMotor {
                                                    name "zarm_r7_joint"
                                                    maxVelocity 21.666
                                                    minPosition -0.698131700797732
                                                    maxPosition 0.698131700797732
                                                    maxTorque 12.0
                                                  }
                                                  PositionSensor {
                                                    name "zarm_r7_joint_sensor"
                                                  }
                                                ]
                                                endPoint Solid {
                                                  translation 0.000000 0.000000 -0.021000
                                                  children [
                                                    Shape {
                                                      appearance DEF zarm_r7_link_material PBRAppearance {
                                                        roughness 1.000000
                                                        metalness 0
                                                      }
                                                      geometry DEF r_hand_pitch Mesh {
                                                        url "kuavo_assets\models\biped_s48\meshes\r_hand_pitch.STL"
                                                      }
                                                    }
                                                    Solid {
                                                      translation 0.000000 0.030000 -0.170000
                                                      name "zarm_r7_end_effector"
                                                      boundingObject Sphere {
                                                        radius 0.005
                                                      }
                                                      physics Physics {
                                                      }
                                                    }
                                                    Solid {
                                                      translation 0.000000 0.000000 -0.070000
                                                      rotation -1.000000 0.000000 0.000000 1.570000
                                                      children [
                                                        Shape {
                                                          appearance DEF r_palm_material PBRAppearance {
                                                            baseColor 0.752940 0.752940 0.752940
                                                            roughness 1.000000
                                                            metalness 0
                                                          }
                                                          geometry DEF r_palm Mesh {
                                                            url "kuavo_assets\models\biped_s48\meshes\r_palm.STL"
                                                          }
                                                        }
                                                        HingeJoint {
                                                          jointParameters HingeJointParameters {
                                                            axis 0.000000 -1.000000 0.000000
                                                            anchor 0.024500 0.024200 0.021628
                                                          }
                                                          device [
                                                            RotationalMotor {
                                                              name "r_thumbCMC"
                                                              maxPosition 1.5708
                                                              maxTorque 10000
                                                            }
                                                            PositionSensor {
                                                              name "r_thumbCMC_sensor"
                                                            }
                                                          ]
                                                          endPoint Solid {
                                                            translation 0.024500 0.024200 0.021628
                                                            rotation 0.000000 -1.000000 0.000000 0.496420
                                                            children [
                                                              Shape {
                                                                appearance DEF r_thumb_prox_material PBRAppearance {
                                                                  roughness 1.000000
                                                                  metalness 0
                                                                }
                                                                geometry DEF r_thumb_prox Mesh {
                                                                  url "kuavo_assets\models\biped_s48\meshes\r_thumb_prox.STL"
                                                                }
                                                              }
                                                              HingeJoint {
                                                                jointParameters HingeJointParameters {
                                                                  axis 0.476286 -0.000003 0.879290
                                                                  anchor 0.013647 0.000000 0.000000
                                                                }
                                                                device [
                                                                  RotationalMotor {
                                                                    name "r_thumbMCP"
                                                                    maxPosition 0.87266
                                                                    maxTorque 10000
                                                                  }
                                                                  PositionSensor {
                                                                    name "r_thumbMCP_sensor"
                                                                  }
                                                                ]
                                                                endPoint Solid {
                                                                  translation 0.013647 0.000000 0.000000
                                                                  rotation -0.217349 0.466115 -0.857610 0.996030
                                                                  children [
                                                                    Shape {
                                                                      appearance DEF r_thumb_dist_material PBRAppearance {
                                                                        baseColor 0.752940 0.752940 0.752940
                                                                        roughness 1.000000
                                                                        metalness 0
                                                                      }
                                                                      geometry DEF r_thumb_dist Mesh {
                                                                        url "kuavo_assets\models\biped_s48\meshes\r_thumb_dist.STL"
                                                                      }
                                                                    }
                                                                  ]
                                                                  name "r_thumb_dist"
                                                                  boundingObject USE r_thumb_dist
                                                                  physics Physics {
                                                                    density -1
                                                                    mass 0.040000
                                                                    centerOfMass [ 0.008356 0.037204 -0.000000 ]
                                                                    inertiaMatrix [
                                                                      7.149800e-06 9.150100e-07 6.874700e-06
                                                                      2.015700e-07 -6.072600e-11 5.450200e-10
                                                                    ]
                                                                  }
                                                                }
                                                              }
                                                            ]
                                                            name "r_thumb_prox"
                                                            boundingObject USE r_thumb_prox
                                                            physics Physics {
                                                              density -1
                                                              mass 0.005000
                                                              centerOfMass [ 0.006204 -0.000000 0.001531 ]
                                                              inertiaMatrix [
                                                                4.063900e-08 9.248500e-08 8.558600e-08
                                                                5.867500e-13 2.429900e-09 7.104900e-13
                                                              ]
                                                            }
                                                          }
                                                        }
                                                        HingeJoint {
                                                          jointParameters HingeJointParameters {
                                                            axis 0.998021 -0.031116 0.054640
                                                            anchor 0.029003 0.088231 -0.003949
                                                          }
                                                          device [
                                                            RotationalMotor {
                                                              name "r_indexMCP"
                                                              maxPosition 1.309
                                                              maxTorque 10000
                                                            }
                                                            PositionSensor {
                                                              name "r_indexMCP_sensor"
                                                            }
                                                          ]
                                                          endPoint Solid {
                                                            translation 0.029003 0.088231 -0.003949
                                                            rotation -0.846557 -0.448787 -0.286235 0.118254
                                                            children [
                                                              Shape {
                                                                appearance DEF r_index_prox_material PBRAppearance {
                                                                  baseColor 0.752940 0.752940 0.752940
                                                                  roughness 1.000000
                                                                  metalness 0
                                                                }
                                                                geometry DEF r_index_prox Mesh {
                                                                  url "kuavo_assets\models\biped_s48\meshes\r_index_prox.STL"
                                                                }
                                                              }
                                                              HingeJoint {
                                                                jointParameters HingeJointParameters {
                                                                  anchor 0.000000 0.035000 0.000000
                                                                }
                                                                device [
                                                                  RotationalMotor {
                                                                    name "r_indexPIP"
                                                                    maxPosition 1.25
                                                                    maxTorque 10000
                                                                  }
                                                                  PositionSensor {
                                                                    name "r_indexPIP_sensor"
                                                                  }
                                                                ]
                                                                endPoint Solid {
                                                                  translation 0.000000 0.035000 0.000000
                                                                  rotation 1.000000 0.000000 0.000000 0.193530
                                                                  children [
                                                                    Shape {
                                                                      appearance DEF r_index_dist_material PBRAppearance {
                                                                        baseColor 0.752940 0.752940 0.752940
                                                                        roughness 1.000000
                                                                        metalness 0
                                                                      }
                                                                      geometry DEF r_index_dist Mesh {
                                                                        url "kuavo_assets\models\biped_s48\meshes\r_index_dist.STL"
                                                                      }
                                                                    }
                                                                  ]
                                                                  name "r_index_dist"
                                                                  boundingObject USE r_index_dist
                                                                  physics Physics {
                                                                    density -1
                                                                    mass 0.011000
                                                                    centerOfMass [ 0.000006 0.025449 0.003278 ]
                                                                    inertiaMatrix [
                                                                      8.480100e-07 1.414700e-07 8.550200e-07
                                                                      -1.087800e-09 -1.368300e-10 -1.007800e-07
                                                                    ]
                                                                  }
                                                                }
                                                              }
                                                            ]
                                                            name "r_index_prox"
                                                            boundingObject USE r_index_prox
                                                            physics Physics {
                                                              density -1
                                                              mass 0.008000
                                                              centerOfMass [ -0.000001 0.016609 0.000457 ]
                                                              inertiaMatrix [
                                                                3.352600e-07 1.013300e-07 3.709200e-07
                                                                2.940100e-11 -2.478200e-12 2.057600e-08
                                                              ]
                                                            }
                                                          }
                                                        }
                                                        HingeJoint {
                                                          jointParameters HingeJointParameters {
                                                            anchor 0.008000 0.091935 -0.008204
                                                          }
                                                          device [
                                                            RotationalMotor {
                                                              name "r_middleMCP"
                                                              maxPosition 1.309
                                                              maxTorque 10000
                                                            }
                                                            PositionSensor {
                                                              name "r_middleMCP_sensor"
                                                            }
                                                          ]
                                                          endPoint Solid {
                                                            translation 0.008000 0.091935 -0.008204
                                                            rotation -1.000000 0.000000 0.000000 0.069813
                                                            children [
                                                              Shape {
                                                                appearance DEF r_middle_prox_material PBRAppearance {
                                                                  baseColor 0.752940 0.752940 0.752940
                                                                  roughness 1.000000
                                                                  metalness 0
                                                                }
                                                                geometry DEF r_middle_prox Mesh {
                                                                  url "kuavo_assets\models\biped_s48\meshes\r_middle_prox.STL"
                                                                }
                                                              }
                                                              HingeJoint {
                                                                jointParameters HingeJointParameters {
                                                                  anchor 0.000000 0.042000 0.000000
                                                                }
                                                                device [
                                                                  RotationalMotor {
                                                                    name "r_middlePIP"
                                                                    maxPosition 1.25
                                                                    maxTorque 10000
                                                                  }
                                                                  PositionSensor {
                                                                    name "r_middlePIP_sensor"
                                                                  }
                                                                ]
                                                                endPoint Solid {
                                                                  translation 0.000000 0.042000 0.000000
                                                                  rotation 1.000000 0.000000 0.000000 0.183570
                                                                  children [
                                                                    Shape {
                                                                      appearance DEF r_middle_dist_material PBRAppearance {
                                                                        baseColor 0.752940 0.752940 0.752940
                                                                        roughness 1.000000
                                                                        metalness 0
                                                                      }
                                                                      geometry DEF r_middle_dist Mesh {
                                                                        url "kuavo_assets\models\biped_s48\meshes\r_middle_dist.STL"
                                                                      }
                                                                    }
                                                                  ]
                                                                  name "r_middle_dist"
                                                                  boundingObject USE r_middle_dist
                                                                  physics Physics {
                                                                    density -1
                                                                    mass 0.011000
                                                                    centerOfMass [ 0.000006 0.025449 0.003278 ]
                                                                    inertiaMatrix [
                                                                      8.480100e-07 1.414700e-07 8.550100e-07
                                                                      -1.087900e-09 -1.370500e-10 -1.007800e-07
                                                                    ]
                                                                  }
                                                                }
                                                              }
                                                            ]
                                                            name "r_middle_prox"
                                                            boundingObject USE r_middle_prox
                                                            physics Physics {
                                                              density -1
                                                              mass 0.011000
                                                              centerOfMass [ 0.000000 0.020205 0.000540 ]
                                                              inertiaMatrix [
                                                                5.562400e-07 1.329800e-07 6.014600e-07
                                                                8.000000e-12 -8.515100e-12 2.669000e-08
                                                              ]
                                                            }
                                                          }
                                                        }
                                                        HingeJoint {
                                                          jointParameters HingeJointParameters {
                                                            axis 0.998021 0.031116 -0.054640
                                                            anchor -0.013103 0.089947 -0.008079
                                                          }
                                                          device [
                                                            RotationalMotor {
                                                              name "r_ringMCP"
                                                              maxPosition 1.309
                                                              maxTorque 10000
                                                            }
                                                            PositionSensor {
                                                              name "r_ringMCP_sensor"
                                                            }
                                                          ]
                                                          endPoint Solid {
                                                            translation -0.013103 0.089947 -0.008079
                                                            rotation -0.785707 0.524878 0.327364 0.101741
                                                            children [
                                                              Shape {
                                                                appearance DEF r_ring_prox_material PBRAppearance {
                                                                  baseColor 0.752940 0.752940 0.752940
                                                                  roughness 1.000000
                                                                  metalness 0
                                                                }
                                                                geometry DEF r_ring_prox Mesh {
                                                                  url "kuavo_assets\models\biped_s48\meshes\r_ring_prox.STL"
                                                                }
                                                              }
                                                              HingeJoint {
                                                                jointParameters HingeJointParameters {
                                                                  anchor 0.000000 0.042000 0.000000
                                                                }
                                                                device [
                                                                  RotationalMotor {
                                                                    name "r_ringPIP"
                                                                    maxPosition 1.25
                                                                    maxTorque 10000
                                                                  }
                                                                  PositionSensor {
                                                                    name "r_ringPIP_sensor"
                                                                  }
                                                                ]
                                                                endPoint Solid {
                                                                  translation 0.000000 0.042000 0.000000
                                                                  rotation 1.000000 0.000000 0.000000 0.165830
                                                                  children [
                                                                    Shape {
                                                                      appearance DEF r_ring_dist_material PBRAppearance {
                                                                        baseColor 0.752940 0.752940 0.752940
                                                                        roughness 1.000000
                                                                        metalness 0
                                                                      }
                                                                      geometry DEF r_ring_dist Mesh {
                                                                        url "kuavo_assets\models\biped_s48\meshes\r_ring_dist.STL"
                                                                      }
                                                                    }
                                                                  ]
                                                                  name "r_ring_dist"
                                                                  boundingObject USE r_ring_dist
                                                                  physics Physics {
                                                                    density -1
                                                                    mass 0.008000
                                                                    centerOfMass [ 0.000001 0.020388 0.002908 ]
                                                                    inertiaMatrix [
                                                                      3.679300e-07 8.420800e-08 3.836900e-07
                                                                      -6.504000e-13 -1.154100e-11 -4.573700e-08
                                                                    ]
                                                                  }
                                                                }
                                                              }
                                                            ]
                                                            name "r_ring_prox"
                                                            boundingObject USE r_ring_prox
                                                            physics Physics {
                                                              density -1
                                                              mass 0.011000
                                                              centerOfMass [ 0.000000 0.020236 0.000424 ]
                                                              inertiaMatrix [
                                                                5.562300e-07 1.329500e-07 6.014900e-07
                                                                7.460400e-12 -8.587600e-12 2.771900e-08
                                                              ]
                                                            }
                                                          }
                                                        }
                                                        HingeJoint {
                                                          jointParameters HingeJointParameters {
                                                            axis 0.996197 0.065841 -0.057068
                                                            anchor -0.033731 0.083727 -0.003634
                                                          }
                                                          device [
                                                            RotationalMotor {
                                                              name "r_littleMCP"
                                                              maxPosition 1.309
                                                              maxTorque 10000
                                                            }
                                                            PositionSensor {
                                                              name "r_littleMCP_sensor"
                                                            }
                                                          ]
                                                          endPoint Solid {
                                                            translation -0.033731 0.083727 -0.003634
                                                            rotation -0.741633 0.414385 0.527509 0.130105
                                                            children [
                                                              Shape {
                                                                appearance DEF r_little_prox_material PBRAppearance {
                                                                  baseColor 0.752940 0.752940 0.752940
                                                                  roughness 1.000000
                                                                  metalness 0
                                                                }
                                                                geometry DEF r_little_prox Mesh {
                                                                  url "kuavo_assets\models\biped_s48\meshes\r_little_prox.STL"
                                                                }
                                                              }
                                                              HingeJoint {
                                                                jointParameters HingeJointParameters {
                                                                  anchor 0.000000 0.035000 0.000000
                                                                }
                                                                device [
                                                                  RotationalMotor {
                                                                    name "r_littlePIP"
                                                                    maxPosition 1.25
                                                                    maxTorque 10000
                                                                  }
                                                                  PositionSensor {
                                                                    name "r_littlePIP_sensor"
                                                                  }
                                                                ]
                                                                endPoint Solid {
                                                                  translation 0.000000 0.035000 0.000000
                                                                  rotation 1.000000 0.000000 0.000000 0.202940
                                                                  children [
                                                                    Shape {
                                                                      appearance DEF r_little_dist_material PBRAppearance {
                                                                        baseColor 0.752940 0.752940 0.752940
                                                                        roughness 1.000000
                                                                        metalness 0
                                                                      }
                                                                      geometry DEF r_little_dist Mesh {
                                                                        url "kuavo_assets\models\biped_s48\meshes\r_little_dist.STL"
                                                                      }
                                                                    }
                                                                  ]
                                                                  name "r_little_dist"
                                                                  boundingObject USE r_little_dist
                                                                  physics Physics {
                                                                    density -1
                                                                    mass 0.008000
                                                                    centerOfMass [ 0.000011 0.017869 0.002086 ]
                                                                    inertiaMatrix [
                                                                      2.326200e-07 6.430400e-08 2.491600e-07
                                                                      -4.913500e-10 -4.950600e-11 -2.356400e-08
                                                                    ]
                                                                  }
                                                                }
                                                              }
                                                            ]
                                                            name "r_little_prox"
                                                            boundingObject USE r_little_prox
                                                            physics Physics {
                                                              density -1
                                                              mass 0.008000
                                                              centerOfMass [ -0.000001 0.016662 0.000407 ]
                                                              inertiaMatrix [
                                                                3.352600e-07 1.012900e-07 3.709600e-07
                                                                2.846100e-11 -2.335800e-12 2.134600e-08
                                                              ]
                                                            }
                                                          }
                                                        }
                                                      ]
                                                      name "r_palm"
                                                      boundingObject USE r_palm
                                                      physics Physics {
                                                        density -1
                                                        mass 0.427000
                                                        centerOfMass [ -0.000994 0.040537 -0.002283 ]
                                                        inertiaMatrix [
                                                          3.436400e-05 3.946700e-05 6.398400e-05
                                                          -1.240400e-06 5.654000e-07 3.895500e-06
                                                        ]
                                                      }
                                                    }
                                                  ]
                                                  name "zarm_r7_link"
                                                  physics Physics {
                                                    density -1
                                                    mass 0.054211
                                                    centerOfMass [ 0.001860 -0.010140 -0.090440 ]
                                                    inertiaMatrix [
                                                      6.900000e-04 6.800000e-04 1.200000e-04
                                                      -1.000000e-05 2.000000e-05 5.000000e-05
                                                    ]
                                                  }
                                                }
                                              }
                                            ]
                                            name "zarm_r6_link"
                                            physics Physics {
                                              density -1
                                              mass 0.331000
                                              centerOfMass [ -0.001110 -0.003350 -0.013350 ]
                                              inertiaMatrix [
                                                2.200000e-04 2.700000e-04 2.800000e-04
                                                0.000000e+00 0.000000e+00 0.000000e+00
                                              ]
                                            }
                                          }
                                        }
                                      ]
                                      name "zarm_r5_link"
                                      physics Physics {
                                        density -1
                                        mass 0.610000
                                        centerOfMass [ -0.002070 -0.000180 -0.050790 ]
                                        inertiaMatrix [
                                          1.070000e-03 1.460000e-03 8.300000e-04
                                          0.000000e+00 -4.000000e-05 0.000000e+00
                                        ]
                                      }
                                    }
                                  }
                                ]
                                name "zarm_r4_link"
                                physics Physics {
                                  density -1
                                  mass 0.429000
                                  centerOfMass [ -0.016110 -0.001430 -0.048570 ]
                                  inertiaMatrix [
                                    1.350000e-03 1.140000e-03 8.300000e-04
                                    0.000000e+00 -1.000000e-04 0.000000e+00
                                  ]
                                }
                              }
                            }
                          ]
                          name "zarm_r3_link"
                          physics Physics {
                            density -1
                            mass 1.650000
                            centerOfMass [ 0.006280 -0.001070 -0.208780 ]
                            inertiaMatrix [
                              8.150000e-03 8.280000e-03 2.060000e-03
                              4.000000e-05 8.500000e-04 -1.400000e-04
                            ]
                          }
                        }
                      }
                    ]
                    name "zarm_r2_link"
                    physics Physics {
                      density -1
                      mass 0.570000
                      centerOfMass [ -0.007910 0.000000 -0.046550 ]
                      inertiaMatrix [
                        1.630000e-03 2.110000e-03 1.220000e-03
                        0.000000e+00 5.000000e-05 0.000000e+00
                      ]
                    }
                  }
                }
              ]
              name "zarm_r1_link"
              physics Physics {
                density -1
                mass 0.962000
                centerOfMass [ -0.000830 0.022180 0.000350 ]
                inertiaMatrix [
                  2.250000e-03 9.900000e-04 2.270000e-03
                  3.000000e-05 0.000000e+00 2.000000e-05
                ]
              }
            }
          }
          HingeJoint {
            jointParameters HingeJointParameters {
              axis 0.000000 0.000000 1.000000
              anchor -0.018500 0.000000 0.601400
            }
            device [
              RotationalMotor {
                name "zhead_1_joint"
                maxVelocity 5.23333333333333
                minPosition -1.5707963267949
                maxPosition 1.5707963267949
                maxTorque 1.5
              }
              PositionSensor {
                name "zhead_1_joint_sensor"
              }
            ]
            endPoint Solid {
              translation -0.018500 0.000000 0.601400
              children [
                Shape {
                  appearance DEF zhead_1_link_material PBRAppearance {
                    roughness 1.000000
                    metalness 0
                  }
                  geometry DEF head_yaw Mesh {
                    url "kuavo_assets\models\biped_s48\meshes\head_yaw.STL"
                  }
                }
                HingeJoint {
                  jointParameters HingeJointParameters {
                    axis 0.000000 1.000000 0.000000
                  }
                  device [
                    RotationalMotor {
                      name "zhead_2_joint"
                      maxVelocity 5.23333333333333
                      minPosition -0.523598775598299
                      maxPosition 0.523598775598299
                      maxTorque 12.0
                    }
                    PositionSensor {
                      name "zhead_2_joint_sensor"
                    }
                  ]
                  endPoint Solid {
                    children [
                      Shape {
                        appearance DEF zhead_2_link_material PBRAppearance {
                          roughness 1.000000
                          metalness 0
                        }
                        geometry DEF head_pitch Mesh {
                          url "kuavo_assets\models\biped_s48\meshes\head_pitch.STL"
                        }
                      }
                      Solid {
                        translation 0.096751 0.017500 0.125953
                        rotation 0.000000 1.000000 0.000000 0.488692
                        children [
                          Shape {
                            appearance DEF camera_material PBRAppearance {
                              roughness 1.000000
                              metalness 0
                            }
                            geometry DEF camera Mesh {
                              url "kuavo_assets\models\biped_s48\meshes\camera.STL"
                            }
                          }
                        ]
                        name "camera"
                        physics Physics {
                          density -1
                          mass 0.047000
                          centerOfMass [ -0.042570 -0.017360 -0.011610 ]
                          inertiaMatrix [
                            6.500000e-04 9.100000e-04 1.050000e-03
                            0.000000e+00 1.500000e-04 0.000000e+00
                          ]
                        }
                      }
                      Solid {
                        translation 0.082892 0.000000 0.119165
                        rotation 0.000000 1.000000 0.000000 0.488692
                        children [
                          Shape {
                            appearance DEF camera_base_material PBRAppearance {
                              roughness 1.000000
                              metalness 0
                            }
                            geometry DEF camera_base Mesh {
                              url "kuavo_assets\models\biped_s48\meshes\camera_base.STL"
                            }
                          }
                        ]
                        name "camera_base"
                        boundingObject USE camera_base
                        physics Physics {
                          density -1
                          mass 0.017026
                          centerOfMass [ 0.003541 0.001404 0.012451 ]
                          inertiaMatrix [
                            1.091826e-05 8.571790e-07 1.028699e-05
                            1.053544e-07 1.058715e-08 1.640187e-08
                          ]
                        }
                      }
                      Solid {
                        translation 0.021780 0.000000 0.105417
                        rotation 0.000000 1.000000 0.000000 0.229686
                        children [
                          Shape {
                            appearance DEF radar_material PBRAppearance {
                              roughness 1.000000
                              metalness 0
                            }
                            geometry DEF radar Mesh {
                              url "kuavo_assets\models\biped_s48\meshes\radar.STL"
                            }
                          }
                        ]
                        name "radar"
                        physics Physics {
                          density -1
                          mass 0.268800
                          centerOfMass [ -0.000180 0.000010 0.017770 ]
                          inertiaMatrix [
                            1.300000e-04 1.400000e-04 1.400000e-04
                            0.000000e+00 0.000000e+00 0.000000e+00
                          ]
                        }
                      }
                    ]
                    name "zhead_2_link"
                    physics Physics {
                      density -1
                      mass 0.549200
                      centerOfMass [ 0.026480 -0.001420 0.106740 ]
                      inertiaMatrix [
                        3.460000e-03 3.480000e-03 2.220000e-03
                        -3.000000e-05 1.700000e-04 -7.000000e-05
                      ]
                    }
                  }
                }
              ]
              name "zhead_1_link"
              physics Physics {
                density -1
                mass 0.350000
                centerOfMass [ 0.000020 0.006050 -0.010520 ]
                inertiaMatrix [
                  7.000000e-05 5.000000e-05 5.000000e-05
                  0.000000e+00 0.000000e+00 0.000000e+00
                ]
              }
            }
          }
        ]
        name "base_link"
        physics Physics {
          density -1
          mass 22.112938
          centerOfMass [ -0.018500 0.000320 0.192957 ]
          inertiaMatrix [
            9.310313e-01 8.259053e-01 2.768661e-01
            1.176300e-04 -7.210993e-02 6.880000e-06
          ]
        }
      }
    ]
    name IS name
  }
}
