#VRML_SIM R2025a utf8

EXTERNPROTO "https://raw.githubusercontent.com/cyberbotics/webots/R2025a/projects/objects/floors/protos/Floor.proto"
EXTERNPROTO "https://raw.githubusercontent.com/cyberbotics/webots/R2025a/projects/objects/backgrounds/protos/TexturedBackgroundLight.proto"

WorldInfo {
}
Viewpoint {
  orientation 0.32822284792172507 -0.11753961024269083 -0.9372588767923986 4.007926700784666
  position 4.413841726700392 -4.627012514489133 4.805669347551688
}
Floor {
  size 8 8
}
TexturedBackgroundLight {
  luminosity 0.6
  castShadows FALSE
}
DEF conveyor Solid {
  translation 1.5 -1.02 0.75
  rotation 1 0 0 1.5708000000000002
  children [
    DEF conveyor Shape {
      appearance Appearance {
        material Material {
          diffuseColor 0 0 1
        }
        texture ImageTexture {
        }
        textureTransform TextureTransform {
        }
      }
      geometry Mesh {
        url [
          "../protos/stl/endless conveyor line.STL"
        ]
        ccw FALSE
      }
      castShadows FALSE
      isPickable FALSE
    }
  ]
}
DEF wall1 Solid {
  translation 0.36 -0.0698409 0.85
  rotation 1 0 0 3.14
  children [
    DEF wall Shape {
      appearance PBRAppearance {
        transparency 1
        emissiveColor 0.333333 0.666667 1
      }
      geometry Mesh {
        url [
          "../protos/stl/wall.STL"
        ]
      }
    }
  ]
  name "wall1"
  boundingObject USE wall
  locked TRUE
}
DEF target Solid {
  translation 1.566598839684898 0.37706342117457003 0.8992515586571497
  rotation 0.13584690434234784 0.03528504088274408 -0.9901013001054509 -0.2562823537863075
  children [
    DEF goods Shape {
      appearance PBRAppearance {
        emissiveColor 1 1 0
      }
      geometry Box {
        size 0.1 0.1 0.2
      }
    }
  ]
  name "target"
  boundingObject USE goods
  physics Physics {
    damping Damping {
    }
  }
  linearVelocity -0.004396966990538356 0.26616329979982145 -0.000355255844704418
  angularVelocity -0.0015218751037942185 -0.0006206679148102929 0.19855716634085843
}
DEF robot Robot {
  translation 0.32707 -0.0323 0.62
  children [
    HingeJoint {
      jointParameters HingeJointParameters {
        position 180.9440000000987
        axis 0 0 1
        anchor 0 0 0.35
      }
      device [
        DEF motor RotationalMotor {
          name "motor"
          maxVelocity 5
        }
      ]
      endPoint DEF bogan Solid {
        translation 0 0 -8.326672684688674e-16
        rotation 0 0 1 5.014811399070275
        children [
          DEF zhou1 Solid {
            translation 0.02394240112671034 -0.014290492609151606 0.25553455192560126
            rotation 0.12649688129137443 -0.9293428393608457 -0.3468723482093625 0.02837604790840806
            children [
              DEF bogan1 Group {
                children [
                  DEF gan Pose {
                    translation 0 1.27 0
                    children [
                      DEF gan0 Shape {
                        appearance PBRAppearance {
                          transparency 1
                        }
                        geometry Box {
                          size 0.1 2.5 0.1
                        }
                      }
                    ]
                  }
                  DEF xiaozhou Shape {
                    appearance PBRAppearance {
                      transparency 1
                    }
                    geometry Cylinder {
                      height 0.1
                      radius 0.05
                    }
                  }
                ]
              }
            ]
            name "zhou"
            boundingObject USE gan
            physics Physics {
              density -1
              mass 1
              damping Damping {
              }
            }
            linearVelocity 6.562149441112839e-05 -0.00019207738714567644 -8.328202834515488e-05
            angularVelocity -5.540593950230319e-06 -2.00891846795866e-06 -1.326234326749301e-05
          }
          DEF zhou Shape {
            appearance PBRAppearance {
              transparency 1
            }
            geometry Cylinder {
              height 0.6
              radius 0.05
            }
          }
        ]
      }
    }
  ]
  recognitionColors [
    0 0 0
  ]
  controller "rotational_motor"
}
DEF SAVELOADER Robot {
  name "save_loader"
  controller "save_load_server"
  supervisor TRUE
}